Process A [NEW] (arrival time 9 ms) 16 CPU bursts
Process B [NEW] (arrival time 18 ms) 21 CPU bursts
Process C [NEW] (arrival time 84 ms) 82 CPU bursts
Process D [NEW] (arrival time 86 ms) 36 CPU bursts
Process E [NEW] (arrival time 2 ms) 26 CPU bursts
Process F [NEW] (arrival time 25 ms) 39 CPU bursts
Process G [NEW] (arrival time 13 ms) 76 CPU bursts
Process H [NEW] (arrival time 46 ms) 82 CPU bursts
Process I [NEW] (arrival time 64 ms) 63 CPU bursts
Process J [NEW] (arrival time 31 ms) 21 CPU bursts
Process K [NEW] (arrival time 56 ms) 1 CPU bursts
Process L [NEW] (arrival time 12 ms) 3 CPU bursts
time 0ms: Simulator started for SJF [Q <empty>]
time 2ms: Process E (tau 100ms) arrived; added to ready queue [Q E]
time 4ms: Process E started using the CPU for 11ms burst [Q <empty>]
time 9ms: Process A (tau 100ms) arrived; added to ready queue [Q A]
time 12ms: Process L (tau 100ms) arrived; added to ready queue [Q A L]
time 13ms: Process G (tau 100ms) arrived; added to ready queue [Q A G L]
time 15ms: Process E completed a CPU burst; 25 bursts to go [Q A G L]
time 15ms: Recalculated tau = 56ms for process E [Q A G L]
time 15ms: Process E switching out of CPU; will block on I/O until time 34ms [Q A G L]
time 18ms: Process B (tau 100ms) arrived; added to ready queue [Q B G L]
time 19ms: Process A started using the CPU for 56ms burst [Q B G L]
time 25ms: Process F (tau 100ms) arrived; added to ready queue [Q B F G L]
time 31ms: Process J (tau 100ms) arrived; added to ready queue [Q B F G J L]
time 34ms: Process E (tau 56ms) completed I/O; added to ready queue [Q E B F G J L]
time 46ms: Process H (tau 100ms) arrived; added to ready queue [Q E B F G H J L]
time 56ms: Process K (tau 100ms) arrived; added to ready queue [Q E B F G H J K L]
time 64ms: Process I (tau 100ms) arrived; added to ready queue [Q E B F G H I J K L]
time 75ms: Process A completed a CPU burst; 15 bursts to go [Q E B F G H I J K L]
time 75ms: Recalculated tau = 78ms for process A [Q E B F G H I J K L]
time 75ms: Process A switching out of CPU; will block on I/O until time 100ms [Q E B F G H I J K L]
time 79ms: Process E started using the CPU for 65ms burst [Q B F G H I J K L]
time 84ms: Process C (tau 100ms) arrived; added to ready queue [Q B C F G H I J K L]
time 86ms: Process D (tau 100ms) arrived; added to ready queue [Q B C D F G H I J K L]
time 100ms: Process A (tau 78ms) completed I/O; added to ready queue [Q A B C D F G H I J K L]
time 144ms: Process E completed a CPU burst; 24 bursts to go [Q A B C D F G H I J K L]
time 144ms: Recalculated tau = 61ms for process E [Q A B C D F G H I J K L]
time 144ms: Process E switching out of CPU; will block on I/O until time 201ms [Q A B C D F G H I J K L]
time 148ms: Process A started using the CPU for 60ms burst [Q B C D F G H I J K L]
time 201ms: Process E (tau 61ms) completed I/O; added to ready queue [Q E B C D F G H I J K L]
time 208ms: Process A completed a CPU burst; 14 bursts to go [Q E B C D F G H I J K L]
time 208ms: Recalculated tau = 69ms for process A [Q E B C D F G H I J K L]
time 208ms: Process A switching out of CPU; will block on I/O until time 363ms [Q E B C D F G H I J K L]
time 212ms: Process E started using the CPU for 52ms burst [Q B C D F G H I J K L]
time 264ms: Process E completed a CPU burst; 23 bursts to go [Q B C D F G H I J K L]
time 264ms: Recalculated tau = 57ms for process E [Q B C D F G H I J K L]
time 264ms: Process E switching out of CPU; will block on I/O until time 362ms [Q B C D F G H I J K L]
time 268ms: Process B started using the CPU for 106ms burst [Q C D F G H I J K L]
time 362ms: Process E (tau 57ms) completed I/O; added to ready queue [Q E C D F G H I J K L]
time 363ms: Process A (tau 69ms) completed I/O; added to ready queue [Q E A C D F G H I J K L]
time 374ms: Process B completed a CPU burst; 20 bursts to go [Q E A C D F G H I J K L]
time 374ms: Recalculated tau = 103ms for process B [Q E A C D F G H I J K L]
time 374ms: Process B switching out of CPU; will block on I/O until time 532ms [Q E A C D F G H I J K L]
time 378ms: Process E started using the CPU for 199ms burst [Q A C D F G H I J K L]
time 532ms: Process B (tau 103ms) completed I/O; added to ready queue [Q A C D F G H I J K L B]
time 577ms: Process E completed a CPU burst; 22 bursts to go [Q A C D F G H I J K L B]
time 577ms: Recalculated tau = 128ms for process E [Q A C D F G H I J K L B]
time 577ms: Process E switching out of CPU; will block on I/O until time 589ms [Q A C D F G H I J K L B]
time 581ms: Process A started using the CPU for 39ms burst [Q C D F G H I J K L B]
time 589ms: Process E (tau 128ms) completed I/O; added to ready queue [Q C D F G H I J K L B E]
time 620ms: Process A completed a CPU burst; 13 bursts to go [Q C D F G H I J K L B E]
time 620ms: Recalculated tau = 54ms for process A [Q C D F G H I J K L B E]
time 620ms: Process A switching out of CPU; will block on I/O until time 672ms [Q C D F G H I J K L B E]
time 624ms: Process C started using the CPU for 79ms burst [Q D F G H I J K L B E]
time 672ms: Process A (tau 54ms) completed I/O; added to ready queue [Q A D F G H I J K L B E]
time 703ms: Process C completed a CPU burst; 81 bursts to go [Q A D F G H I J K L B E]
time 703ms: Recalculated tau = 90ms for process C [Q A D F G H I J K L B E]
time 703ms: Process C switching out of CPU; will block on I/O until time 862ms [Q A D F G H I J K L B E]
time 707ms: Process A started using the CPU for 47ms burst [Q D F G H I J K L B E]
time 754ms: Process A completed a CPU burst; 12 bursts to go [Q D F G H I J K L B E]
time 754ms: Recalculated tau = 51ms for process A [Q D F G H I J K L B E]
time 754ms: Process A switching out of CPU; will block on I/O until time 758ms [Q D F G H I J K L B E]
time 758ms: Process D started using the CPU for 22ms burst [Q F G H I J K L B E]
time 758ms: Process A (tau 51ms) completed I/O; added to ready queue [Q A F G H I J K L B E]
time 780ms: Process D completed a CPU burst; 35 bursts to go [Q A F G H I J K L B E]
time 780ms: Recalculated tau = 61ms for process D [Q A F G H I J K L B E]
time 780ms: Process D switching out of CPU; will block on I/O until time 797ms [Q A F G H I J K L B E]
time 784ms: Process A started using the CPU for 137ms burst [Q F G H I J K L B E]
time 797ms: Process D (tau 61ms) completed I/O; added to ready queue [Q D F G H I J K L B E]
time 862ms: Process C (tau 90ms) completed I/O; added to ready queue [Q D C F G H I J K L B E]
time 921ms: Process A completed a CPU burst; 11 bursts to go [Q D C F G H I J K L B E]
time 921ms: Recalculated tau = 94ms for process A [Q D C F G H I J K L B E]
time 921ms: Process A switching out of CPU; will block on I/O until time 947ms [Q D C F G H I J K L B E]
time 925ms: Process D started using the CPU for 52ms burst [Q C F G H I J K L B E]
time 947ms: Process A (tau 94ms) completed I/O; added to ready queue [Q C A F G H I J K L B E]
time 977ms: Process D completed a CPU burst; 34 bursts to go [Q C A F G H I J K L B E]
time 977ms: Recalculated tau = 57ms for process D [Q C A F G H I J K L B E]
time 977ms: Process D switching out of CPU; will block on I/O until time 988ms [Q C A F G H I J K L B E]
time 981ms: Process C started using the CPU for 148ms burst [Q A F G H I J K L B E]
time 988ms: Process D (tau 57ms) completed I/O; added to ready queue [Q D A F G H I J K L B E]
time 4048ms: Process K terminated [Q J L B H F C A E D G I]
time 5227ms: Process A terminated [Q C F L E D H G I J B]
time 5633ms: Process L terminated [Q F C E D H G I J B]
time 18940ms: Process D terminated [Q G E H I J F B]
time 19359ms: Process E terminated [Q H I J F B]
time 23957ms: Process F terminated [Q B G I]
time 26382ms: Process C terminated [Q H J G B I]
time 28820ms: Process J terminated [Q G H B I]
time 29855ms: Process G terminated [Q I H B]
time 30136ms: Process H terminated [Q I B]
time 31258ms: Process B terminated [Q <empty>]
time 36162ms: Process I terminated [Q <empty>]
time 36164ms: Simulator ended for SJF [Q <empty>]

Process A [NEW] (arrival time 9 ms) 16 CPU bursts
Process B [NEW] (arrival time 18 ms) 21 CPU bursts
Process C [NEW] (arrival time 84 ms) 82 CPU bursts
Process D [NEW] (arrival time 86 ms) 36 CPU bursts
Process E [NEW] (arrival time 2 ms) 26 CPU bursts
Process F [NEW] (arrival time 25 ms) 39 CPU bursts
Process G [NEW] (arrival time 13 ms) 76 CPU bursts
Process H [NEW] (arrival time 46 ms) 82 CPU bursts
Process I [NEW] (arrival time 64 ms) 63 CPU bursts
Process J [NEW] (arrival time 31 ms) 21 CPU bursts
Process K [NEW] (arrival time 56 ms) 1 CPU bursts
Process L [NEW] (arrival time 12 ms) 3 CPU bursts
time 0ms: Simulator started for SRT [Q <empty>]
time 2ms: Process E (tau 100ms) arrived; added to ready queue [Q E]
time 4ms: Process E started using the CPU for 11ms burst [Q <empty>]
time 9ms: Process A (tau 100ms) arrived; added to ready queue [Q A]
time 12ms: Process L (tau 100ms) arrived; added to ready queue [Q A L]
time 13ms: Process G (tau 100ms) arrived; added to ready queue [Q A G L]
time 15ms: Process E completed a CPU burst; 25 bursts to go [Q A G L]
time 15ms: Recalculated tau = 56ms for process E [Q A G L]
time 15ms: Process E switching out of CPU; will block on I/O until time 34ms [Q A G L]
time 18ms: Process B (tau 100ms) arrived; added to ready queue [Q B G L]
time 19ms: Process A started using the CPU for 56ms burst [Q B G L]
time 25ms: Process F (tau 100ms) arrived; added to ready queue [Q B F G L]
time 31ms: Process J (tau 100ms) arrived; added to ready queue [Q B F G J L]
time 34ms: Process E (tau 56ms) completed I/O and will preempt A [Q B F G J L]
time 38ms: Process E started using the CPU for 65ms burst [Q A B F G J L]
time 46ms: Process H (tau 100ms) arrived; added to ready queue [Q A B F G H J L]
time 56ms: Process K (tau 100ms) arrived; added to ready queue [Q A B F G H J K L]
time 64ms: Process I (tau 100ms) arrived; added to ready queue [Q A B F G H I J K L]
time 84ms: Process C (tau 100ms) arrived; added to ready queue [Q A B C F G H I J K L]
time 86ms: Process D (tau 100ms) arrived; added to ready queue [Q A B C D F G H I J K L]
time 103ms: Process E completed a CPU burst; 24 bursts to go [Q A B C D F G H I J K L]
time 103ms: Recalculated tau = 61ms for process E [Q A B C D F G H I J K L]
time 103ms: Process E switching out of CPU; will block on I/O until time 160ms [Q A B C D F G H I J K L]
time 107ms: Process A started using the CPU with 41ms remaining [Q B C D F G H I J K L]
time 148ms: Process A completed a CPU burst; 15 bursts to go [Q B C D F G H I J K L]
time 148ms: Recalculated tau = 78ms for process A [Q B C D F G H I J K L]
time 148ms: Process A switching out of CPU; will block on I/O until time 173ms [Q B C D F G H I J K L]
time 152ms: Process B started using the CPU for 106ms burst [Q C D F G H I J K L]
time 160ms: Process E (tau 61ms) completed I/O and will preempt B [Q C D F G H I J K L]
time 164ms: Process E started using the CPU for 52ms burst [Q B C D F G H I J K L]
time 173ms: Process A (tau 78ms) completed I/O; added to ready queue [Q A B C D F G H I J K L]
time 216ms: Process E completed a CPU burst; 23 bursts to go [Q A B C D F G H I J K L]
time 216ms: Recalculated tau = 57ms for process E [Q A B C D F G H I J K L]
time 216ms: Process E switching out of CPU; will block on I/O until time 314ms [Q A B C D F G H I J K L]
time 220ms: Process A started using the CPU for 60ms burst [Q B C D F G H I J K L]
time 280ms: Process A completed a CPU burst; 14 bursts to go [Q B C D F G H I J K L]
time 280ms: Recalculated tau = 69ms for process A [Q B C D F G H I J K L]
time 280ms: Process A switching out of CPU; will block on I/O until time 435ms [Q B C D F G H I J K L]
time 284ms: Process B started using the CPU with 98ms remaining [Q C D F G H I J K L]
time 314ms: Process E (tau 57ms) completed I/O and will preempt B [Q C D F G H I J K L]
time 318ms: Process E started using the CPU for 199ms burst [Q B C D F G H I J K L]
time 435ms: Process A (tau 69ms) completed I/O; added to ready queue [Q B A C D F G H I J K L]
time 517ms: Process E completed a CPU burst; 22 bursts to go [Q B A C D F G H I J K L]
time 517ms: Recalculated tau = 128ms for process E [Q B A C D F G H I J K L]
time 517ms: Process E switching out of CPU; will block on I/O until time 529ms [Q B A C D F G H I J K L]
time 521ms: Process B started using the CPU with 68ms remaining [Q A C D F G H I J K L]
time 529ms: Process E (tau 128ms) completed I/O; added to ready queue [Q A C D F G H I J K L E]
time 589ms: Process B completed a CPU burst; 20 bursts to go [Q A C D F G H I J K L E]
time 589ms: Recalculated tau = 103ms for process B [Q A C D F G H I J K L E]
time 589ms: Process B switching out of CPU; will block on I/O until time 747ms [Q A C D F G H I J K L E]
time 593ms: Process A started using the CPU for 39ms burst [Q C D F G H I J K L E]
time 632ms: Process A completed a CPU burst; 13 bursts to go [Q C D F G H I J K L E]
time 632ms: Recalculated tau = 54ms for process A [Q C D F G H I J K L E]
time 632ms: Process A switching out of CPU; will block on I/O until time 684ms [Q C D F G H I J K L E]
time 636ms: Process C started using the CPU for 79ms burst [Q D F G H I J K L E]
time 684ms: Process A (tau 54ms) completed I/O; added to ready queue [Q A D F G H I J K L E]
time 715ms: Process C completed a CPU burst; 81 bursts to go [Q A D F G H I J K L E]
time 715ms: Recalculated tau = 90ms for process C [Q A D F G H I J K L E]
time 715ms: Process C switching out of CPU; will block on I/O until time 874ms [Q A D F G H I J K L E]
time 719ms: Process A started using the CPU for 47ms burst [Q D F G H I J K L E]
time 747ms: Process B (tau 103ms) completed I/O; added to ready queue [Q D F G H I J K L B E]
time 766ms: Process A completed a CPU burst; 12 bursts to go [Q D F G H I J K L B E]
time 766ms: Recalculated tau = 51ms for process A [Q D F G H I J K L B E]
time 766ms: Process A switching out of CPU; will block on I/O until time 770ms [Q D F G H I J K L B E]
time 770ms: Process D started using the CPU for 22ms burst [Q F G H I J K L B E]
time 770ms: Process A (tau 51ms) completed I/O and will preempt D [Q F G H I J K L B E]
time 774ms: Process A started using the CPU for 137ms burst [Q D F G H I J K L B E]
time 874ms: Process C (tau 90ms) completed I/O; added to ready queue [Q C D F G H I J K L B E]
time 911ms: Process A completed a CPU burst; 11 bursts to go [Q C D F G H I J K L B E]
time 911ms: Recalculated tau = 94ms for process A [Q C D F G H I J K L B E]
time 911ms: Process A switching out of CPU; will block on I/O until time 937ms [Q C D F G H I J K L B E]
time 915ms: Process C started using the CPU for 148ms burst [Q D F G H I J K L B E]
time 937ms: Process A (tau 94ms) completed I/O; added to ready queue [Q A D F G H I J K L B E]
time 4241ms: Process K terminated [Q L B J H F C A E D G I]
time 5448ms: Process A terminated [Q C F L E D H G I J B]
time 5738ms: Process L terminated [Q C F E D H G I J B]
time 18853ms: Process E terminated [Q I J F B]
time 18958ms: Process D terminated [Q C G I J F B]
time 22753ms: Process C terminated [Q I H J F B]
time 24405ms: Process F terminated [Q B G]
time 28392ms: Process J terminated [Q G H B I]
time 29208ms: Process H terminated [Q G B I]
time 31375ms: Process G terminated [Q I B]
time 31553ms: Process B terminated [Q <empty>]
time 36882ms: Process I terminated [Q <empty>]
time 36884ms: Simulator ended for SRT [Q <empty>]

Process A [NEW] (arrival time 9 ms) 16 CPU bursts
Process B [NEW] (arrival time 18 ms) 21 CPU bursts
Process C [NEW] (arrival time 84 ms) 82 CPU bursts
Process D [NEW] (arrival time 86 ms) 36 CPU bursts
Process E [NEW] (arrival time 2 ms) 26 CPU bursts
Process F [NEW] (arrival time 25 ms) 39 CPU bursts
Process G [NEW] (arrival time 13 ms) 76 CPU bursts
Process H [NEW] (arrival time 46 ms) 82 CPU bursts
Process I [NEW] (arrival time 64 ms) 63 CPU bursts
Process J [NEW] (arrival time 31 ms) 21 CPU bursts
Process K [NEW] (arrival time 56 ms) 1 CPU bursts
Process L [NEW] (arrival time 12 ms) 3 CPU bursts
time 0ms: Simulator started for FCFS [Q <empty>]
time 2ms: Process E arrived; added to ready queue [Q E]
time 4ms: Process E started using the CPU for 11ms burst [Q <empty>]
time 9ms: Process A arrived; added to ready queue [Q A]
time 12ms: Process L arrived; added to ready queue [Q A L]
time 13ms: Process G arrived; added to ready queue [Q A L G]
time 15ms: Process E completed a CPU burst; 25 bursts to go [Q A L G]
time 15ms: Process E switching out of CPU; will block on I/O until time 34ms [Q A L G]
time 18ms: Process B arrived; added to ready queue [Q L G B]
time 19ms: Process A started using the CPU for 56ms burst [Q L G B]
time 25ms: Process F arrived; added to ready queue [Q L G B F]
time 31ms: Process J arrived; added to ready queue [Q L G B F J]
time 34ms: Process E completed I/O; added to ready queue [Q L G B F J E]
time 46ms: Process H arrived; added to ready queue [Q L G B F J E H]
time 56ms: Process K arrived; added to ready queue [Q L G B F J E H K]
time 64ms: Process I arrived; added to ready queue [Q L G B F J E H K I]
time 75ms: Process A completed a CPU burst; 15 bursts to go [Q L G B F J E H K I]
time 75ms: Process A switching out of CPU; will block on I/O until time 100ms [Q L G B F J E H K I]
time 79ms: Process L started using the CPU for 133ms burst [Q G B F J E H K I]
time 84ms: Process C arrived; added to ready queue [Q G B F J E H K I C]
time 86ms: Process D arrived; added to ready queue [Q G B F J E H K I C D]
time 100ms: Process A completed I/O; added to ready queue [Q G B F J E H K I C D A]
time 212ms: Process L completed a CPU burst; 2 bursts to go [Q G B F J E H K I C D A]
time 212ms: Process L switching out of CPU; will block on I/O until time 344ms [Q G B F J E H K I C D A]
time 216ms: Process G started using the CPU for 76ms burst [Q B F J E H K I C D A]
time 292ms: Process G completed a CPU burst; 75 bursts to go [Q B F J E H K I C D A]
time 292ms: Process G switching out of CPU; will block on I/O until time 437ms [Q B F J E H K I C D A]
time 296ms: Process B started using the CPU for 106ms burst [Q F J E H K I C D A]
time 344ms: Process L completed I/O; added to ready queue [Q F J E H K I C D A L]
time 402ms: Process B completed a CPU burst; 20 bursts to go [Q F J E H K I C D A L]
time 402ms: Process B switching out of CPU; will block on I/O until time 560ms [Q F J E H K I C D A L]
time 406ms: Process F started using the CPU for 24ms burst [Q J E H K I C D A L]
time 430ms: Process F completed a CPU burst; 38 bursts to go [Q J E H K I C D A L]
time 430ms: Process F switching out of CPU; will block on I/O until time 498ms [Q J E H K I C D A L]
time 434ms: Process J started using the CPU for 97ms burst [Q E H K I C D A L]
time 437ms: Process G completed I/O; added to ready queue [Q E H K I C D A L G]
time 498ms: Process F completed I/O; added to ready queue [Q E H K I C D A L G F]
time 531ms: Process J completed a CPU burst; 20 bursts to go [Q E H K I C D A L G F]
time 531ms: Process J switching out of CPU; will block on I/O until time 624ms [Q E H K I C D A L G F]
time 535ms: Process E started using the CPU for 65ms burst [Q H K I C D A L G F]
time 560ms: Process B completed I/O; added to ready queue [Q H K I C D A L G F B]
time 600ms: Process E completed a CPU burst; 24 bursts to go [Q H K I C D A L G F B]
time 600ms: Process E switching out of CPU; will block on I/O until time 657ms [Q H K I C D A L G F B]
time 604ms: Process H started using the CPU for 9ms burst [Q K I C D A L G F B]
time 613ms: Process H completed a CPU burst; 81 bursts to go [Q K I C D A L G F B]
time 613ms: Process H switching out of CPU; will block on I/O until time 794ms [Q K I C D A L G F B]
time 617ms: Process K started using the CPU for 37ms burst [Q I C D A L G F B]
time 624ms: Process J completed I/O; added to ready queue [Q I C D A L G F B J]
time 654ms: Process K terminated [Q I C D A L G F B J]
time 657ms: Process E completed I/O; added to ready queue [Q C D A L G F B J E]
time 658ms: Process I started using the CPU for 190ms burst [Q C D A L G F B J E]
time 794ms: Process H completed I/O; added to ready queue [Q C D A L G F B J E H]
time 848ms: Process I completed a CPU burst; 62 bursts to go [Q C D A L G F B J E H]
time 848ms: Process I switching out of CPU; will block on I/O until time 985ms [Q C D A L G F B J E H]
time 852ms: Process C started using the CPU for 79ms burst [Q D A L G F B J E H]
time 931ms: Process C completed a CPU burst; 81 bursts to go [Q D A L G F B J E H]
time 931ms: Process C switching out of CPU; will block on I/O until time 1090ms [Q D A L G F B J E H]
time 935ms: Process D started using the CPU for 22ms burst [Q A L G F B J E H]
time 957ms: Process D completed a CPU burst; 35 bursts to go [Q A L G F B J E H]
time 957ms: Process D switching out of CPU; will block on I/O until time 974ms [Q A L G F B J E H]
time 961ms: Process A started using the CPU for 60ms burst [Q L G F B J E H]
time 974ms: Process D completed I/O; added to ready queue [Q L G F B J E H D]
time 985ms: Process I completed I/O; added to ready queue [Q L G F B J E H D I]
time 2115ms: Process L terminated [Q A G F J B E D H I C]
time 12237ms: Process A terminated [Q H G I D E J C F B]
time 15661ms: Process B terminated [Q C D H I J]
time 15965ms: Process J terminated [Q F E G C D H I]
time 18021ms: Process E terminated [Q G D I C]
time 21907ms: Process D terminated [Q I H C G F]
time 23102ms: Process F terminated [Q C I]
time 31040ms: Process I terminated [Q G C H]
time 33199ms: Process G terminated [Q H C]
time 33599ms: Process C terminated [Q <empty>]
time 33805ms: Process H terminated [Q <empty>]
time 33807ms: Simulator ended for FCFS [Q <empty>]

Process A [NEW] (arrival time 9 ms) 16 CPU bursts
Process B [NEW] (arrival time 18 ms) 21 CPU bursts
Process C [NEW] (arrival time 84 ms) 82 CPU bursts
Process D [NEW] (arrival time 86 ms) 36 CPU bursts
Process E [NEW] (arrival time 2 ms) 26 CPU bursts
Process F [NEW] (arrival time 25 ms) 39 CPU bursts
Process G [NEW] (arrival time 13 ms) 76 CPU bursts
Process H [NEW] (arrival time 46 ms) 82 CPU bursts
Process I [NEW] (arrival time 64 ms) 63 CPU bursts
Process J [NEW] (arrival time 31 ms) 21 CPU bursts
Process K [NEW] (arrival time 56 ms) 1 CPU bursts
Process L [NEW] (arrival time 12 ms) 3 CPU bursts
time 0ms: Simulator started for RR [Q <empty>]
time 2ms: Process E arrived; added to ready queue [Q E]
time 4ms: Process E started using the CPU for 11ms burst [Q <empty>]
time 9ms: Process A arrived; added to ready queue [Q A]
time 12ms: Process L arrived; added to ready queue [Q A L]
time 13ms: Process G arrived; added to ready queue [Q A L G]
time 15ms: Process E completed a CPU burst; 25 bursts to go [Q A L G]
time 15ms: Process E switching out of CPU; will block on I/O until time 34ms [Q A L G]
time 18ms: Process B arrived; added to ready queue [Q L G B]
time 19ms: Process A started using the CPU for 56ms burst [Q L G B]
time 25ms: Process F arrived; added to ready queue [Q L G B F]
time 31ms: Process J arrived; added to ready queue [Q L G B F J]
time 34ms: Process E completed I/O; added to ready queue [Q L G B F J E]
time 46ms: Process H arrived; added to ready queue [Q L G B F J E H]
time 56ms: Process K arrived; added to ready queue [Q L G B F J E H K]
time 64ms: Process I arrived; added to ready queue [Q L G B F J E H K I]
time 75ms: Process A completed a CPU burst; 15 bursts to go [Q L G B F J E H K I]
time 75ms: Process A switching out of CPU; will block on I/O until time 100ms [Q L G B F J E H K I]
time 79ms: Process L started using the CPU for 133ms burst [Q G B F J E H K I]
time 84ms: Process C arrived; added to ready queue [Q G B F J E H K I C]
time 86ms: Process D arrived; added to ready queue [Q G B F J E H K I C D]
time 100ms: Process A completed I/O; added to ready queue [Q G B F J E H K I C D A]
time 199ms: Time slice expired; process L preempted with 13ms to go [Q G B F J E H K I C D A]
time 203ms: Process G started using the CPU for 76ms burst [Q B F J E H K I C D A L]
time 279ms: Process G completed a CPU burst; 75 bursts to go [Q B F J E H K I C D A L]
time 279ms: Process G switching out of CPU; will block on I/O until time 424ms [Q B F J E H K I C D A L]
time 283ms: Process B started using the CPU for 106ms burst [Q F J E H K I C D A L]
time 389ms: Process B completed a CPU burst; 20 bursts to go [Q F J E H K I C D A L]
time 389ms: Process B switching out of CPU; will block on I/O until time 547ms [Q F J E H K I C D A L]
time 393ms: Process F started using the CPU for 24ms burst [Q J E H K I C D A L]
time 417ms: Process F completed a CPU burst; 38 bursts to go [Q J E H K I C D A L]
time 417ms: Process F switching out of CPU; will block on I/O until time 485ms [Q J E H K I C D A L]
time 421ms: Process J started using the CPU for 97ms burst [Q E H K I C D A L]
time 424ms: Process G completed I/O; added to ready queue [Q E H K I C D A L G]
time 485ms: Process F completed I/O; added to ready queue [Q E H K I C D A L G F]
time 518ms: Process J completed a CPU burst; 20 bursts to go [Q E H K I C D A L G F]
time 518ms: Process J switching out of CPU; will block on I/O until time 611ms [Q E H K I C D A L G F]
time 522ms: Process E started using the CPU for 65ms burst [Q H K I C D A L G F]
time 547ms: Process B completed I/O; added to ready queue [Q H K I C D A L G F B]
time 587ms: Process E completed a CPU burst; 24 bursts to go [Q H K I C D A L G F B]
time 587ms: Process E switching out of CPU; will block on I/O until time 644ms [Q H K I C D A L G F B]
time 591ms: Process H started using the CPU for 9ms burst [Q K I C D A L G F B]
time 600ms: Process H completed a CPU burst; 81 bursts to go [Q K I C D A L G F B]
time 600ms: Process H switching out of CPU; will block on I/O until time 781ms [Q K I C D A L G F B]
time 604ms: Process K started using the CPU for 37ms burst [Q I C D A L G F B]
time 611ms: Process J completed I/O; added to ready queue [Q I C D A L G F B J]
time 641ms: Process K terminated [Q I C D A L G F B J]
time 644ms: Process E completed I/O; added to ready queue [Q C D A L G F B J E]
time 645ms: Process I started using the CPU for 190ms burst [Q C D A L G F B J E]
time 765ms: Time slice expired; process I preempted with 70ms to go [Q C D A L G F B J E]
time 769ms: Process C started using the CPU for 79ms burst [Q D A L G F B J E I]
time 781ms: Process H completed I/O; added to ready queue [Q D A L G F B J E I H]
time 848ms: Process C completed a CPU burst; 81 bursts to go [Q D A L G F B J E I H]
time 848ms: Process C switching out of CPU; will block on I/O until time 1007ms [Q D A L G F B J E I H]
time 852ms: Process D started using the CPU for 22ms burst [Q A L G F B J E I H]
time 874ms: Process D completed a CPU burst; 35 bursts to go [Q A L G F B J E I H]
time 874ms: Process D switching out of CPU; will block on I/O until time 891ms [Q A L G F B J E I H]
time 878ms: Process A started using the CPU for 60ms burst [Q L G F B J E I H]
time 891ms: Process D completed I/O; added to ready queue [Q L G F B J E I H D]
time 938ms: Process A completed a CPU burst; 14 bursts to go [Q L G F B J E I H D]
time 938ms: Process A switching out of CPU; will block on I/O until time 1093ms [Q L G F B J E I H D]
time 942ms: Process L started using the CPU with 13ms remaining [Q G F B J E I H D]
time 955ms: Process L completed a CPU burst; 2 bursts to go [Q G F B J E I H D]
time 955ms: Process L switching out of CPU; will block on I/O until time 1087ms [Q G F B J E I H D]
time 959ms: Process G started using the CPU for 184ms burst [Q F B J E I H D]
time 2647ms: Process L terminated [Q A F B J E I D C H G]
time 13066ms: Process A terminated [Q G D C E B H F J]
time 16561ms: Process J terminated [Q B G C F E D I H]
time 17513ms: Process B terminated [Q I E G C H D]
time 18875ms: Process E terminated [Q F G I]
time 22538ms: Process D terminated [Q G F I C]
time 23420ms: Process F terminated [Q I G C]
time 30762ms: Process I terminated [Q H]
time 33583ms: Process G terminated [Q H C]
time 34078ms: Process H terminated [Q C]
time 34342ms: Process C terminated [Q <empty>]
time 34344ms: Simulator ended for RR [Q <empty>]
