Process A [NEW] (arrival time 9 ms) 16 CPU bursts
Process B [NEW] (arrival time 18 ms) 21 CPU bursts
time 0ms: Simulator started for SJF [Q <empty>]
time 9ms: Process A (tau 100ms) arrived; added to ready queue [Q A]
time 11ms: Process A started using the CPU for 56ms burst [Q <empty>]
time 18ms: Process B (tau 100ms) arrived; added to ready queue [Q B]
time 67ms: Process A completed a CPU burst; 15 bursts to go [Q B]
time 67ms: Recalculated tau = 78ms for process A [Q B]
time 67ms: Process A switching out of CPU; will block on I/O until time 92ms [Q B]
time 71ms: Process B started using the CPU for 106ms burst [Q <empty>]
time 92ms: Process A (tau 78ms) completed I/O; added to ready queue [Q A]
time 177ms: Process B completed a CPU burst; 20 bursts to go [Q A]
time 177ms: Recalculated tau = 103ms for process B [Q A]
time 177ms: Process B switching out of CPU; will block on I/O until time 335ms [Q A]
time 181ms: Process A started using the CPU for 60ms burst [Q <empty>]
time 241ms: Process A completed a CPU burst; 14 bursts to go [Q <empty>]
time 241ms: Recalculated tau = 69ms for process A [Q <empty>]
time 241ms: Process A switching out of CPU; will block on I/O until time 396ms [Q <empty>]
time 335ms: Process B (tau 103ms) completed I/O; added to ready queue [Q B]
time 337ms: Process B started using the CPU for 198ms burst [Q <empty>]
time 396ms: Process A (tau 69ms) completed I/O; added to ready queue [Q A]
time 535ms: Process B completed a CPU burst; 19 bursts to go [Q A]
time 535ms: Recalculated tau = 151ms for process B [Q A]
time 535ms: Process B switching out of CPU; will block on I/O until time 650ms [Q A]
time 539ms: Process A started using the CPU for 39ms burst [Q <empty>]
time 578ms: Process A completed a CPU burst; 13 bursts to go [Q <empty>]
time 578ms: Recalculated tau = 54ms for process A [Q <empty>]
time 578ms: Process A switching out of CPU; will block on I/O until time 630ms [Q <empty>]
time 630ms: Process A (tau 54ms) completed I/O; added to ready queue [Q A]
time 632ms: Process A started using the CPU for 47ms burst [Q <empty>]
time 650ms: Process B (tau 151ms) completed I/O; added to ready queue [Q B]
time 679ms: Process A completed a CPU burst; 12 bursts to go [Q B]
time 679ms: Recalculated tau = 51ms for process A [Q B]
time 679ms: Process A switching out of CPU; will block on I/O until time 683ms [Q B]
time 683ms: Process B started using the CPU for 162ms burst [Q <empty>]
time 683ms: Process A (tau 51ms) completed I/O; added to ready queue [Q A]
time 845ms: Process B completed a CPU burst; 18 bursts to go [Q A]
time 845ms: Recalculated tau = 157ms for process B [Q A]
time 845ms: Process B switching out of CPU; will block on I/O until time 897ms [Q A]
time 849ms: Process A started using the CPU for 137ms burst [Q <empty>]
time 897ms: Process B (tau 157ms) completed I/O; added to ready queue [Q B]
time 986ms: Process A completed a CPU burst; 11 bursts to go [Q B]
time 986ms: Recalculated tau = 94ms for process A [Q B]
time 986ms: Process A switching out of CPU; will block on I/O until time 1012ms [Q B]
time 990ms: Process B started using the CPU for 46ms burst [Q <empty>]
time 1012ms: Process A (tau 94ms) completed I/O; added to ready queue [Q A]
time 1036ms: Process B completed a CPU burst; 17 bursts to go [Q A]
time 1036ms: Recalculated tau = 102ms for process B [Q A]
time 1036ms: Process B switching out of CPU; will block on I/O until time 1120ms [Q A]
time 1040ms: Process A started using the CPU for 64ms burst [Q <empty>]
time 1104ms: Process A completed a CPU burst; 10 bursts to go [Q <empty>]
time 1104ms: Recalculated tau = 79ms for process A [Q <empty>]
time 1104ms: Process A switching out of CPU; will block on I/O until time 1121ms [Q <empty>]
time 1120ms: Process B (tau 102ms) completed I/O; added to ready queue [Q B]
time 1121ms: Process A (tau 79ms) completed I/O; added to ready queue [Q A]
time 1122ms: Process B started using the CPU for 16ms burst [Q A]
time 1138ms: Process B completed a CPU burst; 16 bursts to go [Q A]
time 1138ms: Recalculated tau = 59ms for process B [Q A]
time 1138ms: Process B switching out of CPU; will block on I/O until time 1147ms [Q A]
time 1142ms: Process A started using the CPU for 68ms burst [Q <empty>]
time 1147ms: Process B (tau 59ms) completed I/O; added to ready queue [Q B]
time 1210ms: Process A completed a CPU burst; 9 bursts to go [Q B]
time 1210ms: Recalculated tau = 74ms for process A [Q B]
time 1210ms: Process A switching out of CPU; will block on I/O until time 1276ms [Q B]
time 1214ms: Process B started using the CPU for 30ms burst [Q <empty>]
time 1244ms: Process B completed a CPU burst; 15 bursts to go [Q <empty>]
time 1244ms: Recalculated tau = 45ms for process B [Q <empty>]
time 1244ms: Process B switching out of CPU; will block on I/O until time 1298ms [Q <empty>]
time 1276ms: Process A (tau 74ms) completed I/O; added to ready queue [Q A]
time 1278ms: Process A started using the CPU for 113ms burst [Q <empty>]
time 1298ms: Process B (tau 45ms) completed I/O; added to ready queue [Q B]
time 1391ms: Process A completed a CPU burst; 8 bursts to go [Q B]
time 1391ms: Recalculated tau = 94ms for process A [Q B]
time 1391ms: Process A switching out of CPU; will block on I/O until time 1409ms [Q B]
time 1395ms: Process B started using the CPU for 12ms burst [Q <empty>]
time 1407ms: Process B completed a CPU burst; 14 bursts to go [Q <empty>]
time 1407ms: Recalculated tau = 29ms for process B [Q <empty>]
time 1407ms: Process B switching out of CPU; will block on I/O until time 1486ms [Q <empty>]
time 1409ms: Process A (tau 94ms) completed I/O; added to ready queue [Q A]
time 1411ms: Process A started using the CPU for 11ms burst [Q <empty>]
time 1422ms: Process A completed a CPU burst; 7 bursts to go [Q <empty>]
time 1422ms: Recalculated tau = 53ms for process A [Q <empty>]
time 1422ms: Process A switching out of CPU; will block on I/O until time 1586ms [Q <empty>]
time 1486ms: Process B (tau 29ms) completed I/O; added to ready queue [Q B]
time 1488ms: Process B started using the CPU for 138ms burst [Q <empty>]
time 1586ms: Process A (tau 53ms) completed I/O; added to ready queue [Q A]
time 1626ms: Process B completed a CPU burst; 13 bursts to go [Q A]
time 1626ms: Recalculated tau = 84ms for process B [Q A]
time 1626ms: Process B switching out of CPU; will block on I/O until time 1710ms [Q A]
time 1630ms: Process A started using the CPU for 24ms burst [Q <empty>]
time 1654ms: Process A completed a CPU burst; 6 bursts to go [Q <empty>]
time 1654ms: Recalculated tau = 39ms for process A [Q <empty>]
time 1654ms: Process A switching out of CPU; will block on I/O until time 1773ms [Q <empty>]
time 1710ms: Process B (tau 84ms) completed I/O; added to ready queue [Q B]
time 1712ms: Process B started using the CPU for 67ms burst [Q <empty>]
time 1773ms: Process A (tau 39ms) completed I/O; added to ready queue [Q A]
time 1779ms: Process B completed a CPU burst; 12 bursts to go [Q A]
time 1779ms: Recalculated tau = 76ms for process B [Q A]
time 1779ms: Process B switching out of CPU; will block on I/O until time 1788ms [Q A]
time 1783ms: Process A started using the CPU for 76ms burst [Q <empty>]
time 1788ms: Process B (tau 76ms) completed I/O; added to ready queue [Q B]
time 1859ms: Process A completed a CPU burst; 5 bursts to go [Q B]
time 1859ms: Recalculated tau = 58ms for process A [Q B]
time 1859ms: Process A switching out of CPU; will block on I/O until time 1889ms [Q B]
time 1863ms: Process B started using the CPU for 120ms burst [Q <empty>]
time 1889ms: Process A (tau 58ms) completed I/O; added to ready queue [Q A]
time 1983ms: Process B completed a CPU burst; 11 bursts to go [Q A]
time 1983ms: Recalculated tau = 98ms for process B [Q A]
time 1983ms: Process B switching out of CPU; will block on I/O until time 1998ms [Q A]
time 1987ms: Process A started using the CPU for 122ms burst [Q <empty>]
time 1998ms: Process B (tau 98ms) completed I/O; added to ready queue [Q B]
time 2109ms: Process A completed a CPU burst; 4 bursts to go [Q B]
time 2109ms: Recalculated tau = 90ms for process A [Q B]
time 2109ms: Process A switching out of CPU; will block on I/O until time 2144ms [Q B]
time 2113ms: Process B started using the CPU for 49ms burst [Q <empty>]
time 2144ms: Process A (tau 90ms) completed I/O; added to ready queue [Q A]
time 2162ms: Process B completed a CPU burst; 10 bursts to go [Q A]
time 2162ms: Recalculated tau = 74ms for process B [Q A]
time 2162ms: Process B switching out of CPU; will block on I/O until time 2206ms [Q A]
time 2166ms: Process A started using the CPU for 9ms burst [Q <empty>]
time 2175ms: Process A completed a CPU burst; 3 bursts to go [Q <empty>]
time 2175ms: Recalculated tau = 50ms for process A [Q <empty>]
time 2175ms: Process A switching out of CPU; will block on I/O until time 2245ms [Q <empty>]
time 2206ms: Process B (tau 74ms) completed I/O; added to ready queue [Q B]
time 2208ms: Process B started using the CPU for 134ms burst [Q <empty>]
time 2245ms: Process A (tau 50ms) completed I/O; added to ready queue [Q A]
time 2342ms: Process B completed a CPU burst; 9 bursts to go [Q A]
time 2342ms: Recalculated tau = 104ms for process B [Q A]
time 2342ms: Process B switching out of CPU; will block on I/O until time 2376ms [Q A]
time 2346ms: Process A started using the CPU for 62ms burst [Q <empty>]
time 2376ms: Process B (tau 104ms) completed I/O; added to ready queue [Q B]
time 2408ms: Process A completed a CPU burst; 2 bursts to go [Q B]
time 2408ms: Recalculated tau = 56ms for process A [Q B]
time 2408ms: Process A switching out of CPU; will block on I/O until time 2487ms [Q B]
time 2412ms: Process B started using the CPU for 144ms burst [Q <empty>]
time 2487ms: Process A (tau 56ms) completed I/O; added to ready queue [Q A]
time 2556ms: Process B completed a CPU burst; 8 bursts to go [Q A]
time 2556ms: Recalculated tau = 124ms for process B [Q A]
time 2556ms: Process B switching out of CPU; will block on I/O until time 2637ms [Q A]
time 2560ms: Process A started using the CPU for 200ms burst [Q <empty>]
time 2637ms: Process B (tau 124ms) completed I/O; added to ready queue [Q B]
time 2760ms: Process A completed a CPU burst; 1 burst to go [Q B]
time 2760ms: Recalculated tau = 128ms for process A [Q B]
time 2760ms: Process A switching out of CPU; will block on I/O until time 2773ms [Q B]
time 2764ms: Process B started using the CPU for 183ms burst [Q <empty>]
time 2773ms: Process A (tau 128ms) completed I/O; added to ready queue [Q A]
time 2947ms: Process B completed a CPU burst; 7 bursts to go [Q A]
time 2947ms: Recalculated tau = 154ms for process B [Q A]
time 2947ms: Process B switching out of CPU; will block on I/O until time 2955ms [Q A]
time 2951ms: Process A started using the CPU for 197ms burst [Q <empty>]
time 2955ms: Process B (tau 154ms) completed I/O; added to ready queue [Q B]
time 3148ms: Process A terminated [Q B]
time 3152ms: Process B started using the CPU for 23ms burst [Q <empty>]
time 3175ms: Process B completed a CPU burst; 6 bursts to go [Q <empty>]
time 3175ms: Recalculated tau = 89ms for process B [Q <empty>]
time 3175ms: Process B switching out of CPU; will block on I/O until time 3241ms [Q <empty>]
time 3241ms: Process B (tau 89ms) completed I/O; added to ready queue [Q B]
time 3243ms: Process B started using the CPU for 80ms burst [Q <empty>]
time 3323ms: Process B completed a CPU burst; 5 bursts to go [Q <empty>]
time 3323ms: Recalculated tau = 85ms for process B [Q <empty>]
time 3323ms: Process B switching out of CPU; will block on I/O until time 3358ms [Q <empty>]
time 3358ms: Process B (tau 85ms) completed I/O; added to ready queue [Q B]
time 3360ms: Process B started using the CPU for 74ms burst [Q <empty>]
time 3434ms: Process B completed a CPU burst; 4 bursts to go [Q <empty>]
time 3434ms: Recalculated tau = 80ms for process B [Q <empty>]
time 3434ms: Process B switching out of CPU; will block on I/O until time 3499ms [Q <empty>]
time 3499ms: Process B (tau 80ms) completed I/O; added to ready queue [Q B]
time 3501ms: Process B started using the CPU for 170ms burst [Q <empty>]
time 3671ms: Process B completed a CPU burst; 3 bursts to go [Q <empty>]
time 3671ms: Recalculated tau = 125ms for process B [Q <empty>]
time 3671ms: Process B switching out of CPU; will block on I/O until time 3730ms [Q <empty>]
time 3730ms: Process B (tau 125ms) completed I/O; added to ready queue [Q B]
time 3732ms: Process B started using the CPU for 43ms burst [Q <empty>]
time 3775ms: Process B completed a CPU burst; 2 bursts to go [Q <empty>]
time 3775ms: Recalculated tau = 84ms for process B [Q <empty>]
time 3775ms: Process B switching out of CPU; will block on I/O until time 3871ms [Q <empty>]
time 3871ms: Process B (tau 84ms) completed I/O; added to ready queue [Q B]
time 3873ms: Process B started using the CPU for 158ms burst [Q <empty>]
time 4031ms: Process B completed a CPU burst; 1 burst to go [Q <empty>]
time 4031ms: Recalculated tau = 121ms for process B [Q <empty>]
time 4031ms: Process B switching out of CPU; will block on I/O until time 4150ms [Q <empty>]
time 4150ms: Process B (tau 121ms) completed I/O; added to ready queue [Q B]
time 4152ms: Process B started using the CPU for 17ms burst [Q <empty>]
time 4169ms: Process B terminated [Q <empty>]
time 4171ms: Simulator ended for SJF [Q <empty>]

Process A [NEW] (arrival time 9 ms) 16 CPU bursts
Process B [NEW] (arrival time 18 ms) 21 CPU bursts
time 0ms: Simulator started for SRT [Q <empty>]
time 9ms: Process A (tau 100ms) arrived; added to ready queue [Q A]
time 11ms: Process A started using the CPU for 56ms burst [Q <empty>]
time 18ms: Process B (tau 100ms) arrived; added to ready queue [Q B]
time 67ms: Process A completed a CPU burst; 15 bursts to go [Q B]
time 67ms: Recalculated tau = 78ms for process A [Q B]
time 67ms: Process A switching out of CPU; will block on I/O until time 92ms [Q B]
time 71ms: Process B started using the CPU for 106ms burst [Q <empty>]
time 92ms: Process A (tau 78ms) completed I/O and will preempt B [Q <empty>]
time 96ms: Process A started using the CPU for 60ms burst [Q B]
time 156ms: Process A completed a CPU burst; 14 bursts to go [Q B]
time 156ms: Recalculated tau = 69ms for process A [Q B]
time 156ms: Process A switching out of CPU; will block on I/O until time 311ms [Q B]
time 160ms: Process B started using the CPU with 85ms remaining [Q <empty>]
time 245ms: Process B completed a CPU burst; 20 bursts to go [Q <empty>]
time 245ms: Recalculated tau = 103ms for process B [Q <empty>]
time 245ms: Process B switching out of CPU; will block on I/O until time 403ms [Q <empty>]
time 311ms: Process A (tau 69ms) completed I/O; added to ready queue [Q A]
time 313ms: Process A started using the CPU for 39ms burst [Q <empty>]
time 352ms: Process A completed a CPU burst; 13 bursts to go [Q <empty>]
time 352ms: Recalculated tau = 54ms for process A [Q <empty>]
time 352ms: Process A switching out of CPU; will block on I/O until time 404ms [Q <empty>]
time 403ms: Process B (tau 103ms) completed I/O; added to ready queue [Q B]
time 404ms: Process A (tau 54ms) completed I/O; added to ready queue [Q A]
time 405ms: Process B started using the CPU for 198ms burst [Q A]
time 405ms: Process A (tau 54ms) will preempt B [Q A]
time 409ms: Process A started using the CPU for 47ms burst [Q B]
time 456ms: Process A completed a CPU burst; 12 bursts to go [Q B]
time 456ms: Recalculated tau = 51ms for process A [Q B]
time 456ms: Process A switching out of CPU; will block on I/O until time 460ms [Q B]
time 460ms: Process B started using the CPU for 198ms burst [Q <empty>]
time 460ms: Process A (tau 51ms) completed I/O and will preempt B [Q <empty>]
time 464ms: Process A started using the CPU for 137ms burst [Q B]
time 601ms: Process A completed a CPU burst; 11 bursts to go [Q B]
time 601ms: Recalculated tau = 94ms for process A [Q B]
time 601ms: Process A switching out of CPU; will block on I/O until time 627ms [Q B]
time 605ms: Process B started using the CPU for 198ms burst [Q <empty>]
time 627ms: Process A (tau 94ms) completed I/O; added to ready queue [Q A]
time 803ms: Process B completed a CPU burst; 19 bursts to go [Q A]
time 803ms: Recalculated tau = 151ms for process B [Q A]
time 803ms: Process B switching out of CPU; will block on I/O until time 918ms [Q A]
time 807ms: Process A started using the CPU for 64ms burst [Q <empty>]
time 871ms: Process A completed a CPU burst; 10 bursts to go [Q <empty>]
time 871ms: Recalculated tau = 79ms for process A [Q <empty>]
time 871ms: Process A switching out of CPU; will block on I/O until time 888ms [Q <empty>]
time 888ms: Process A (tau 79ms) completed I/O; added to ready queue [Q A]
time 890ms: Process A started using the CPU for 68ms burst [Q <empty>]
time 918ms: Process B (tau 151ms) completed I/O; added to ready queue [Q B]
time 958ms: Process A completed a CPU burst; 9 bursts to go [Q B]
time 958ms: Recalculated tau = 74ms for process A [Q B]
time 958ms: Process A switching out of CPU; will block on I/O until time 1024ms [Q B]
time 962ms: Process B started using the CPU for 162ms burst [Q <empty>]
time 1024ms: Process A (tau 74ms) completed I/O and will preempt B [Q <empty>]
time 1028ms: Process A started using the CPU for 113ms burst [Q B]
time 1141ms: Process A completed a CPU burst; 8 bursts to go [Q B]
time 1141ms: Recalculated tau = 94ms for process A [Q B]
time 1141ms: Process A switching out of CPU; will block on I/O until time 1159ms [Q B]
time 1145ms: Process B started using the CPU with 100ms remaining [Q <empty>]
time 1159ms: Process A (tau 94ms) completed I/O; added to ready queue [Q A]
time 1245ms: Process B completed a CPU burst; 18 bursts to go [Q A]
time 1245ms: Recalculated tau = 157ms for process B [Q A]
time 1245ms: Process B switching out of CPU; will block on I/O until time 1297ms [Q A]
time 1249ms: Process A started using the CPU for 11ms burst [Q <empty>]
time 1260ms: Process A completed a CPU burst; 7 bursts to go [Q <empty>]
time 1260ms: Recalculated tau = 53ms for process A [Q <empty>]
time 1260ms: Process A switching out of CPU; will block on I/O until time 1424ms [Q <empty>]
time 1297ms: Process B (tau 157ms) completed I/O; added to ready queue [Q B]
time 1299ms: Process B started using the CPU for 46ms burst [Q <empty>]
time 1345ms: Process B completed a CPU burst; 17 bursts to go [Q <empty>]
time 1345ms: Recalculated tau = 102ms for process B [Q <empty>]
time 1345ms: Process B switching out of CPU; will block on I/O until time 1429ms [Q <empty>]
time 1424ms: Process A (tau 53ms) completed I/O; added to ready queue [Q A]
time 1426ms: Process A started using the CPU for 24ms burst [Q <empty>]
time 1429ms: Process B (tau 102ms) completed I/O; added to ready queue [Q B]
time 1450ms: Process A completed a CPU burst; 6 bursts to go [Q B]
time 1450ms: Recalculated tau = 39ms for process A [Q B]
time 1450ms: Process A switching out of CPU; will block on I/O until time 1569ms [Q B]
time 1454ms: Process B started using the CPU for 16ms burst [Q <empty>]
time 1470ms: Process B completed a CPU burst; 16 bursts to go [Q <empty>]
time 1470ms: Recalculated tau = 59ms for process B [Q <empty>]
time 1470ms: Process B switching out of CPU; will block on I/O until time 1479ms [Q <empty>]
time 1479ms: Process B (tau 59ms) completed I/O; added to ready queue [Q B]
time 1481ms: Process B started using the CPU for 30ms burst [Q <empty>]
time 1511ms: Process B completed a CPU burst; 15 bursts to go [Q <empty>]
time 1511ms: Recalculated tau = 45ms for process B [Q <empty>]
time 1511ms: Process B switching out of CPU; will block on I/O until time 1565ms [Q <empty>]
time 1565ms: Process B (tau 45ms) completed I/O; added to ready queue [Q B]
time 1567ms: Process B started using the CPU for 12ms burst [Q <empty>]
time 1569ms: Process A (tau 39ms) completed I/O and will preempt B [Q <empty>]
time 1573ms: Process A started using the CPU for 76ms burst [Q B]
time 1649ms: Process A completed a CPU burst; 5 bursts to go [Q B]
time 1649ms: Recalculated tau = 58ms for process A [Q B]
time 1649ms: Process A switching out of CPU; will block on I/O until time 1679ms [Q B]
time 1653ms: Process B started using the CPU with 10ms remaining [Q <empty>]
time 1663ms: Process B completed a CPU burst; 14 bursts to go [Q <empty>]
time 1663ms: Recalculated tau = 29ms for process B [Q <empty>]
time 1663ms: Process B switching out of CPU; will block on I/O until time 1742ms [Q <empty>]
time 1679ms: Process A (tau 58ms) completed I/O; added to ready queue [Q A]
time 1681ms: Process A started using the CPU for 122ms burst [Q <empty>]
time 1742ms: Process B (tau 29ms) completed I/O; added to ready queue [Q B]
time 1803ms: Process A completed a CPU burst; 4 bursts to go [Q B]
time 1803ms: Recalculated tau = 90ms for process A [Q B]
time 1803ms: Process A switching out of CPU; will block on I/O until time 1838ms [Q B]
time 1807ms: Process B started using the CPU for 138ms burst [Q <empty>]
time 1838ms: Process A (tau 90ms) completed I/O; added to ready queue [Q A]
time 1945ms: Process B completed a CPU burst; 13 bursts to go [Q A]
time 1945ms: Recalculated tau = 84ms for process B [Q A]
time 1945ms: Process B switching out of CPU; will block on I/O until time 2029ms [Q A]
time 1949ms: Process A started using the CPU for 9ms burst [Q <empty>]
time 1958ms: Process A completed a CPU burst; 3 bursts to go [Q <empty>]
time 1958ms: Recalculated tau = 50ms for process A [Q <empty>]
time 1958ms: Process A switching out of CPU; will block on I/O until time 2028ms [Q <empty>]
time 2028ms: Process A (tau 50ms) completed I/O; added to ready queue [Q A]
time 2029ms: Process B (tau 84ms) completed I/O; added to ready queue [Q B]
time 2030ms: Process A started using the CPU for 62ms burst [Q B]
time 2092ms: Process A completed a CPU burst; 2 bursts to go [Q B]
time 2092ms: Recalculated tau = 56ms for process A [Q B]
time 2092ms: Process A switching out of CPU; will block on I/O until time 2171ms [Q B]
time 2096ms: Process B started using the CPU for 67ms burst [Q <empty>]
time 2163ms: Process B completed a CPU burst; 12 bursts to go [Q <empty>]
time 2163ms: Recalculated tau = 76ms for process B [Q <empty>]
time 2163ms: Process B switching out of CPU; will block on I/O until time 2172ms [Q <empty>]
time 2171ms: Process A (tau 56ms) completed I/O; added to ready queue [Q A]
time 2172ms: Process B (tau 76ms) completed I/O; added to ready queue [Q B]
time 2173ms: Process A started using the CPU for 200ms burst [Q B]
time 2373ms: Process A completed a CPU burst; 1 burst to go [Q B]
time 2373ms: Recalculated tau = 128ms for process A [Q B]
time 2373ms: Process A switching out of CPU; will block on I/O until time 2386ms [Q B]
time 2377ms: Process B started using the CPU for 120ms burst [Q <empty>]
time 2386ms: Process A (tau 128ms) completed I/O; added to ready queue [Q A]
time 2497ms: Process B completed a CPU burst; 11 bursts to go [Q A]
time 2497ms: Recalculated tau = 98ms for process B [Q A]
time 2497ms: Process B switching out of CPU; will block on I/O until time 2512ms [Q A]
time 2501ms: Process A started using the CPU for 197ms burst [Q <empty>]
time 2512ms: Process B (tau 98ms) completed I/O and will preempt A [Q <empty>]
time 2516ms: Process B started using the CPU for 49ms burst [Q A]
time 2565ms: Process B completed a CPU burst; 10 bursts to go [Q A]
time 2565ms: Recalculated tau = 74ms for process B [Q A]
time 2565ms: Process B switching out of CPU; will block on I/O until time 2609ms [Q A]
time 2569ms: Process A started using the CPU with 186ms remaining [Q <empty>]
time 2609ms: Process B (tau 74ms) completed I/O and will preempt A [Q <empty>]
time 2613ms: Process B started using the CPU for 134ms burst [Q A]
time 2747ms: Process B completed a CPU burst; 9 bursts to go [Q A]
time 2747ms: Recalculated tau = 104ms for process B [Q A]
time 2747ms: Process B switching out of CPU; will block on I/O until time 2781ms [Q A]
time 2751ms: Process A started using the CPU with 146ms remaining [Q <empty>]
time 2781ms: Process B (tau 104ms) completed I/O; added to ready queue [Q B]
time 2897ms: Process A terminated [Q B]
time 2901ms: Process B started using the CPU for 144ms burst [Q <empty>]
time 3045ms: Process B completed a CPU burst; 8 bursts to go [Q <empty>]
time 3045ms: Recalculated tau = 124ms for process B [Q <empty>]
time 3045ms: Process B switching out of CPU; will block on I/O until time 3126ms [Q <empty>]
time 3126ms: Process B (tau 124ms) completed I/O; added to ready queue [Q B]
time 3128ms: Process B started using the CPU for 183ms burst [Q <empty>]
time 3311ms: Process B completed a CPU burst; 7 bursts to go [Q <empty>]
time 3311ms: Recalculated tau = 154ms for process B [Q <empty>]
time 3311ms: Process B switching out of CPU; will block on I/O until time 3319ms [Q <empty>]
time 3319ms: Process B (tau 154ms) completed I/O; added to ready queue [Q B]
time 3321ms: Process B started using the CPU for 23ms burst [Q <empty>]
time 3344ms: Process B completed a CPU burst; 6 bursts to go [Q <empty>]
time 3344ms: Recalculated tau = 89ms for process B [Q <empty>]
time 3344ms: Process B switching out of CPU; will block on I/O until time 3410ms [Q <empty>]
time 3410ms: Process B (tau 89ms) completed I/O; added to ready queue [Q B]
time 3412ms: Process B started using the CPU for 80ms burst [Q <empty>]
time 3492ms: Process B completed a CPU burst; 5 bursts to go [Q <empty>]
time 3492ms: Recalculated tau = 85ms for process B [Q <empty>]
time 3492ms: Process B switching out of CPU; will block on I/O until time 3527ms [Q <empty>]
time 3527ms: Process B (tau 85ms) completed I/O; added to ready queue [Q B]
time 3529ms: Process B started using the CPU for 74ms burst [Q <empty>]
time 3603ms: Process B completed a CPU burst; 4 bursts to go [Q <empty>]
time 3603ms: Recalculated tau = 80ms for process B [Q <empty>]
time 3603ms: Process B switching out of CPU; will block on I/O until time 3668ms [Q <empty>]
time 3668ms: Process B (tau 80ms) completed I/O; added to ready queue [Q B]
time 3670ms: Process B started using the CPU for 170ms burst [Q <empty>]
time 3840ms: Process B completed a CPU burst; 3 bursts to go [Q <empty>]
time 3840ms: Recalculated tau = 125ms for process B [Q <empty>]
time 3840ms: Process B switching out of CPU; will block on I/O until time 3899ms [Q <empty>]
time 3899ms: Process B (tau 125ms) completed I/O; added to ready queue [Q B]
time 3901ms: Process B started using the CPU for 43ms burst [Q <empty>]
time 3944ms: Process B completed a CPU burst; 2 bursts to go [Q <empty>]
time 3944ms: Recalculated tau = 84ms for process B [Q <empty>]
time 3944ms: Process B switching out of CPU; will block on I/O until time 4040ms [Q <empty>]
time 4040ms: Process B (tau 84ms) completed I/O; added to ready queue [Q B]
time 4042ms: Process B started using the CPU for 158ms burst [Q <empty>]
time 4200ms: Process B completed a CPU burst; 1 burst to go [Q <empty>]
time 4200ms: Recalculated tau = 121ms for process B [Q <empty>]
time 4200ms: Process B switching out of CPU; will block on I/O until time 4319ms [Q <empty>]
time 4319ms: Process B (tau 121ms) completed I/O; added to ready queue [Q B]
time 4321ms: Process B started using the CPU for 17ms burst [Q <empty>]
time 4338ms: Process B terminated [Q <empty>]
time 4340ms: Simulator ended for SRT [Q <empty>]

Process A [NEW] (arrival time 9 ms) 16 CPU bursts
Process B [NEW] (arrival time 18 ms) 21 CPU bursts
time 0ms: Simulator started for FCFS [Q <empty>]
time 9ms: Process A arrived; added to ready queue [Q A]
time 11ms: Process A started using the CPU for 56ms burst [Q <empty>]
time 18ms: Process B arrived; added to ready queue [Q B]
time 67ms: Process A completed a CPU burst; 15 bursts to go [Q B]
time 67ms: Process A switching out of CPU; will block on I/O until time 92ms [Q B]
time 71ms: Process B started using the CPU for 106ms burst [Q <empty>]
time 92ms: Process A completed I/O; added to ready queue [Q A]
time 177ms: Process B completed a CPU burst; 20 bursts to go [Q A]
time 177ms: Process B switching out of CPU; will block on I/O until time 335ms [Q A]
time 181ms: Process A started using the CPU for 60ms burst [Q <empty>]
time 241ms: Process A completed a CPU burst; 14 bursts to go [Q <empty>]
time 241ms: Process A switching out of CPU; will block on I/O until time 396ms [Q <empty>]
time 335ms: Process B completed I/O; added to ready queue [Q B]
time 337ms: Process B started using the CPU for 198ms burst [Q <empty>]
time 396ms: Process A completed I/O; added to ready queue [Q A]
time 535ms: Process B completed a CPU burst; 19 bursts to go [Q A]
time 535ms: Process B switching out of CPU; will block on I/O until time 650ms [Q A]
time 539ms: Process A started using the CPU for 39ms burst [Q <empty>]
time 578ms: Process A completed a CPU burst; 13 bursts to go [Q <empty>]
time 578ms: Process A switching out of CPU; will block on I/O until time 630ms [Q <empty>]
time 630ms: Process A completed I/O; added to ready queue [Q A]
time 632ms: Process A started using the CPU for 47ms burst [Q <empty>]
time 650ms: Process B completed I/O; added to ready queue [Q B]
time 679ms: Process A completed a CPU burst; 12 bursts to go [Q B]
time 679ms: Process A switching out of CPU; will block on I/O until time 683ms [Q B]
time 683ms: Process B started using the CPU for 162ms burst [Q <empty>]
time 683ms: Process A completed I/O; added to ready queue [Q A]
time 845ms: Process B completed a CPU burst; 18 bursts to go [Q A]
time 845ms: Process B switching out of CPU; will block on I/O until time 897ms [Q A]
time 849ms: Process A started using the CPU for 137ms burst [Q <empty>]
time 897ms: Process B completed I/O; added to ready queue [Q B]
time 986ms: Process A completed a CPU burst; 11 bursts to go [Q B]
time 986ms: Process A switching out of CPU; will block on I/O until time 1012ms [Q B]
time 990ms: Process B started using the CPU for 46ms burst [Q <empty>]
time 1012ms: Process A completed I/O; added to ready queue [Q A]
time 1036ms: Process B completed a CPU burst; 17 bursts to go [Q A]
time 1036ms: Process B switching out of CPU; will block on I/O until time 1120ms [Q A]
time 1040ms: Process A started using the CPU for 64ms burst [Q <empty>]
time 1104ms: Process A completed a CPU burst; 10 bursts to go [Q <empty>]
time 1104ms: Process A switching out of CPU; will block on I/O until time 1121ms [Q <empty>]
time 1120ms: Process B completed I/O; added to ready queue [Q B]
time 1121ms: Process A completed I/O; added to ready queue [Q A]
time 1122ms: Process B started using the CPU for 16ms burst [Q A]
time 1138ms: Process B completed a CPU burst; 16 bursts to go [Q A]
time 1138ms: Process B switching out of CPU; will block on I/O until time 1147ms [Q A]
time 1142ms: Process A started using the CPU for 68ms burst [Q <empty>]
time 1147ms: Process B completed I/O; added to ready queue [Q B]
time 1210ms: Process A completed a CPU burst; 9 bursts to go [Q B]
time 1210ms: Process A switching out of CPU; will block on I/O until time 1276ms [Q B]
time 1214ms: Process B started using the CPU for 30ms burst [Q <empty>]
time 1244ms: Process B completed a CPU burst; 15 bursts to go [Q <empty>]
time 1244ms: Process B switching out of CPU; will block on I/O until time 1298ms [Q <empty>]
time 1276ms: Process A completed I/O; added to ready queue [Q A]
time 1278ms: Process A started using the CPU for 113ms burst [Q <empty>]
time 1298ms: Process B completed I/O; added to ready queue [Q B]
time 1391ms: Process A completed a CPU burst; 8 bursts to go [Q B]
time 1391ms: Process A switching out of CPU; will block on I/O until time 1409ms [Q B]
time 1395ms: Process B started using the CPU for 12ms burst [Q <empty>]
time 1407ms: Process B completed a CPU burst; 14 bursts to go [Q <empty>]
time 1407ms: Process B switching out of CPU; will block on I/O until time 1486ms [Q <empty>]
time 1409ms: Process A completed I/O; added to ready queue [Q A]
time 1411ms: Process A started using the CPU for 11ms burst [Q <empty>]
time 1422ms: Process A completed a CPU burst; 7 bursts to go [Q <empty>]
time 1422ms: Process A switching out of CPU; will block on I/O until time 1586ms [Q <empty>]
time 1486ms: Process B completed I/O; added to ready queue [Q B]
time 1488ms: Process B started using the CPU for 138ms burst [Q <empty>]
time 1586ms: Process A completed I/O; added to ready queue [Q A]
time 1626ms: Process B completed a CPU burst; 13 bursts to go [Q A]
time 1626ms: Process B switching out of CPU; will block on I/O until time 1710ms [Q A]
time 1630ms: Process A started using the CPU for 24ms burst [Q <empty>]
time 1654ms: Process A completed a CPU burst; 6 bursts to go [Q <empty>]
time 1654ms: Process A switching out of CPU; will block on I/O until time 1773ms [Q <empty>]
time 1710ms: Process B completed I/O; added to ready queue [Q B]
time 1712ms: Process B started using the CPU for 67ms burst [Q <empty>]
time 1773ms: Process A completed I/O; added to ready queue [Q A]
time 1779ms: Process B completed a CPU burst; 12 bursts to go [Q A]
time 1779ms: Process B switching out of CPU; will block on I/O until time 1788ms [Q A]
time 1783ms: Process A started using the CPU for 76ms burst [Q <empty>]
time 1788ms: Process B completed I/O; added to ready queue [Q B]
time 1859ms: Process A completed a CPU burst; 5 bursts to go [Q B]
time 1859ms: Process A switching out of CPU; will block on I/O until time 1889ms [Q B]
time 1863ms: Process B started using the CPU for 120ms burst [Q <empty>]
time 1889ms: Process A completed I/O; added to ready queue [Q A]
time 1983ms: Process B completed a CPU burst; 11 bursts to go [Q A]
time 1983ms: Process B switching out of CPU; will block on I/O until time 1998ms [Q A]
time 1987ms: Process A started using the CPU for 122ms burst [Q <empty>]
time 1998ms: Process B completed I/O; added to ready queue [Q B]
time 2109ms: Process A completed a CPU burst; 4 bursts to go [Q B]
time 2109ms: Process A switching out of CPU; will block on I/O until time 2144ms [Q B]
time 2113ms: Process B started using the CPU for 49ms burst [Q <empty>]
time 2144ms: Process A completed I/O; added to ready queue [Q A]
time 2162ms: Process B completed a CPU burst; 10 bursts to go [Q A]
time 2162ms: Process B switching out of CPU; will block on I/O until time 2206ms [Q A]
time 2166ms: Process A started using the CPU for 9ms burst [Q <empty>]
time 2175ms: Process A completed a CPU burst; 3 bursts to go [Q <empty>]
time 2175ms: Process A switching out of CPU; will block on I/O until time 2245ms [Q <empty>]
time 2206ms: Process B completed I/O; added to ready queue [Q B]
time 2208ms: Process B started using the CPU for 134ms burst [Q <empty>]
time 2245ms: Process A completed I/O; added to ready queue [Q A]
time 2342ms: Process B completed a CPU burst; 9 bursts to go [Q A]
time 2342ms: Process B switching out of CPU; will block on I/O until time 2376ms [Q A]
time 2346ms: Process A started using the CPU for 62ms burst [Q <empty>]
time 2376ms: Process B completed I/O; added to ready queue [Q B]
time 2408ms: Process A completed a CPU burst; 2 bursts to go [Q B]
time 2408ms: Process A switching out of CPU; will block on I/O until time 2487ms [Q B]
time 2412ms: Process B started using the CPU for 144ms burst [Q <empty>]
time 2487ms: Process A completed I/O; added to ready queue [Q A]
time 2556ms: Process B completed a CPU burst; 8 bursts to go [Q A]
time 2556ms: Process B switching out of CPU; will block on I/O until time 2637ms [Q A]
time 2560ms: Process A started using the CPU for 200ms burst [Q <empty>]
time 2637ms: Process B completed I/O; added to ready queue [Q B]
time 2760ms: Process A completed a CPU burst; 1 burst to go [Q B]
time 2760ms: Process A switching out of CPU; will block on I/O until time 2773ms [Q B]
time 2764ms: Process B started using the CPU for 183ms burst [Q <empty>]
time 2773ms: Process A completed I/O; added to ready queue [Q A]
time 2947ms: Process B completed a CPU burst; 7 bursts to go [Q A]
time 2947ms: Process B switching out of CPU; will block on I/O until time 2955ms [Q A]
time 2951ms: Process A started using the CPU for 197ms burst [Q <empty>]
time 2955ms: Process B completed I/O; added to ready queue [Q B]
time 3148ms: Process A terminated [Q B]
time 3152ms: Process B started using the CPU for 23ms burst [Q <empty>]
time 3175ms: Process B completed a CPU burst; 6 bursts to go [Q <empty>]
time 3175ms: Process B switching out of CPU; will block on I/O until time 3241ms [Q <empty>]
time 3241ms: Process B completed I/O; added to ready queue [Q B]
time 3243ms: Process B started using the CPU for 80ms burst [Q <empty>]
time 3323ms: Process B completed a CPU burst; 5 bursts to go [Q <empty>]
time 3323ms: Process B switching out of CPU; will block on I/O until time 3358ms [Q <empty>]
time 3358ms: Process B completed I/O; added to ready queue [Q B]
time 3360ms: Process B started using the CPU for 74ms burst [Q <empty>]
time 3434ms: Process B completed a CPU burst; 4 bursts to go [Q <empty>]
time 3434ms: Process B switching out of CPU; will block on I/O until time 3499ms [Q <empty>]
time 3499ms: Process B completed I/O; added to ready queue [Q B]
time 3501ms: Process B started using the CPU for 170ms burst [Q <empty>]
time 3671ms: Process B completed a CPU burst; 3 bursts to go [Q <empty>]
time 3671ms: Process B switching out of CPU; will block on I/O until time 3730ms [Q <empty>]
time 3730ms: Process B completed I/O; added to ready queue [Q B]
time 3732ms: Process B started using the CPU for 43ms burst [Q <empty>]
time 3775ms: Process B completed a CPU burst; 2 bursts to go [Q <empty>]
time 3775ms: Process B switching out of CPU; will block on I/O until time 3871ms [Q <empty>]
time 3871ms: Process B completed I/O; added to ready queue [Q B]
time 3873ms: Process B started using the CPU for 158ms burst [Q <empty>]
time 4031ms: Process B completed a CPU burst; 1 burst to go [Q <empty>]
time 4031ms: Process B switching out of CPU; will block on I/O until time 4150ms [Q <empty>]
time 4150ms: Process B completed I/O; added to ready queue [Q B]
time 4152ms: Process B started using the CPU for 17ms burst [Q <empty>]
time 4169ms: Process B terminated [Q <empty>]
time 4171ms: Simulator ended for FCFS [Q <empty>]

Process A [NEW] (arrival time 9 ms) 16 CPU bursts
Process B [NEW] (arrival time 18 ms) 21 CPU bursts
time 0ms: Simulator started for RR [Q <empty>]
time 9ms: Process A arrived; added to ready queue [Q A]
time 11ms: Process A started using the CPU for 56ms burst [Q <empty>]
time 18ms: Process B arrived; added to ready queue [Q B]
time 67ms: Process A completed a CPU burst; 15 bursts to go [Q B]
time 67ms: Process A switching out of CPU; will block on I/O until time 92ms [Q B]
time 71ms: Process B started using the CPU for 106ms burst [Q <empty>]
time 92ms: Process A completed I/O; added to ready queue [Q A]
time 177ms: Process B completed a CPU burst; 20 bursts to go [Q A]
time 177ms: Process B switching out of CPU; will block on I/O until time 335ms [Q A]
time 181ms: Process A started using the CPU for 60ms burst [Q <empty>]
time 241ms: Process A completed a CPU burst; 14 bursts to go [Q <empty>]
time 241ms: Process A switching out of CPU; will block on I/O until time 396ms [Q <empty>]
time 335ms: Process B completed I/O; added to ready queue [Q B]
time 337ms: Process B started using the CPU for 198ms burst [Q <empty>]
time 396ms: Process A completed I/O; added to ready queue [Q A]
time 457ms: Time slice expired; process B preempted with 78ms to go [Q A]
time 461ms: Process A started using the CPU for 39ms burst [Q B]
time 500ms: Process A completed a CPU burst; 13 bursts to go [Q B]
time 500ms: Process A switching out of CPU; will block on I/O until time 552ms [Q B]
time 504ms: Process B started using the CPU with 78ms remaining [Q <empty>]
time 552ms: Process A completed I/O; added to ready queue [Q A]
time 582ms: Process B completed a CPU burst; 19 bursts to go [Q A]
time 582ms: Process B switching out of CPU; will block on I/O until time 697ms [Q A]
time 586ms: Process A started using the CPU for 47ms burst [Q <empty>]
time 633ms: Process A completed a CPU burst; 12 bursts to go [Q <empty>]
time 633ms: Process A switching out of CPU; will block on I/O until time 637ms [Q <empty>]
time 637ms: Process A completed I/O; added to ready queue [Q A]
time 639ms: Process A started using the CPU for 137ms burst [Q <empty>]
time 697ms: Process B completed I/O; added to ready queue [Q B]
time 759ms: Time slice expired; process A preempted with 17ms to go [Q B]
time 763ms: Process B started using the CPU for 162ms burst [Q A]
time 883ms: Time slice expired; process B preempted with 42ms to go [Q A]
time 887ms: Process A started using the CPU with 17ms remaining [Q B]
time 904ms: Process A completed a CPU burst; 11 bursts to go [Q B]
time 904ms: Process A switching out of CPU; will block on I/O until time 930ms [Q B]
time 908ms: Process B started using the CPU with 42ms remaining [Q <empty>]
time 930ms: Process A completed I/O; added to ready queue [Q A]
time 950ms: Process B completed a CPU burst; 18 bursts to go [Q A]
time 950ms: Process B switching out of CPU; will block on I/O until time 1002ms [Q A]
time 954ms: Process A started using the CPU for 64ms burst [Q <empty>]
time 1002ms: Process B completed I/O; added to ready queue [Q B]
time 1018ms: Process A completed a CPU burst; 10 bursts to go [Q B]
time 1018ms: Process A switching out of CPU; will block on I/O until time 1035ms [Q B]
time 1022ms: Process B started using the CPU for 46ms burst [Q <empty>]
time 1035ms: Process A completed I/O; added to ready queue [Q A]
time 1068ms: Process B completed a CPU burst; 17 bursts to go [Q A]
time 1068ms: Process B switching out of CPU; will block on I/O until time 1152ms [Q A]
time 1072ms: Process A started using the CPU for 68ms burst [Q <empty>]
time 1140ms: Process A completed a CPU burst; 9 bursts to go [Q <empty>]
time 1140ms: Process A switching out of CPU; will block on I/O until time 1206ms [Q <empty>]
time 1152ms: Process B completed I/O; added to ready queue [Q B]
time 1154ms: Process B started using the CPU for 16ms burst [Q <empty>]
time 1170ms: Process B completed a CPU burst; 16 bursts to go [Q <empty>]
time 1170ms: Process B switching out of CPU; will block on I/O until time 1179ms [Q <empty>]
time 1179ms: Process B completed I/O; added to ready queue [Q B]
time 1181ms: Process B started using the CPU for 30ms burst [Q <empty>]
time 1206ms: Process A completed I/O; added to ready queue [Q A]
time 1211ms: Process B completed a CPU burst; 15 bursts to go [Q A]
time 1211ms: Process B switching out of CPU; will block on I/O until time 1265ms [Q A]
time 1215ms: Process A started using the CPU for 113ms burst [Q <empty>]
time 1265ms: Process B completed I/O; added to ready queue [Q B]
time 1328ms: Process A completed a CPU burst; 8 bursts to go [Q B]
time 1328ms: Process A switching out of CPU; will block on I/O until time 1346ms [Q B]
time 1332ms: Process B started using the CPU for 12ms burst [Q <empty>]
time 1344ms: Process B completed a CPU burst; 14 bursts to go [Q <empty>]
time 1344ms: Process B switching out of CPU; will block on I/O until time 1423ms [Q <empty>]
time 1346ms: Process A completed I/O; added to ready queue [Q A]
time 1348ms: Process A started using the CPU for 11ms burst [Q <empty>]
time 1359ms: Process A completed a CPU burst; 7 bursts to go [Q <empty>]
time 1359ms: Process A switching out of CPU; will block on I/O until time 1523ms [Q <empty>]
time 1423ms: Process B completed I/O; added to ready queue [Q B]
time 1425ms: Process B started using the CPU for 138ms burst [Q <empty>]
time 1523ms: Process A completed I/O; added to ready queue [Q A]
time 1545ms: Time slice expired; process B preempted with 18ms to go [Q A]
time 1549ms: Process A started using the CPU for 24ms burst [Q B]
time 1573ms: Process A completed a CPU burst; 6 bursts to go [Q B]
time 1573ms: Process A switching out of CPU; will block on I/O until time 1692ms [Q B]
time 1577ms: Process B started using the CPU with 18ms remaining [Q <empty>]
time 1595ms: Process B completed a CPU burst; 13 bursts to go [Q <empty>]
time 1595ms: Process B switching out of CPU; will block on I/O until time 1679ms [Q <empty>]
time 1679ms: Process B completed I/O; added to ready queue [Q B]
time 1681ms: Process B started using the CPU for 67ms burst [Q <empty>]
time 1692ms: Process A completed I/O; added to ready queue [Q A]
time 1748ms: Process B completed a CPU burst; 12 bursts to go [Q A]
time 1748ms: Process B switching out of CPU; will block on I/O until time 1757ms [Q A]
time 1752ms: Process A started using the CPU for 76ms burst [Q <empty>]
time 1757ms: Process B completed I/O; added to ready queue [Q B]
time 1828ms: Process A completed a CPU burst; 5 bursts to go [Q B]
time 1828ms: Process A switching out of CPU; will block on I/O until time 1858ms [Q B]
time 1832ms: Process B started using the CPU for 120ms burst [Q <empty>]
time 1858ms: Process A completed I/O; added to ready queue [Q A]
time 1952ms: Process B completed a CPU burst; 11 bursts to go [Q A]
time 1952ms: Process B switching out of CPU; will block on I/O until time 1967ms [Q A]
time 1956ms: Process A started using the CPU for 122ms burst [Q <empty>]
time 1967ms: Process B completed I/O; added to ready queue [Q B]
time 2076ms: Time slice expired; process A preempted with 2ms to go [Q B]
time 2080ms: Process B started using the CPU for 49ms burst [Q A]
time 2129ms: Process B completed a CPU burst; 10 bursts to go [Q A]
time 2129ms: Process B switching out of CPU; will block on I/O until time 2173ms [Q A]
time 2133ms: Process A started using the CPU with 2ms remaining [Q <empty>]
time 2135ms: Process A completed a CPU burst; 4 bursts to go [Q <empty>]
time 2135ms: Process A switching out of CPU; will block on I/O until time 2170ms [Q <empty>]
time 2170ms: Process A completed I/O; added to ready queue [Q A]
time 2172ms: Process A started using the CPU for 9ms burst [Q <empty>]
time 2173ms: Process B completed I/O; added to ready queue [Q B]
time 2181ms: Process A completed a CPU burst; 3 bursts to go [Q B]
time 2181ms: Process A switching out of CPU; will block on I/O until time 2251ms [Q B]
time 2185ms: Process B started using the CPU for 134ms burst [Q <empty>]
time 2251ms: Process A completed I/O; added to ready queue [Q A]
time 2305ms: Time slice expired; process B preempted with 14ms to go [Q A]
time 2309ms: Process A started using the CPU for 62ms burst [Q B]
time 2371ms: Process A completed a CPU burst; 2 bursts to go [Q B]
time 2371ms: Process A switching out of CPU; will block on I/O until time 2450ms [Q B]
time 2375ms: Process B started using the CPU with 14ms remaining [Q <empty>]
time 2389ms: Process B completed a CPU burst; 9 bursts to go [Q <empty>]
time 2389ms: Process B switching out of CPU; will block on I/O until time 2423ms [Q <empty>]
time 2423ms: Process B completed I/O; added to ready queue [Q B]
time 2425ms: Process B started using the CPU for 144ms burst [Q <empty>]
time 2450ms: Process A completed I/O; added to ready queue [Q A]
time 2545ms: Time slice expired; process B preempted with 24ms to go [Q A]
time 2549ms: Process A started using the CPU for 200ms burst [Q B]
time 2669ms: Time slice expired; process A preempted with 80ms to go [Q B]
time 2673ms: Process B started using the CPU with 24ms remaining [Q A]
time 2697ms: Process B completed a CPU burst; 8 bursts to go [Q A]
time 2697ms: Process B switching out of CPU; will block on I/O until time 2778ms [Q A]
time 2701ms: Process A started using the CPU with 80ms remaining [Q <empty>]
time 2778ms: Process B completed I/O; added to ready queue [Q B]
time 2781ms: Process A completed a CPU burst; 1 burst to go [Q B]
time 2781ms: Process A switching out of CPU; will block on I/O until time 2794ms [Q B]
time 2785ms: Process B started using the CPU for 183ms burst [Q <empty>]
time 2794ms: Process A completed I/O; added to ready queue [Q A]
time 2905ms: Time slice expired; process B preempted with 63ms to go [Q A]
time 2909ms: Process A started using the CPU for 197ms burst [Q B]
time 3029ms: Time slice expired; process A preempted with 77ms to go [Q B]
time 3033ms: Process B started using the CPU with 63ms remaining [Q A]
time 3096ms: Process B completed a CPU burst; 7 bursts to go [Q A]
time 3096ms: Process B switching out of CPU; will block on I/O until time 3104ms [Q A]
time 3100ms: Process A started using the CPU with 77ms remaining [Q <empty>]
time 3104ms: Process B completed I/O; added to ready queue [Q B]
time 3177ms: Process A terminated [Q B]
time 3181ms: Process B started using the CPU for 23ms burst [Q <empty>]
time 3204ms: Process B completed a CPU burst; 6 bursts to go [Q <empty>]
time 3204ms: Process B switching out of CPU; will block on I/O until time 3270ms [Q <empty>]
time 3270ms: Process B completed I/O; added to ready queue [Q B]
time 3272ms: Process B started using the CPU for 80ms burst [Q <empty>]
time 3352ms: Process B completed a CPU burst; 5 bursts to go [Q <empty>]
time 3352ms: Process B switching out of CPU; will block on I/O until time 3387ms [Q <empty>]
time 3387ms: Process B completed I/O; added to ready queue [Q B]
time 3389ms: Process B started using the CPU for 74ms burst [Q <empty>]
time 3463ms: Process B completed a CPU burst; 4 bursts to go [Q <empty>]
time 3463ms: Process B switching out of CPU; will block on I/O until time 3528ms [Q <empty>]
time 3528ms: Process B completed I/O; added to ready queue [Q B]
time 3530ms: Process B started using the CPU for 170ms burst [Q <empty>]
time 3650ms: Time slice expired; no preemption because ready queue is empty [Q <empty>]
time 3700ms: Process B completed a CPU burst; 3 bursts to go [Q <empty>]
time 3700ms: Process B switching out of CPU; will block on I/O until time 3759ms [Q <empty>]
time 3759ms: Process B completed I/O; added to ready queue [Q B]
time 3761ms: Process B started using the CPU for 43ms burst [Q <empty>]
time 3804ms: Process B completed a CPU burst; 2 bursts to go [Q <empty>]
time 3804ms: Process B switching out of CPU; will block on I/O until time 3900ms [Q <empty>]
time 3900ms: Process B completed I/O; added to ready queue [Q B]
time 3902ms: Process B started using the CPU for 158ms burst [Q <empty>]
time 4022ms: Time slice expired; no preemption because ready queue is empty [Q <empty>]
time 4060ms: Process B completed a CPU burst; 1 burst to go [Q <empty>]
time 4060ms: Process B switching out of CPU; will block on I/O until time 4179ms [Q <empty>]
time 4179ms: Process B completed I/O; added to ready queue [Q B]
time 4181ms: Process B started using the CPU for 17ms burst [Q <empty>]
time 4198ms: Process B terminated [Q <empty>]
time 4200ms: Simulator ended for RR [Q <empty>]
