Process A [NEW] (arrival time 9 ms) 16 CPU bursts
time 0ms: Simulator started for SJF [Q <empty>]
time 9ms: Process A (tau 100ms) arrived; added to ready queue [Q A]
time 11ms: Process A started using the CPU for 56ms burst [Q <empty>]
time 67ms: Process A completed a CPU burst; 15 bursts to go [Q <empty>]
time 67ms: Recalculated tau = 78ms for process A [Q <empty>]
time 67ms: Process A switching out of CPU; will block on I/O until time 92ms [Q <empty>]
time 92ms: Process A (tau 78ms) completed I/O; added to ready queue [Q A]
time 94ms: Process A started using the CPU for 60ms burst [Q <empty>]
time 154ms: Process A completed a CPU burst; 14 bursts to go [Q <empty>]
time 154ms: Recalculated tau = 69ms for process A [Q <empty>]
time 154ms: Process A switching out of CPU; will block on I/O until time 309ms [Q <empty>]
time 309ms: Process A (tau 69ms) completed I/O; added to ready queue [Q A]
time 311ms: Process A started using the CPU for 39ms burst [Q <empty>]
time 350ms: Process A completed a CPU burst; 13 bursts to go [Q <empty>]
time 350ms: Recalculated tau = 54ms for process A [Q <empty>]
time 350ms: Process A switching out of CPU; will block on I/O until time 402ms [Q <empty>]
time 402ms: Process A (tau 54ms) completed I/O; added to ready queue [Q A]
time 404ms: Process A started using the CPU for 47ms burst [Q <empty>]
time 451ms: Process A completed a CPU burst; 12 bursts to go [Q <empty>]
time 451ms: Recalculated tau = 51ms for process A [Q <empty>]
time 451ms: Process A switching out of CPU; will block on I/O until time 455ms [Q <empty>]
time 455ms: Process A (tau 51ms) completed I/O; added to ready queue [Q A]
time 457ms: Process A started using the CPU for 137ms burst [Q <empty>]
time 594ms: Process A completed a CPU burst; 11 bursts to go [Q <empty>]
time 594ms: Recalculated tau = 94ms for process A [Q <empty>]
time 594ms: Process A switching out of CPU; will block on I/O until time 620ms [Q <empty>]
time 620ms: Process A (tau 94ms) completed I/O; added to ready queue [Q A]
time 622ms: Process A started using the CPU for 64ms burst [Q <empty>]
time 686ms: Process A completed a CPU burst; 10 bursts to go [Q <empty>]
time 686ms: Recalculated tau = 79ms for process A [Q <empty>]
time 686ms: Process A switching out of CPU; will block on I/O until time 703ms [Q <empty>]
time 703ms: Process A (tau 79ms) completed I/O; added to ready queue [Q A]
time 705ms: Process A started using the CPU for 68ms burst [Q <empty>]
time 773ms: Process A completed a CPU burst; 9 bursts to go [Q <empty>]
time 773ms: Recalculated tau = 74ms for process A [Q <empty>]
time 773ms: Process A switching out of CPU; will block on I/O until time 839ms [Q <empty>]
time 839ms: Process A (tau 74ms) completed I/O; added to ready queue [Q A]
time 841ms: Process A started using the CPU for 113ms burst [Q <empty>]
time 954ms: Process A completed a CPU burst; 8 bursts to go [Q <empty>]
time 954ms: Recalculated tau = 94ms for process A [Q <empty>]
time 954ms: Process A switching out of CPU; will block on I/O until time 972ms [Q <empty>]
time 972ms: Process A (tau 94ms) completed I/O; added to ready queue [Q A]
time 974ms: Process A started using the CPU for 11ms burst [Q <empty>]
time 985ms: Process A completed a CPU burst; 7 bursts to go [Q <empty>]
time 985ms: Recalculated tau = 53ms for process A [Q <empty>]
time 985ms: Process A switching out of CPU; will block on I/O until time 1149ms [Q <empty>]
time 2199ms: Process A terminated [Q <empty>]
time 2201ms: Simulator ended for SJF [Q <empty>]

Process A [NEW] (arrival time 9 ms) 16 CPU bursts
time 0ms: Simulator started for SRT [Q <empty>]
time 9ms: Process A (tau 100ms) arrived; added to ready queue [Q A]
time 11ms: Process A started using the CPU for 56ms burst [Q <empty>]
time 67ms: Process A completed a CPU burst; 15 bursts to go [Q <empty>]
time 67ms: Recalculated tau = 78ms for process A [Q <empty>]
time 67ms: Process A switching out of CPU; will block on I/O until time 92ms [Q <empty>]
time 92ms: Process A (tau 78ms) completed I/O; added to ready queue [Q A]
time 94ms: Process A started using the CPU for 60ms burst [Q <empty>]
time 154ms: Process A completed a CPU burst; 14 bursts to go [Q <empty>]
time 154ms: Recalculated tau = 69ms for process A [Q <empty>]
time 154ms: Process A switching out of CPU; will block on I/O until time 309ms [Q <empty>]
time 309ms: Process A (tau 69ms) completed I/O; added to ready queue [Q A]
time 311ms: Process A started using the CPU for 39ms burst [Q <empty>]
time 350ms: Process A completed a CPU burst; 13 bursts to go [Q <empty>]
time 350ms: Recalculated tau = 54ms for process A [Q <empty>]
time 350ms: Process A switching out of CPU; will block on I/O until time 402ms [Q <empty>]
time 402ms: Process A (tau 54ms) completed I/O; added to ready queue [Q A]
time 404ms: Process A started using the CPU for 47ms burst [Q <empty>]
time 451ms: Process A completed a CPU burst; 12 bursts to go [Q <empty>]
time 451ms: Recalculated tau = 51ms for process A [Q <empty>]
time 451ms: Process A switching out of CPU; will block on I/O until time 455ms [Q <empty>]
time 455ms: Process A (tau 51ms) completed I/O; added to ready queue [Q A]
time 457ms: Process A started using the CPU for 137ms burst [Q <empty>]
time 594ms: Process A completed a CPU burst; 11 bursts to go [Q <empty>]
time 594ms: Recalculated tau = 94ms for process A [Q <empty>]
time 594ms: Process A switching out of CPU; will block on I/O until time 620ms [Q <empty>]
time 620ms: Process A (tau 94ms) completed I/O; added to ready queue [Q A]
time 622ms: Process A started using the CPU for 64ms burst [Q <empty>]
time 686ms: Process A completed a CPU burst; 10 bursts to go [Q <empty>]
time 686ms: Recalculated tau = 79ms for process A [Q <empty>]
time 686ms: Process A switching out of CPU; will block on I/O until time 703ms [Q <empty>]
time 703ms: Process A (tau 79ms) completed I/O; added to ready queue [Q A]
time 705ms: Process A started using the CPU for 68ms burst [Q <empty>]
time 773ms: Process A completed a CPU burst; 9 bursts to go [Q <empty>]
time 773ms: Recalculated tau = 74ms for process A [Q <empty>]
time 773ms: Process A switching out of CPU; will block on I/O until time 839ms [Q <empty>]
time 839ms: Process A (tau 74ms) completed I/O; added to ready queue [Q A]
time 841ms: Process A started using the CPU for 113ms burst [Q <empty>]
time 954ms: Process A completed a CPU burst; 8 bursts to go [Q <empty>]
time 954ms: Recalculated tau = 94ms for process A [Q <empty>]
time 954ms: Process A switching out of CPU; will block on I/O until time 972ms [Q <empty>]
time 972ms: Process A (tau 94ms) completed I/O; added to ready queue [Q A]
time 974ms: Process A started using the CPU for 11ms burst [Q <empty>]
time 985ms: Process A completed a CPU burst; 7 bursts to go [Q <empty>]
time 985ms: Recalculated tau = 53ms for process A [Q <empty>]
time 985ms: Process A switching out of CPU; will block on I/O until time 1149ms [Q <empty>]
time 2199ms: Process A terminated [Q <empty>]
time 2201ms: Simulator ended for SRT [Q <empty>]

Process A [NEW] (arrival time 9 ms) 16 CPU bursts
time 0ms: Simulator started for FCFS [Q <empty>]
time 9ms: Process A arrived; added to ready queue [Q A]
time 11ms: Process A started using the CPU for 56ms burst [Q <empty>]
time 67ms: Process A completed a CPU burst; 15 bursts to go [Q <empty>]
time 67ms: Process A switching out of CPU; will block on I/O until time 92ms [Q <empty>]
time 92ms: Process A completed I/O; added to ready queue [Q A]
time 94ms: Process A started using the CPU for 60ms burst [Q <empty>]
time 154ms: Process A completed a CPU burst; 14 bursts to go [Q <empty>]
time 154ms: Process A switching out of CPU; will block on I/O until time 309ms [Q <empty>]
time 309ms: Process A completed I/O; added to ready queue [Q A]
time 311ms: Process A started using the CPU for 39ms burst [Q <empty>]
time 350ms: Process A completed a CPU burst; 13 bursts to go [Q <empty>]
time 350ms: Process A switching out of CPU; will block on I/O until time 402ms [Q <empty>]
time 402ms: Process A completed I/O; added to ready queue [Q A]
time 404ms: Process A started using the CPU for 47ms burst [Q <empty>]
time 451ms: Process A completed a CPU burst; 12 bursts to go [Q <empty>]
time 451ms: Process A switching out of CPU; will block on I/O until time 455ms [Q <empty>]
time 455ms: Process A completed I/O; added to ready queue [Q A]
time 457ms: Process A started using the CPU for 137ms burst [Q <empty>]
time 594ms: Process A completed a CPU burst; 11 bursts to go [Q <empty>]
time 594ms: Process A switching out of CPU; will block on I/O until time 620ms [Q <empty>]
time 620ms: Process A completed I/O; added to ready queue [Q A]
time 622ms: Process A started using the CPU for 64ms burst [Q <empty>]
time 686ms: Process A completed a CPU burst; 10 bursts to go [Q <empty>]
time 686ms: Process A switching out of CPU; will block on I/O until time 703ms [Q <empty>]
time 703ms: Process A completed I/O; added to ready queue [Q A]
time 705ms: Process A started using the CPU for 68ms burst [Q <empty>]
time 773ms: Process A completed a CPU burst; 9 bursts to go [Q <empty>]
time 773ms: Process A switching out of CPU; will block on I/O until time 839ms [Q <empty>]
time 839ms: Process A completed I/O; added to ready queue [Q A]
time 841ms: Process A started using the CPU for 113ms burst [Q <empty>]
time 954ms: Process A completed a CPU burst; 8 bursts to go [Q <empty>]
time 954ms: Process A switching out of CPU; will block on I/O until time 972ms [Q <empty>]
time 972ms: Process A completed I/O; added to ready queue [Q A]
time 974ms: Process A started using the CPU for 11ms burst [Q <empty>]
time 985ms: Process A completed a CPU burst; 7 bursts to go [Q <empty>]
time 985ms: Process A switching out of CPU; will block on I/O until time 1149ms [Q <empty>]
time 2199ms: Process A terminated [Q <empty>]
time 2201ms: Simulator ended for FCFS [Q <empty>]

Process A [NEW] (arrival time 9 ms) 16 CPU bursts
time 0ms: Simulator started for RR [Q <empty>]
time 9ms: Process A arrived; added to ready queue [Q A]
time 11ms: Process A started using the CPU for 56ms burst [Q <empty>]
time 67ms: Process A completed a CPU burst; 15 bursts to go [Q <empty>]
time 67ms: Process A switching out of CPU; will block on I/O until time 92ms [Q <empty>]
time 92ms: Process A completed I/O; added to ready queue [Q A]
time 94ms: Process A started using the CPU for 60ms burst [Q <empty>]
time 154ms: Process A completed a CPU burst; 14 bursts to go [Q <empty>]
time 154ms: Process A switching out of CPU; will block on I/O until time 309ms [Q <empty>]
time 309ms: Process A completed I/O; added to ready queue [Q A]
time 311ms: Process A started using the CPU for 39ms burst [Q <empty>]
time 350ms: Process A completed a CPU burst; 13 bursts to go [Q <empty>]
time 350ms: Process A switching out of CPU; will block on I/O until time 402ms [Q <empty>]
time 402ms: Process A completed I/O; added to ready queue [Q A]
time 404ms: Process A started using the CPU for 47ms burst [Q <empty>]
time 451ms: Process A completed a CPU burst; 12 bursts to go [Q <empty>]
time 451ms: Process A switching out of CPU; will block on I/O until time 455ms [Q <empty>]
time 455ms: Process A completed I/O; added to ready queue [Q A]
time 457ms: Process A started using the CPU for 137ms burst [Q <empty>]
time 577ms: Time slice expired; no preemption because ready queue is empty [Q <empty>]
time 594ms: Process A completed a CPU burst; 11 bursts to go [Q <empty>]
time 594ms: Process A switching out of CPU; will block on I/O until time 620ms [Q <empty>]
time 620ms: Process A completed I/O; added to ready queue [Q A]
time 622ms: Process A started using the CPU for 64ms burst [Q <empty>]
time 686ms: Process A completed a CPU burst; 10 bursts to go [Q <empty>]
time 686ms: Process A switching out of CPU; will block on I/O until time 703ms [Q <empty>]
time 703ms: Process A completed I/O; added to ready queue [Q A]
time 705ms: Process A started using the CPU for 68ms burst [Q <empty>]
time 773ms: Process A completed a CPU burst; 9 bursts to go [Q <empty>]
time 773ms: Process A switching out of CPU; will block on I/O until time 839ms [Q <empty>]
time 839ms: Process A completed I/O; added to ready queue [Q A]
time 841ms: Process A started using the CPU for 113ms burst [Q <empty>]
time 954ms: Process A completed a CPU burst; 8 bursts to go [Q <empty>]
time 954ms: Process A switching out of CPU; will block on I/O until time 972ms [Q <empty>]
time 972ms: Process A completed I/O; added to ready queue [Q A]
time 974ms: Process A started using the CPU for 11ms burst [Q <empty>]
time 985ms: Process A completed a CPU burst; 7 bursts to go [Q <empty>]
time 985ms: Process A switching out of CPU; will block on I/O until time 1149ms [Q <empty>]
time 2199ms: Process A terminated [Q <empty>]
time 2201ms: Simulator ended for RR [Q <empty>]
