Process A [NEW] (arrival time 301 ms) 19 CPU bursts
Process B [NEW] (arrival time 40 ms) 89 CPU bursts
Process C [NEW] (arrival time 902 ms) 81 CPU bursts
Process D [NEW] (arrival time 1656 ms) 74 CPU bursts
Process E [NEW] (arrival time 947 ms) 33 CPU bursts
Process F [NEW] (arrival time 240 ms) 87 CPU bursts
Process G [NEW] (arrival time 2263 ms) 63 CPU bursts
Process H [NEW] (arrival time 499 ms) 12 CPU bursts
Process I [NEW] (arrival time 42 ms) 8 CPU bursts
Process J [NEW] (arrival time 2754 ms) 33 CPU bursts
Process K [NEW] (arrival time 492 ms) 9 CPU bursts
Process L [NEW] (arrival time 1710 ms) 17 CPU bursts
time 0ms: Simulator started for SJF [Q <empty>]
time 40ms: Process B (tau 1000ms) arrived; added to ready queue [Q B]
time 42ms: Process B started using the CPU for 505ms burst [Q <empty>]
time 42ms: Process I (tau 1000ms) arrived; added to ready queue [Q I]
time 240ms: Process F (tau 1000ms) arrived; added to ready queue [Q F I]
time 301ms: Process A (tau 1000ms) arrived; added to ready queue [Q A F I]
time 492ms: Process K (tau 1000ms) arrived; added to ready queue [Q A F I K]
time 499ms: Process H (tau 1000ms) arrived; added to ready queue [Q A F H I K]
time 547ms: Process B completed a CPU burst; 88 bursts to go [Q A F H I K]
time 547ms: Recalculated tau = 753ms for process B [Q A F H I K]
time 547ms: Process B switching out of CPU; will block on I/O until time 725ms [Q A F H I K]
time 551ms: Process A started using the CPU for 159ms burst [Q F H I K]
time 710ms: Process A completed a CPU burst; 18 bursts to go [Q F H I K]
time 710ms: Recalculated tau = 580ms for process A [Q F H I K]
time 710ms: Process A switching out of CPU; will block on I/O until time 1048ms [Q F H I K]
time 714ms: Process F started using the CPU for 308ms burst [Q H I K]
time 725ms: Process B (tau 753ms) completed I/O; added to ready queue [Q B H I K]
time 902ms: Process C (tau 1000ms) arrived; added to ready queue [Q B C H I K]
time 947ms: Process E (tau 1000ms) arrived; added to ready queue [Q B C E H I K]
time 1022ms: Process F completed a CPU burst; 86 bursts to go [Q B C E H I K]
time 1022ms: Recalculated tau = 654ms for process F [Q B C E H I K]
time 1022ms: Process F switching out of CPU; will block on I/O until time 2073ms [Q B C E H I K]
time 1026ms: Process B started using the CPU for 188ms burst [Q C E H I K]
time 1048ms: Process A (tau 580ms) completed I/O; added to ready queue [Q A C E H I K]
time 1214ms: Process B completed a CPU burst; 87 bursts to go [Q A C E H I K]
time 1214ms: Recalculated tau = 471ms for process B [Q A C E H I K]
time 1214ms: Process B switching out of CPU; will block on I/O until time 1375ms [Q A C E H I K]
time 1218ms: Process A started using the CPU for 596ms burst [Q C E H I K]
time 1375ms: Process B (tau 471ms) completed I/O; added to ready queue [Q B C E H I K]
time 1656ms: Process D (tau 1000ms) arrived; added to ready queue [Q B C D E H I K]
time 1710ms: Process L (tau 1000ms) arrived; added to ready queue [Q B C D E H I K L]
time 1814ms: Process A completed a CPU burst; 17 bursts to go [Q B C D E H I K L]
time 1814ms: Recalculated tau = 588ms for process A [Q B C D E H I K L]
time 1814ms: Process A switching out of CPU; will block on I/O until time 1972ms [Q B C D E H I K L]
time 1818ms: Process B started using the CPU for 558ms burst [Q C D E H I K L]
time 1972ms: Process A (tau 588ms) completed I/O; added to ready queue [Q A C D E H I K L]
time 2073ms: Process F (tau 654ms) completed I/O; added to ready queue [Q A F C D E H I K L]
time 2263ms: Process G (tau 1000ms) arrived; added to ready queue [Q A F C D E G H I K L]
time 2376ms: Process B completed a CPU burst; 86 bursts to go [Q A F C D E G H I K L]
time 2376ms: Recalculated tau = 515ms for process B [Q A F C D E G H I K L]
time 2376ms: Process B switching out of CPU; will block on I/O until time 2411ms [Q A F C D E G H I K L]
time 2380ms: Process A started using the CPU for 287ms burst [Q F C D E G H I K L]
time 2411ms: Process B (tau 515ms) completed I/O; added to ready queue [Q B F C D E G H I K L]
time 2667ms: Process A completed a CPU burst; 16 bursts to go [Q B F C D E G H I K L]
time 2667ms: Recalculated tau = 438ms for process A [Q B F C D E G H I K L]
time 2667ms: Process A switching out of CPU; will block on I/O until time 2814ms [Q B F C D E G H I K L]
time 2671ms: Process B started using the CPU for 270ms burst [Q F C D E G H I K L]
time 2754ms: Process J (tau 1000ms) arrived; added to ready queue [Q F C D E G H I J K L]
time 2814ms: Process A (tau 438ms) completed I/O; added to ready queue [Q A F C D E G H I J K L]
time 2941ms: Process B completed a CPU burst; 85 bursts to go [Q A F C D E G H I J K L]
time 2941ms: Recalculated tau = 393ms for process B [Q A F C D E G H I J K L]
time 2941ms: Process B switching out of CPU; will block on I/O until time 3917ms [Q A F C D E G H I J K L]
time 2945ms: Process A started using the CPU for 2396ms burst [Q F C D E G H I J K L]
time 3917ms: Process B (tau 393ms) completed I/O; added to ready queue [Q B F C D E G H I J K L]
time 5341ms: Process A completed a CPU burst; 15 bursts to go [Q B F C D E G H I J K L]
time 5341ms: Recalculated tau = 1417ms for process A [Q B F C D E G H I J K L]
time 5341ms: Process A switching out of CPU; will block on I/O until time 5992ms [Q B F C D E G H I J K L]
time 5345ms: Process B started using the CPU for 1451ms burst [Q F C D E G H I J K L]
time 5992ms: Process A (tau 1417ms) completed I/O; added to ready queue [Q F C D E G H I J K L A]
time 6796ms: Process B completed a CPU burst; 84 bursts to go [Q F C D E G H I J K L A]
time 6796ms: Recalculated tau = 922ms for process B [Q F C D E G H I J K L A]
time 6796ms: Process B switching out of CPU; will block on I/O until time 6897ms [Q F C D E G H I J K L A]
time 6800ms: Process F started using the CPU for 156ms burst [Q C D E G H I J K L A]
time 6897ms: Process B (tau 922ms) completed I/O; added to ready queue [Q B C D E G H I J K L A]
time 6956ms: Process F completed a CPU burst; 85 bursts to go [Q B C D E G H I J K L A]
time 6956ms: Recalculated tau = 405ms for process F [Q B C D E G H I J K L A]
time 6956ms: Process F switching out of CPU; will block on I/O until time 7485ms [Q B C D E G H I J K L A]
time 6960ms: Process B started using the CPU for 985ms burst [Q C D E G H I J K L A]
time 7485ms: Process F (tau 405ms) completed I/O; added to ready queue [Q F C D E G H I J K L A]
time 7945ms: Process B completed a CPU burst; 83 bursts to go [Q F C D E G H I J K L A]
time 7945ms: Recalculated tau = 954ms for process B [Q F C D E G H I J K L A]
time 7945ms: Process B switching out of CPU; will block on I/O until time 8252ms [Q F C D E G H I J K L A]
time 7949ms: Process F started using the CPU for 1016ms burst [Q C D E G H I J K L A]
time 8252ms: Process B (tau 954ms) completed I/O; added to ready queue [Q B C D E G H I J K L A]
time 8965ms: Process F completed a CPU burst; 84 bursts to go [Q B C D E G H I J K L A]
time 8965ms: Recalculated tau = 711ms for process F [Q B C D E G H I J K L A]
time 8965ms: Process F switching out of CPU; will block on I/O until time 10186ms [Q B C D E G H I J K L A]
time 8969ms: Process B started using the CPU for 1288ms burst [Q C D E G H I J K L A]
time 10186ms: Process F (tau 711ms) completed I/O; added to ready queue [Q F C D E G H I J K L A]
time 10257ms: Process B completed a CPU burst; 82 bursts to go [Q F C D E G H I J K L A]
time 10257ms: Recalculated tau = 1121ms for process B [Q F C D E G H I J K L A]
time 10257ms: Process B switching out of CPU; will block on I/O until time 12622ms [Q F C D E G H I J K L A]
time 10261ms: Process F started using the CPU for 835ms burst [Q C D E G H I J K L A]
time 11096ms: Process F completed a CPU burst; 83 bursts to go [Q C D E G H I J K L A]
time 11096ms: Recalculated tau = 773ms for process F [Q C D E G H I J K L A]
time 11096ms: Process F switching out of CPU; will block on I/O until time 11764ms [Q C D E G H I J K L A]
time 11100ms: Process C started using the CPU for 1227ms burst [Q D E G H I J K L A]
time 11764ms: Process F (tau 773ms) completed I/O; added to ready queue [Q F D E G H I J K L A]
time 12327ms: Process C completed a CPU burst; 80 bursts to go [Q F D E G H I J K L A]
time 12327ms: Recalculated tau = 1114ms for process C [Q F D E G H I J K L A]
time 12327ms: Process C switching out of CPU; will block on I/O until time 12379ms [Q F D E G H I J K L A]
time 12331ms: Process F started using the CPU for 655ms burst [Q D E G H I J K L A]
time 12379ms: Process C (tau 1114ms) completed I/O; added to ready queue [Q D E G H I J K L C A]
time 12622ms: Process B (tau 1121ms) completed I/O; added to ready queue [Q D E G H I J K L C B A]
time 12986ms: Process F completed a CPU burst; 82 bursts to go [Q D E G H I J K L C B A]
time 12986ms: Recalculated tau = 714ms for process F [Q D E G H I J K L C B A]
time 12986ms: Process F switching out of CPU; will block on I/O until time 14168ms [Q D E G H I J K L C B A]
time 12990ms: Process D started using the CPU for 1000ms burst [Q E G H I J K L C B A]
time 13990ms: Process D completed a CPU burst; 73 bursts to go [Q E G H I J K L C B A]
time 13990ms: Recalculated tau = 1000ms for process D [Q E G H I J K L C B A]
time 13990ms: Process D switching out of CPU; will block on I/O until time 14181ms [Q E G H I J K L C B A]
time 13994ms: Process E started using the CPU for 1032ms burst [Q G H I J K L C B A]
time 14168ms: Process F (tau 714ms) completed I/O; added to ready queue [Q F G H I J K L C B A]
time 14181ms: Process D (tau 1000ms) completed I/O; added to ready queue [Q F D G H I J K L C B A]
time 15026ms: Process E completed a CPU burst; 32 bursts to go [Q F D G H I J K L C B A]
time 15026ms: Recalculated tau = 1016ms for process E [Q F D G H I J K L C B A]
time 15026ms: Process E switching out of CPU; will block on I/O until time 15286ms [Q F D G H I J K L C B A]
time 15030ms: Process F started using the CPU for 5ms burst [Q D G H I J K L C B A]
time 15035ms: Process F completed a CPU burst; 81 bursts to go [Q D G H I J K L C B A]
time 15035ms: Recalculated tau = 360ms for process F [Q D G H I J K L C B A]
time 15035ms: Process F switching out of CPU; will block on I/O until time 15305ms [Q D G H I J K L C B A]
time 15039ms: Process D started using the CPU for 1980ms burst [Q G H I J K L C B A]
time 15286ms: Process E (tau 1016ms) completed I/O; added to ready queue [Q G H I J K L E C B A]
time 15305ms: Process F (tau 360ms) completed I/O; added to ready queue [Q F G H I J K L E C B A]
time 17019ms: Process D completed a CPU burst; 72 bursts to go [Q F G H I J K L E C B A]
time 17019ms: Recalculated tau = 1490ms for process D [Q F G H I J K L E C B A]
time 17019ms: Process D switching out of CPU; will block on I/O until time 19676ms [Q F G H I J K L E C B A]
time 17023ms: Process F started using the CPU for 447ms burst [Q G H I J K L E C B A]
time 17470ms: Process F completed a CPU burst; 80 bursts to go [Q G H I J K L E C B A]
time 17470ms: Recalculated tau = 404ms for process F [Q G H I J K L E C B A]
time 17470ms: Process F switching out of CPU; will block on I/O until time 18714ms [Q G H I J K L E C B A]
time 17474ms: Process G started using the CPU for 683ms burst [Q H I J K L E C B A]
time 18157ms: Process G completed a CPU burst; 62 bursts to go [Q H I J K L E C B A]
time 18157ms: Recalculated tau = 842ms for process G [Q H I J K L E C B A]
time 18157ms: Process G switching out of CPU; will block on I/O until time 18387ms [Q H I J K L E C B A]
time 18161ms: Process H started using the CPU for 1781ms burst [Q I J K L E C B A]
time 18387ms: Process G (tau 842ms) completed I/O; added to ready queue [Q G I J K L E C B A]
time 18714ms: Process F (tau 404ms) completed I/O; added to ready queue [Q F G I J K L E C B A]
time 19676ms: Process D (tau 1490ms) completed I/O; added to ready queue [Q F G I J K L E C B A D]
time 19942ms: Process H completed a CPU burst; 11 bursts to go [Q F G I J K L E C B A D]
time 19942ms: Recalculated tau = 1391ms for process H [Q F G I J K L E C B A D]
time 19942ms: Process H switching out of CPU; will block on I/O until time 21607ms [Q F G I J K L E C B A D]
time 19946ms: Process F started using the CPU for 2906ms burst [Q G I J K L E C B A D]
time 21607ms: Process H (tau 1391ms) completed I/O; added to ready queue [Q G I J K L E C B H A D]
time 22852ms: Process F completed a CPU burst; 79 bursts to go [Q G I J K L E C B H A D]
time 22852ms: Recalculated tau = 1655ms for process F [Q G I J K L E C B H A D]
time 22852ms: Process F switching out of CPU; will block on I/O until time 24042ms [Q G I J K L E C B H A D]
time 22856ms: Process G started using the CPU for 1421ms burst [Q I J K L E C B H A D]
time 24042ms: Process F (tau 1655ms) completed I/O; added to ready queue [Q I J K L E C B H A D F]
time 24277ms: Process G completed a CPU burst; 61 bursts to go [Q I J K L E C B H A D F]
time 24277ms: Recalculated tau = 1132ms for process G [Q I J K L E C B H A D F]
time 24277ms: Process G switching out of CPU; will block on I/O until time 25481ms [Q I J K L E C B H A D F]
time 24281ms: Process I started using the CPU for 532ms burst [Q J K L E C B H A D F]
time 24813ms: Process I completed a CPU burst; 7 bursts to go [Q J K L E C B H A D F]
time 24813ms: Recalculated tau = 766ms for process I [Q J K L E C B H A D F]
time 24813ms: Process I switching out of CPU; will block on I/O until time 24902ms [Q J K L E C B H A D F]
time 24817ms: Process J started using the CPU for 1471ms burst [Q K L E C B H A D F]
time 24902ms: Process I (tau 766ms) completed I/O; added to ready queue [Q I K L E C B H A D F]
time 25481ms: Process G (tau 1132ms) completed I/O; added to ready queue [Q I K L E C B G H A D F]
time 26288ms: Process J completed a CPU burst; 32 bursts to go [Q I K L E C B G H A D F]
time 26288ms: Recalculated tau = 1236ms for process J [Q I K L E C B G H A D F]
time 26288ms: Process J switching out of CPU; will block on I/O until time 26574ms [Q I K L E C B G H A D F]
time 26292ms: Process I started using the CPU for 41ms burst [Q K L E C B G H A D F]
time 26333ms: Process I completed a CPU burst; 6 bursts to go [Q K L E C B G H A D F]
time 26333ms: Recalculated tau = 404ms for process I [Q K L E C B G H A D F]
time 26333ms: Process I switching out of CPU; will block on I/O until time 28219ms [Q K L E C B G H A D F]
time 26337ms: Process K started using the CPU for 543ms burst [Q L E C B G H A D F]
time 26574ms: Process J (tau 1236ms) completed I/O; added to ready queue [Q L E C B G J H A D F]
time 26880ms: Process K completed a CPU burst; 8 bursts to go [Q L E C B G J H A D F]
time 26880ms: Recalculated tau = 772ms for process K [Q L E C B G J H A D F]
time 26880ms: Process K switching out of CPU; will block on I/O until time 27975ms [Q L E C B G J H A D F]
time 26884ms: Process L started using the CPU for 1057ms burst [Q E C B G J H A D F]
time 27941ms: Process L completed a CPU burst; 16 bursts to go [Q E C B G J H A D F]
time 27941ms: Recalculated tau = 1029ms for process L [Q E C B G J H A D F]
time 27941ms: Process L switching out of CPU; will block on I/O until time 28068ms [Q E C B G J H A D F]
time 27945ms: Process E started using the CPU for 922ms burst [Q C B G J H A D F]
time 27975ms: Process K (tau 772ms) completed I/O; added to ready queue [Q K C B G J H A D F]
time 28068ms: Process L (tau 1029ms) completed I/O; added to ready queue [Q K L C B G J H A D F]
time 28219ms: Process I (tau 404ms) completed I/O; added to ready queue [Q I K L C B G J H A D F]
time 28867ms: Process E completed a CPU burst; 31 bursts to go [Q I K L C B G J H A D F]
time 28867ms: Recalculated tau = 969ms for process E [Q I K L C B G J H A D F]
time 28867ms: Process E switching out of CPU; will block on I/O until time 29160ms [Q I K L C B G J H A D F]
time 28871ms: Process I started using the CPU for 2399ms burst [Q K L C B G J H A D F]
time 29160ms: Process E (tau 969ms) completed I/O; added to ready queue [Q K E L C B G J H A D F]
time 31270ms: Process I completed a CPU burst; 5 bursts to go [Q K E L C B G J H A D F]
time 31270ms: Recalculated tau = 1402ms for process I [Q K E L C B G J H A D F]
time 31270ms: Process I switching out of CPU; will block on I/O until time 32476ms [Q K E L C B G J H A D F]
time 31274ms: Process K started using the CPU for 91ms burst [Q E L C B G J H A D F]
time 31365ms: Process K completed a CPU burst; 7 bursts to go [Q E L C B G J H A D F]
time 31365ms: Recalculated tau = 432ms for process K [Q E L C B G J H A D F]
time 31365ms: Process K switching out of CPU; will block on I/O until time 32124ms [Q E L C B G J H A D F]
time 31369ms: Process E started using the CPU for 129ms burst [Q L C B G J H A D F]
time 31498ms: Process E completed a CPU burst; 30 bursts to go [Q L C B G J H A D F]
time 31498ms: Recalculated tau = 549ms for process E [Q L C B G J H A D F]
time 31498ms: Process E switching out of CPU; will block on I/O until time 32641ms [Q L C B G J H A D F]
time 31502ms: Process L started using the CPU for 582ms burst [Q C B G J H A D F]
time 32084ms: Process L completed a CPU burst; 15 bursts to go [Q C B G J H A D F]
time 32084ms: Recalculated tau = 806ms for process L [Q C B G J H A D F]
time 32084ms: Process L switching out of CPU; will block on I/O until time 32448ms [Q C B G J H A D F]
time 32088ms: Process C started using the CPU for 444ms burst [Q B G J H A D F]
time 32124ms: Process K (tau 432ms) completed I/O; added to ready queue [Q K B G J H A D F]
time 32448ms: Process L (tau 806ms) completed I/O; added to ready queue [Q K L B G J H A D F]
time 32476ms: Process I (tau 1402ms) completed I/O; added to ready queue [Q K L B G J H I A D F]
time 32532ms: Process C completed a CPU burst; 79 bursts to go [Q K L B G J H I A D F]
time 32532ms: Recalculated tau = 779ms for process C [Q K L B G J H I A D F]
time 32532ms: Process C switching out of CPU; will block on I/O until time 32852ms [Q K L B G J H I A D F]
time 32536ms: Process K started using the CPU for 103ms burst [Q L B G J H I A D F]
time 32639ms: Process K completed a CPU burst; 6 bursts to go [Q L B G J H I A D F]
time 32639ms: Recalculated tau = 268ms for process K [Q L B G J H I A D F]
time 32639ms: Process K switching out of CPU; will block on I/O until time 34245ms [Q L B G J H I A D F]
time 32641ms: Process E (tau 549ms) completed I/O; added to ready queue [Q E L B G J H I A D F]
time 32643ms: Process E started using the CPU for 720ms burst [Q L B G J H I A D F]
time 32852ms: Process C (tau 779ms) completed I/O; added to ready queue [Q C L B G J H I A D F]
time 33363ms: Process E completed a CPU burst; 29 bursts to go [Q C L B G J H I A D F]
time 33363ms: Recalculated tau = 635ms for process E [Q C L B G J H I A D F]
time 33363ms: Process E switching out of CPU; will block on I/O until time 33744ms [Q C L B G J H I A D F]
time 33367ms: Process C started using the CPU for 2962ms burst [Q L B G J H I A D F]
time 33744ms: Process E (tau 635ms) completed I/O; added to ready queue [Q E L B G J H I A D F]
time 34245ms: Process K (tau 268ms) completed I/O; added to ready queue [Q K E L B G J H I A D F]
time 36329ms: Process C completed a CPU burst; 78 bursts to go [Q K E L B G J H I A D F]
time 36329ms: Recalculated tau = 1871ms for process C [Q K E L B G J H I A D F]
time 36329ms: Process C switching out of CPU; will block on I/O until time 36560ms [Q K E L B G J H I A D F]
time 36333ms: Process K started using the CPU for 1388ms burst [Q E L B G J H I A D F]
time 36560ms: Process C (tau 1871ms) completed I/O; added to ready queue [Q E L B G J H I A D F C]
time 37721ms: Process K completed a CPU burst; 5 bursts to go [Q E L B G J H I A D F C]
time 37721ms: Recalculated tau = 828ms for process K [Q E L B G J H I A D F C]
time 37721ms: Process K switching out of CPU; will block on I/O until time 39004ms [Q E L B G J H I A D F C]
time 37725ms: Process E started using the CPU for 1288ms burst [Q L B G J H I A D F C]
time 39004ms: Process K (tau 828ms) completed I/O; added to ready queue [Q L K B G J H I A D F C]
time 39013ms: Process E completed a CPU burst; 28 bursts to go [Q L K B G J H I A D F C]
time 39013ms: Recalculated tau = 962ms for process E [Q L K B G J H I A D F C]
time 39013ms: Process E switching out of CPU; will block on I/O until time 41023ms [Q L K B G J H I A D F C]
time 39017ms: Process L started using the CPU for 1569ms burst [Q K B G J H I A D F C]
time 40586ms: Process L completed a CPU burst; 14 bursts to go [Q K B G J H I A D F C]
time 40586ms: Recalculated tau = 1188ms for process L [Q K B G J H I A D F C]
time 40586ms: Process L switching out of CPU; will block on I/O until time 41774ms [Q K B G J H I A D F C]
time 40590ms: Process K started using the CPU for 2259ms burst [Q B G J H I A D F C]
time 41023ms: Process E (tau 962ms) completed I/O; added to ready queue [Q E B G J H I A D F C]
time 41774ms: Process L (tau 1188ms) completed I/O; added to ready queue [Q E B G L J H I A D F C]
time 42849ms: Process K completed a CPU burst; 4 bursts to go [Q E B G L J H I A D F C]
time 42849ms: Recalculated tau = 1544ms for process K [Q E B G L J H I A D F C]
time 42849ms: Process K switching out of CPU; will block on I/O until time 43172ms [Q E B G L J H I A D F C]
time 42853ms: Process E started using the CPU for 41ms burst [Q B G L J H I A D F C]
time 42894ms: Process E completed a CPU burst; 27 bursts to go [Q B G L J H I A D F C]
time 42894ms: Recalculated tau = 502ms for process E [Q B G L J H I A D F C]
time 42894ms: Process E switching out of CPU; will block on I/O until time 42991ms [Q B G L J H I A D F C]
time 42898ms: Process B started using the CPU for 2835ms burst [Q G L J H I A D F C]
time 42991ms: Process E (tau 502ms) completed I/O; added to ready queue [Q E G L J H I A D F C]
time 43172ms: Process K (tau 1544ms) completed I/O; added to ready queue [Q E G L J H I A D K F C]
time 45733ms: Process B completed a CPU burst; 81 bursts to go [Q E G L J H I A D K F C]
time 45733ms: Recalculated tau = 1978ms for process B [Q E G L J H I A D K F C]
time 45733ms: Process B switching out of CPU; will block on I/O until time 46750ms [Q E G L J H I A D K F C]
time 45737ms: Process E started using the CPU for 263ms burst [Q G L J H I A D K F C]
time 46000ms: Process E completed a CPU burst; 26 bursts to go [Q G L J H I A D K F C]
time 46000ms: Recalculated tau = 383ms for process E [Q G L J H I A D K F C]
time 46000ms: Process E switching out of CPU; will block on I/O until time 46394ms [Q G L J H I A D K F C]
time 46004ms: Process G started using the CPU for 1277ms burst [Q L J H I A D K F C]
time 46394ms: Process E (tau 383ms) completed I/O; added to ready queue [Q E L J H I A D K F C]
time 46750ms: Process B (tau 1978ms) completed I/O; added to ready queue [Q E L J H I A D K F C B]
time 47281ms: Process G completed a CPU burst; 60 bursts to go [Q E L J H I A D K F C B]
time 47281ms: Recalculated tau = 1205ms for process G [Q E L J H I A D K F C B]
time 47281ms: Process G switching out of CPU; will block on I/O until time 47521ms [Q E L J H I A D K F C B]
time 47285ms: Process E started using the CPU for 1042ms burst [Q L J H I A D K F C B]
time 47521ms: Process G (tau 1205ms) completed I/O; added to ready queue [Q L G J H I A D K F C B]
time 48327ms: Process E completed a CPU burst; 25 bursts to go [Q L G J H I A D K F C B]
time 48327ms: Recalculated tau = 713ms for process E [Q L G J H I A D K F C B]
time 48327ms: Process E switching out of CPU; will block on I/O until time 49210ms [Q L G J H I A D K F C B]
time 48331ms: Process L started using the CPU for 149ms burst [Q G J H I A D K F C B]
time 48480ms: Process L completed a CPU burst; 13 bursts to go [Q G J H I A D K F C B]
time 48480ms: Recalculated tau = 669ms for process L [Q G J H I A D K F C B]
time 48480ms: Process L switching out of CPU; will block on I/O until time 48649ms [Q G J H I A D K F C B]
time 48484ms: Process G started using the CPU for 796ms burst [Q J H I A D K F C B]
time 48649ms: Process L (tau 669ms) completed I/O; added to ready queue [Q L J H I A D K F C B]
time 49210ms: Process E (tau 713ms) completed I/O; added to ready queue [Q L E J H I A D K F C B]
time 49280ms: Process G completed a CPU burst; 59 bursts to go [Q L E J H I A D K F C B]
time 49280ms: Recalculated tau = 1001ms for process G [Q L E J H I A D K F C B]
time 49280ms: Process G switching out of CPU; will block on I/O until time 51466ms [Q L E J H I A D K F C B]
time 49284ms: Process L started using the CPU for 76ms burst [Q E J H I A D K F C B]
time 49360ms: Process L completed a CPU burst; 12 bursts to go [Q E J H I A D K F C B]
time 49360ms: Recalculated tau = 373ms for process L [Q E J H I A D K F C B]
time 49360ms: Process L switching out of CPU; will block on I/O until time 49441ms [Q E J H I A D K F C B]
time 49364ms: Process E started using the CPU for 305ms burst [Q J H I A D K F C B]
time 49441ms: Process L (tau 373ms) completed I/O; added to ready queue [Q L J H I A D K F C B]
time 49669ms: Process E completed a CPU burst; 24 bursts to go [Q L J H I A D K F C B]
time 49669ms: Recalculated tau = 509ms for process E [Q L J H I A D K F C B]
time 49669ms: Process E switching out of CPU; will block on I/O until time 51800ms [Q L J H I A D K F C B]
time 49673ms: Process L started using the CPU for 1125ms burst [Q J H I A D K F C B]
time 50798ms: Process L completed a CPU burst; 11 bursts to go [Q J H I A D K F C B]
time 50798ms: Recalculated tau = 749ms for process L [Q J H I A D K F C B]
time 50798ms: Process L switching out of CPU; will block on I/O until time 51108ms [Q J H I A D K F C B]
time 50802ms: Process J started using the CPU for 1788ms burst [Q H I A D K F C B]
time 51108ms: Process L (tau 749ms) completed I/O; added to ready queue [Q L H I A D K F C B]
time 51466ms: Process G (tau 1001ms) completed I/O; added to ready queue [Q L G H I A D K F C B]
time 51800ms: Process E (tau 509ms) completed I/O; added to ready queue [Q E L G H I A D K F C B]
time 52590ms: Process J completed a CPU burst; 31 bursts to go [Q E L G H I A D K F C B]
time 52590ms: Recalculated tau = 1512ms for process J [Q E L G H I A D K F C B]
time 52590ms: Process J switching out of CPU; will block on I/O until time 54021ms [Q E L G H I A D K F C B]
time 52594ms: Process E started using the CPU for 2014ms burst [Q L G H I A D K F C B]
time 54021ms: Process J (tau 1512ms) completed I/O; added to ready queue [Q L G H I A D J K F C B]
time 54608ms: Process E completed a CPU burst; 23 bursts to go [Q L G H I A D J K F C B]
time 54608ms: Recalculated tau = 1262ms for process E [Q L G H I A D J K F C B]
time 54608ms: Process E switching out of CPU; will block on I/O until time 54877ms [Q L G H I A D J K F C B]
time 54612ms: Process L started using the CPU for 1936ms burst [Q G H I A D J K F C B]
time 54877ms: Process E (tau 1262ms) completed I/O; added to ready queue [Q G E H I A D J K F C B]
time 56548ms: Process L completed a CPU burst; 10 bursts to go [Q G E H I A D J K F C B]
time 56548ms: Recalculated tau = 1343ms for process L [Q G E H I A D J K F C B]
time 56548ms: Process L switching out of CPU; will block on I/O until time 57567ms [Q G E H I A D J K F C B]
time 56552ms: Process G started using the CPU for 1174ms burst [Q E H I A D J K F C B]
time 57567ms: Process L (tau 1343ms) completed I/O; added to ready queue [Q E L H I A D J K F C B]
time 57726ms: Process G completed a CPU burst; 58 bursts to go [Q E L H I A D J K F C B]
time 57726ms: Recalculated tau = 1088ms for process G [Q E L H I A D J K F C B]
time 57726ms: Process G switching out of CPU; will block on I/O until time 59370ms [Q E L H I A D J K F C B]
time 57730ms: Process E started using the CPU for 1533ms burst [Q L H I A D J K F C B]
time 59263ms: Process E completed a CPU burst; 22 bursts to go [Q L H I A D J K F C B]
time 59263ms: Recalculated tau = 1398ms for process E [Q L H I A D J K F C B]
time 59263ms: Process E switching out of CPU; will block on I/O until time 61251ms [Q L H I A D J K F C B]
time 59267ms: Process L started using the CPU for 1021ms burst [Q H I A D J K F C B]
time 59370ms: Process G (tau 1088ms) completed I/O; added to ready queue [Q G H I A D J K F C B]
time 60288ms: Process L completed a CPU burst; 9 bursts to go [Q G H I A D J K F C B]
time 60288ms: Recalculated tau = 1182ms for process L [Q G H I A D J K F C B]
time 60288ms: Process L switching out of CPU; will block on I/O until time 61752ms [Q G H I A D J K F C B]
time 60292ms: Process G started using the CPU for 344ms burst [Q H I A D J K F C B]
time 60636ms: Process G completed a CPU burst; 57 bursts to go [Q H I A D J K F C B]
time 60636ms: Recalculated tau = 716ms for process G [Q H I A D J K F C B]
time 60636ms: Process G switching out of CPU; will block on I/O until time 61789ms [Q H I A D J K F C B]
time 60640ms: Process H started using the CPU for 2035ms burst [Q I A D J K F C B]
time 61251ms: Process E (tau 1398ms) completed I/O; added to ready queue [Q E I A D J K F C B]
time 61752ms: Process L (tau 1182ms) completed I/O; added to ready queue [Q L E I A D J K F C B]
time 61789ms: Process G (tau 716ms) completed I/O; added to ready queue [Q G L E I A D J K F C B]
time 62675ms: Process H completed a CPU burst; 10 bursts to go [Q G L E I A D J K F C B]
time 62675ms: Recalculated tau = 1713ms for process H [Q G L E I A D J K F C B]
time 62675ms: Process H switching out of CPU; will block on I/O until time 63014ms [Q G L E I A D J K F C B]
time 62679ms: Process G started using the CPU for 818ms burst [Q L E I A D J K F C B]
time 63014ms: Process H (tau 1713ms) completed I/O; added to ready queue [Q L E I A D J K F H C B]
time 63497ms: Process G completed a CPU burst; 56 bursts to go [Q L E I A D J K F H C B]
time 63497ms: Recalculated tau = 767ms for process G [Q L E I A D J K F H C B]
time 63497ms: Process G switching out of CPU; will block on I/O until time 64660ms [Q L E I A D J K F H C B]
time 63501ms: Process L started using the CPU for 696ms burst [Q E I A D J K F H C B]
time 64197ms: Process L completed a CPU burst; 8 bursts to go [Q E I A D J K F H C B]
time 64197ms: Recalculated tau = 939ms for process L [Q E I A D J K F H C B]
time 64197ms: Process L switching out of CPU; will block on I/O until time 64566ms [Q E I A D J K F H C B]
time 64201ms: Process E started using the CPU for 344ms burst [Q I A D J K F H C B]
time 64545ms: Process E completed a CPU burst; 21 bursts to go [Q I A D J K F H C B]
time 64545ms: Recalculated tau = 871ms for process E [Q I A D J K F H C B]
time 64545ms: Process E switching out of CPU; will block on I/O until time 64649ms [Q I A D J K F H C B]
time 64549ms: Process I started using the CPU for 1120ms burst [Q A D J K F H C B]
time 64566ms: Process L (tau 939ms) completed I/O; added to ready queue [Q L A D J K F H C B]
time 64649ms: Process E (tau 871ms) completed I/O; added to ready queue [Q E L A D J K F H C B]
time 64660ms: Process G (tau 767ms) completed I/O; added to ready queue [Q G E L A D J K F H C B]
time 65669ms: Process I completed a CPU burst; 4 bursts to go [Q G E L A D J K F H C B]
time 65669ms: Recalculated tau = 1261ms for process I [Q G E L A D J K F H C B]
time 65669ms: Process I switching out of CPU; will block on I/O until time 66483ms [Q G E L A D J K F H C B]
time 65673ms: Process G started using the CPU for 1493ms burst [Q E L A D J K F H C B]
time 66483ms: Process I (tau 1261ms) completed I/O; added to ready queue [Q E L I A D J K F H C B]
time 67166ms: Process G completed a CPU burst; 55 bursts to go [Q E L I A D J K F H C B]
time 67166ms: Recalculated tau = 1130ms for process G [Q E L I A D J K F H C B]
time 67166ms: Process G switching out of CPU; will block on I/O until time 68090ms [Q E L I A D J K F H C B]
time 67170ms: Process E started using the CPU for 1361ms burst [Q L I A D J K F H C B]
time 68090ms: Process G (tau 1130ms) completed I/O; added to ready queue [Q L G I A D J K F H C B]
time 68531ms: Process E completed a CPU burst; 20 bursts to go [Q L G I A D J K F H C B]
time 68531ms: Recalculated tau = 1116ms for process E [Q L G I A D J K F H C B]
time 68531ms: Process E switching out of CPU; will block on I/O until time 70976ms [Q L G I A D J K F H C B]
time 68535ms: Process L started using the CPU for 203ms burst [Q G I A D J K F H C B]
time 68738ms: Process L completed a CPU burst; 7 bursts to go [Q G I A D J K F H C B]
time 68738ms: Recalculated tau = 571ms for process L [Q G I A D J K F H C B]
time 68738ms: Process L switching out of CPU; will block on I/O until time 69933ms [Q G I A D J K F H C B]
time 68742ms: Process G started using the CPU for 428ms burst [Q I A D J K F H C B]
time 69170ms: Process G completed a CPU burst; 54 bursts to go [Q I A D J K F H C B]
time 69170ms: Recalculated tau = 779ms for process G [Q I A D J K F H C B]
time 69170ms: Process G switching out of CPU; will block on I/O until time 69533ms [Q I A D J K F H C B]
time 69174ms: Process I started using the CPU for 437ms burst [Q A D J K F H C B]
time 69533ms: Process G (tau 779ms) completed I/O; added to ready queue [Q G A D J K F H C B]
time 69611ms: Process I completed a CPU burst; 3 bursts to go [Q G A D J K F H C B]
time 69611ms: Recalculated tau = 849ms for process I [Q G A D J K F H C B]
time 69611ms: Process I switching out of CPU; will block on I/O until time 70142ms [Q G A D J K F H C B]
time 69615ms: Process G started using the CPU for 917ms burst [Q A D J K F H C B]
time 69933ms: Process L (tau 571ms) completed I/O; added to ready queue [Q L A D J K F H C B]
time 70142ms: Process I (tau 849ms) completed I/O; added to ready queue [Q L I A D J K F H C B]
time 70532ms: Process G completed a CPU burst; 53 bursts to go [Q L I A D J K F H C B]
time 70532ms: Recalculated tau = 848ms for process G [Q L I A D J K F H C B]
time 70532ms: Process G switching out of CPU; will block on I/O until time 70907ms [Q L I A D J K F H C B]
time 70536ms: Process L started using the CPU for 468ms burst [Q I A D J K F H C B]
time 70907ms: Process G (tau 848ms) completed I/O; added to ready queue [Q G I A D J K F H C B]
time 70976ms: Process E (tau 1116ms) completed I/O; added to ready queue [Q G I E A D J K F H C B]
time 71004ms: Process L completed a CPU burst; 6 bursts to go [Q G I E A D J K F H C B]
time 71004ms: Recalculated tau = 520ms for process L [Q G I E A D J K F H C B]
time 71004ms: Process L switching out of CPU; will block on I/O until time 71751ms [Q G I E A D J K F H C B]
time 71008ms: Process G started using the CPU for 1039ms burst [Q I E A D J K F H C B]
time 71751ms: Process L (tau 520ms) completed I/O; added to ready queue [Q L I E A D J K F H C B]
time 72047ms: Process G completed a CPU burst; 52 bursts to go [Q L I E A D J K F H C B]
time 72047ms: Recalculated tau = 944ms for process G [Q L I E A D J K F H C B]
time 72047ms: Process G switching out of CPU; will block on I/O until time 72281ms [Q L I E A D J K F H C B]
time 72051ms: Process L started using the CPU for 37ms burst [Q I E A D J K F H C B]
time 72088ms: Process L completed a CPU burst; 5 bursts to go [Q I E A D J K F H C B]
time 72088ms: Recalculated tau = 279ms for process L [Q I E A D J K F H C B]
time 72088ms: Process L switching out of CPU; will block on I/O until time 72691ms [Q I E A D J K F H C B]
time 72092ms: Process I started using the CPU for 38ms burst [Q E A D J K F H C B]
time 72130ms: Process I completed a CPU burst; 2 bursts to go [Q E A D J K F H C B]
time 72130ms: Recalculated tau = 444ms for process I [Q E A D J K F H C B]
time 72130ms: Process I switching out of CPU; will block on I/O until time 72503ms [Q E A D J K F H C B]
time 72134ms: Process E started using the CPU for 2037ms burst [Q A D J K F H C B]
time 72281ms: Process G (tau 944ms) completed I/O; added to ready queue [Q G A D J K F H C B]
time 72503ms: Process I (tau 444ms) completed I/O; added to ready queue [Q I G A D J K F H C B]
time 72691ms: Process L (tau 279ms) completed I/O; added to ready queue [Q L I G A D J K F H C B]
time 74171ms: Process E completed a CPU burst; 19 bursts to go [Q L I G A D J K F H C B]
time 74171ms: Recalculated tau = 1577ms for process E [Q L I G A D J K F H C B]
time 74171ms: Process E switching out of CPU; will block on I/O until time 76612ms [Q L I G A D J K F H C B]
time 74175ms: Process L started using the CPU for 150ms burst [Q I G A D J K F H C B]
time 74325ms: Process L completed a CPU burst; 4 bursts to go [Q I G A D J K F H C B]
time 74325ms: Recalculated tau = 215ms for process L [Q I G A D J K F H C B]
time 74325ms: Process L switching out of CPU; will block on I/O until time 75729ms [Q I G A D J K F H C B]
time 74329ms: Process I started using the CPU for 721ms burst [Q G A D J K F H C B]
time 75050ms: Process I completed a CPU burst; 1 burst to go [Q G A D J K F H C B]
time 75050ms: Recalculated tau = 583ms for process I [Q G A D J K F H C B]
time 75050ms: Process I switching out of CPU; will block on I/O until time 75480ms [Q G A D J K F H C B]
time 75054ms: Process G started using the CPU for 461ms burst [Q A D J K F H C B]
time 75480ms: Process I (tau 583ms) completed I/O; added to ready queue [Q I A D J K F H C B]
time 75515ms: Process G completed a CPU burst; 51 bursts to go [Q I A D J K F H C B]
time 75515ms: Recalculated tau = 703ms for process G [Q I A D J K F H C B]
time 75515ms: Process G switching out of CPU; will block on I/O until time 75600ms [Q I A D J K F H C B]
time 75519ms: Process I started using the CPU for 352ms burst [Q A D J K F H C B]
time 75600ms: Process G (tau 703ms) completed I/O; added to ready queue [Q G A D J K F H C B]
time 75729ms: Process L (tau 215ms) completed I/O; added to ready queue [Q L G A D J K F H C B]
time 75871ms: Process I terminated [Q L G A D J K F H C B]
time 75875ms: Process L started using the CPU for 1868ms burst [Q G A D J K F H C B]
time 76612ms: Process E (tau 1577ms) completed I/O; added to ready queue [Q G A D J K E F H C B]
time 77743ms: Process L completed a CPU burst; 3 bursts to go [Q G A D J K E F H C B]
time 77743ms: Recalculated tau = 1042ms for process L [Q G A D J K E F H C B]
time 77743ms: Process L switching out of CPU; will block on I/O until time 78599ms [Q G A D J K E F H C B]
time 77747ms: Process G started using the CPU for 1157ms burst [Q A D J K E F H C B]
time 78599ms: Process L (tau 1042ms) completed I/O; added to ready queue [Q L A D J K E F H C B]
time 78904ms: Process G completed a CPU burst; 50 bursts to go [Q L A D J K E F H C B]
time 78904ms: Recalculated tau = 930ms for process G [Q L A D J K E F H C B]
time 78904ms: Process G switching out of CPU; will block on I/O until time 80403ms [Q L A D J K E F H C B]
time 78908ms: Process L started using the CPU for 356ms burst [Q A D J K E F H C B]
time 79264ms: Process L completed a CPU burst; 2 bursts to go [Q A D J K E F H C B]
time 79264ms: Recalculated tau = 699ms for process L [Q A D J K E F H C B]
time 79264ms: Process L switching out of CPU; will block on I/O until time 80458ms [Q A D J K E F H C B]
time 79268ms: Process A started using the CPU for 953ms burst [Q D J K E F H C B]
time 80221ms: Process A completed a CPU burst; 14 bursts to go [Q D J K E F H C B]
time 80221ms: Recalculated tau = 1185ms for process A [Q D J K E F H C B]
time 80221ms: Process A switching out of CPU; will block on I/O until time 80291ms [Q D J K E F H C B]
time 80225ms: Process D started using the CPU for 1123ms burst [Q J K E F H C B]
time 80291ms: Process A (tau 1185ms) completed I/O; added to ready queue [Q A J K E F H C B]
time 80403ms: Process G (tau 930ms) completed I/O; added to ready queue [Q G A J K E F H C B]
time 80458ms: Process L (tau 699ms) completed I/O; added to ready queue [Q L G A J K E F H C B]
time 81348ms: Process D completed a CPU burst; 71 bursts to go [Q L G A J K E F H C B]
time 81348ms: Recalculated tau = 1307ms for process D [Q L G A J K E F H C B]
time 81348ms: Process D switching out of CPU; will block on I/O until time 81625ms [Q L G A J K E F H C B]
time 81352ms: Process L started using the CPU for 1638ms burst [Q G A J K E F H C B]
time 81625ms: Process D (tau 1307ms) completed I/O; added to ready queue [Q G A D J K E F H C B]
time 82990ms: Process L completed a CPU burst; 1 burst to go [Q G A D J K E F H C B]
time 82990ms: Recalculated tau = 1169ms for process L [Q G A D J K E F H C B]
time 82990ms: Process L switching out of CPU; will block on I/O until time 84090ms [Q G A D J K E F H C B]
time 82994ms: Process G started using the CPU for 87ms burst [Q A D J K E F H C B]
time 83081ms: Process G completed a CPU burst; 49 bursts to go [Q A D J K E F H C B]
time 83081ms: Recalculated tau = 509ms for process G [Q A D J K E F H C B]
time 83081ms: Process G switching out of CPU; will block on I/O until time 84264ms [Q A D J K E F H C B]
time 83085ms: Process A started using the CPU for 54ms burst [Q D J K E F H C B]
time 83139ms: Process A completed a CPU burst; 13 bursts to go [Q D J K E F H C B]
time 83139ms: Recalculated tau = 620ms for process A [Q D J K E F H C B]
time 83139ms: Process A switching out of CPU; will block on I/O until time 84411ms [Q D J K E F H C B]
time 83143ms: Process D started using the CPU for 1779ms burst [Q J K E F H C B]
time 84090ms: Process L (tau 1169ms) completed I/O; added to ready queue [Q L J K E F H C B]
time 84264ms: Process G (tau 509ms) completed I/O; added to ready queue [Q G L J K E F H C B]
time 84411ms: Process A (tau 620ms) completed I/O; added to ready queue [Q G A L J K E F H C B]
time 84922ms: Process D completed a CPU burst; 70 bursts to go [Q G A L J K E F H C B]
time 84922ms: Recalculated tau = 1543ms for process D [Q G A L J K E F H C B]
time 84922ms: Process D switching out of CPU; will block on I/O until time 86195ms [Q G A L J K E F H C B]
time 84926ms: Process G started using the CPU for 870ms burst [Q A L J K E F H C B]
time 85796ms: Process G completed a CPU burst; 48 bursts to go [Q A L J K E F H C B]
time 85796ms: Recalculated tau = 690ms for process G [Q A L J K E F H C B]
time 85796ms: Process G switching out of CPU; will block on I/O until time 85961ms [Q A L J K E F H C B]
time 85800ms: Process A started using the CPU for 179ms burst [Q L J K E F H C B]
time 85961ms: Process G (tau 690ms) completed I/O; added to ready queue [Q G L J K E F H C B]
time 85979ms: Process A completed a CPU burst; 12 bursts to go [Q G L J K E F H C B]
time 85979ms: Recalculated tau = 400ms for process A [Q G L J K E F H C B]
time 85979ms: Process A switching out of CPU; will block on I/O until time 87019ms [Q G L J K E F H C B]
time 85983ms: Process G started using the CPU for 1412ms burst [Q L J K E F H C B]
time 86195ms: Process D (tau 1543ms) completed I/O; added to ready queue [Q L J D K E F H C B]
time 87019ms: Process A (tau 400ms) completed I/O; added to ready queue [Q A L J D K E F H C B]
time 87395ms: Process G completed a CPU burst; 47 bursts to go [Q A L J D K E F H C B]
time 87395ms: Recalculated tau = 1051ms for process G [Q A L J D K E F H C B]
time 87395ms: Process G switching out of CPU; will block on I/O until time 88396ms [Q A L J D K E F H C B]
time 87399ms: Process A started using the CPU for 1034ms burst [Q L J D K E F H C B]
time 88396ms: Process G (tau 1051ms) completed I/O; added to ready queue [Q G L J D K E F H C B]
time 88433ms: Process A completed a CPU burst; 11 bursts to go [Q G L J D K E F H C B]
time 88433ms: Recalculated tau = 717ms for process A [Q G L J D K E F H C B]
time 88433ms: Process A switching out of CPU; will block on I/O until time 89715ms [Q G L J D K E F H C B]
time 88437ms: Process G started using the CPU for 1405ms burst [Q L J D K E F H C B]
time 89715ms: Process A (tau 717ms) completed I/O; added to ready queue [Q A L J D K E F H C B]
time 89842ms: Process G completed a CPU burst; 46 bursts to go [Q A L J D K E F H C B]
time 89842ms: Recalculated tau = 1228ms for process G [Q A L J D K E F H C B]
time 89842ms: Process G switching out of CPU; will block on I/O until time 90190ms [Q A L J D K E F H C B]
time 89846ms: Process A started using the CPU for 527ms burst [Q L J D K E F H C B]
time 90190ms: Process G (tau 1228ms) completed I/O; added to ready queue [Q L G J D K E F H C B]
time 90373ms: Process A completed a CPU burst; 10 bursts to go [Q L G J D K E F H C B]
time 90373ms: Recalculated tau = 622ms for process A [Q L G J D K E F H C B]
time 90373ms: Process A switching out of CPU; will block on I/O until time 91112ms [Q L G J D K E F H C B]
time 90377ms: Process L started using the CPU for 968ms burst [Q G J D K E F H C B]
time 91112ms: Process A (tau 622ms) completed I/O; added to ready queue [Q A G J D K E F H C B]
time 91345ms: Process L terminated [Q A G J D K E F H C B]
time 91349ms: Process A started using the CPU for 1498ms burst [Q G J D K E F H C B]
time 92847ms: Process A completed a CPU burst; 9 bursts to go [Q G J D K E F H C B]
time 92847ms: Recalculated tau = 1060ms for process A [Q G J D K E F H C B]
time 92847ms: Process A switching out of CPU; will block on I/O until time 93176ms [Q G J D K E F H C B]
time 92851ms: Process G started using the CPU for 441ms burst [Q J D K E F H C B]
time 93176ms: Process A (tau 1060ms) completed I/O; added to ready queue [Q A J D K E F H C B]
time 93292ms: Process G completed a CPU burst; 45 bursts to go [Q A J D K E F H C B]
time 93292ms: Recalculated tau = 835ms for process G [Q A J D K E F H C B]
time 93292ms: Process G switching out of CPU; will block on I/O until time 94387ms [Q A J D K E F H C B]
time 93296ms: Process A started using the CPU for 1922ms burst [Q J D K E F H C B]
time 94387ms: Process G (tau 835ms) completed I/O; added to ready queue [Q G J D K E F H C B]
time 95218ms: Process A completed a CPU burst; 8 bursts to go [Q G J D K E F H C B]
time 95218ms: Recalculated tau = 1491ms for process A [Q G J D K E F H C B]
time 95218ms: Process A switching out of CPU; will block on I/O until time 95455ms [Q G J D K E F H C B]
time 95222ms: Process G started using the CPU for 84ms burst [Q J D K E F H C B]
time 95306ms: Process G completed a CPU burst; 44 bursts to go [Q J D K E F H C B]
time 95306ms: Recalculated tau = 460ms for process G [Q J D K E F H C B]
time 95306ms: Process G switching out of CPU; will block on I/O until time 96510ms [Q J D K E F H C B]
time 95310ms: Process J started using the CPU for 410ms burst [Q D K E F H C B]
time 95455ms: Process A (tau 1491ms) completed I/O; added to ready queue [Q A D K E F H C B]
time 95720ms: Process J completed a CPU burst; 30 bursts to go [Q A D K E F H C B]
time 95720ms: Recalculated tau = 961ms for process J [Q A D K E F H C B]
time 95720ms: Process J switching out of CPU; will block on I/O until time 96051ms [Q A D K E F H C B]
time 95724ms: Process A started using the CPU for 557ms burst [Q D K E F H C B]
time 96051ms: Process J (tau 961ms) completed I/O; added to ready queue [Q J D K E F H C B]
time 96281ms: Process A completed a CPU burst; 7 bursts to go [Q J D K E F H C B]
time 96281ms: Recalculated tau = 1024ms for process A [Q J D K E F H C B]
time 96281ms: Process A switching out of CPU; will block on I/O until time 96789ms [Q J D K E F H C B]
time 96285ms: Process J started using the CPU for 1730ms burst [Q D K E F H C B]
time 96510ms: Process G (tau 460ms) completed I/O; added to ready queue [Q G D K E F H C B]
time 96789ms: Process A (tau 1024ms) completed I/O; added to ready queue [Q G A D K E F H C B]
time 98015ms: Process J completed a CPU burst; 29 bursts to go [Q G A D K E F H C B]
time 98015ms: Recalculated tau = 1346ms for process J [Q G A D K E F H C B]
time 98015ms: Process J switching out of CPU; will block on I/O until time 98497ms [Q G A D K E F H C B]
time 98019ms: Process G started using the CPU for 824ms burst [Q A D K E F H C B]
time 98497ms: Process J (tau 1346ms) completed I/O; added to ready queue [Q A J D K E F H C B]
time 98843ms: Process G completed a CPU burst; 43 bursts to go [Q A J D K E F H C B]
time 98843ms: Recalculated tau = 642ms for process G [Q A J D K E F H C B]
time 98843ms: Process G switching out of CPU; will block on I/O until time 99487ms [Q A J D K E F H C B]
time 98847ms: Process A started using the CPU for 169ms burst [Q J D K E F H C B]
time 99016ms: Process A completed a CPU burst; 6 bursts to go [Q J D K E F H C B]
time 99016ms: Recalculated tau = 597ms for process A [Q J D K E F H C B]
time 99016ms: Process A switching out of CPU; will block on I/O until time 99119ms [Q J D K E F H C B]
time 99020ms: Process J started using the CPU for 176ms burst [Q D K E F H C B]
time 99119ms: Process A (tau 597ms) completed I/O; added to ready queue [Q A D K E F H C B]
time 99196ms: Process J completed a CPU burst; 28 bursts to go [Q A D K E F H C B]
time 99196ms: Recalculated tau = 761ms for process J [Q A D K E F H C B]
time 99196ms: Process J switching out of CPU; will block on I/O until time 99258ms [Q A D K E F H C B]
time 99200ms: Process A started using the CPU for 1611ms burst [Q D K E F H C B]
time 99258ms: Process J (tau 761ms) completed I/O; added to ready queue [Q J D K E F H C B]
time 99487ms: Process G (tau 642ms) completed I/O; added to ready queue [Q G J D K E F H C B]
time 100811ms: Process A completed a CPU burst; 5 bursts to go [Q G J D K E F H C B]
time 100811ms: Recalculated tau = 1104ms for process A [Q G J D K E F H C B]
time 100811ms: Process A switching out of CPU; will block on I/O until time 102012ms [Q G J D K E F H C B]
time 100815ms: Process G started using the CPU for 419ms burst [Q J D K E F H C B]
time 101234ms: Process G completed a CPU burst; 42 bursts to go [Q J D K E F H C B]
time 101234ms: Recalculated tau = 531ms for process G [Q J D K E F H C B]
time 101234ms: Process G switching out of CPU; will block on I/O until time 102299ms [Q J D K E F H C B]
time 101238ms: Process J started using the CPU for 1447ms burst [Q D K E F H C B]
time 102012ms: Process A (tau 1104ms) completed I/O; added to ready queue [Q A D K E F H C B]
time 102299ms: Process G (tau 531ms) completed I/O; added to ready queue [Q G A D K E F H C B]
time 102685ms: Process J completed a CPU burst; 27 bursts to go [Q G A D K E F H C B]
time 102685ms: Recalculated tau = 1104ms for process J [Q G A D K E F H C B]
time 102685ms: Process J switching out of CPU; will block on I/O until time 103337ms [Q G A D K E F H C B]
time 102689ms: Process G started using the CPU for 420ms burst [Q A D K E F H C B]
time 103109ms: Process G completed a CPU burst; 41 bursts to go [Q A D K E F H C B]
time 103109ms: Recalculated tau = 476ms for process G [Q A D K E F H C B]
time 103109ms: Process G switching out of CPU; will block on I/O until time 103993ms [Q A D K E F H C B]
time 103113ms: Process A started using the CPU for 872ms burst [Q D K E F H C B]
time 103337ms: Process J (tau 1104ms) completed I/O; added to ready queue [Q J D K E F H C B]
time 103985ms: Process A completed a CPU burst; 4 bursts to go [Q J D K E F H C B]
time 103985ms: Recalculated tau = 988ms for process A [Q J D K E F H C B]
time 103985ms: Process A switching out of CPU; will block on I/O until time 104356ms [Q J D K E F H C B]
time 103989ms: Process J started using the CPU for 196ms burst [Q D K E F H C B]
time 103993ms: Process G (tau 476ms) completed I/O; added to ready queue [Q G D K E F H C B]
time 104185ms: Process J completed a CPU burst; 26 bursts to go [Q G D K E F H C B]
time 104185ms: Recalculated tau = 650ms for process J [Q G D K E F H C B]
time 104185ms: Process J switching out of CPU; will block on I/O until time 105267ms [Q G D K E F H C B]
time 104189ms: Process G started using the CPU for 391ms burst [Q D K E F H C B]
time 104356ms: Process A (tau 988ms) completed I/O; added to ready queue [Q A D K E F H C B]
time 104580ms: Process G completed a CPU burst; 40 bursts to go [Q A D K E F H C B]
time 104580ms: Recalculated tau = 434ms for process G [Q A D K E F H C B]
time 104580ms: Process G switching out of CPU; will block on I/O until time 105018ms [Q A D K E F H C B]
time 104584ms: Process A started using the CPU for 1709ms burst [Q D K E F H C B]
time 105018ms: Process G (tau 434ms) completed I/O; added to ready queue [Q G D K E F H C B]
time 105267ms: Process J (tau 650ms) completed I/O; added to ready queue [Q G J D K E F H C B]
time 106293ms: Process A completed a CPU burst; 3 bursts to go [Q G J D K E F H C B]
time 106293ms: Recalculated tau = 1349ms for process A [Q G J D K E F H C B]
time 106293ms: Process A switching out of CPU; will block on I/O until time 106503ms [Q G J D K E F H C B]
time 106297ms: Process G started using the CPU for 1546ms burst [Q J D K E F H C B]
time 106503ms: Process A (tau 1349ms) completed I/O; added to ready queue [Q J A D K E F H C B]
time 107843ms: Process G completed a CPU burst; 39 bursts to go [Q J A D K E F H C B]
time 107843ms: Recalculated tau = 990ms for process G [Q J A D K E F H C B]
time 107843ms: Process G switching out of CPU; will block on I/O until time 107859ms [Q J A D K E F H C B]
time 107847ms: Process J started using the CPU for 342ms burst [Q A D K E F H C B]
time 107859ms: Process G (tau 990ms) completed I/O; added to ready queue [Q G A D K E F H C B]
time 108189ms: Process J completed a CPU burst; 25 bursts to go [Q G A D K E F H C B]
time 108189ms: Recalculated tau = 496ms for process J [Q G A D K E F H C B]
time 108189ms: Process J switching out of CPU; will block on I/O until time 108560ms [Q G A D K E F H C B]
time 108193ms: Process G started using the CPU for 691ms burst [Q A D K E F H C B]
time 108560ms: Process J (tau 496ms) completed I/O; added to ready queue [Q J A D K E F H C B]
time 108884ms: Process G completed a CPU burst; 38 bursts to go [Q J A D K E F H C B]
time 108884ms: Recalculated tau = 841ms for process G [Q J A D K E F H C B]
time 108884ms: Process G switching out of CPU; will block on I/O until time 108989ms [Q J A D K E F H C B]
time 108888ms: Process J started using the CPU for 721ms burst [Q A D K E F H C B]
time 108989ms: Process G (tau 841ms) completed I/O; added to ready queue [Q G A D K E F H C B]
time 109609ms: Process J completed a CPU burst; 24 bursts to go [Q G A D K E F H C B]
time 109609ms: Recalculated tau = 609ms for process J [Q G A D K E F H C B]
time 109609ms: Process J switching out of CPU; will block on I/O until time 109688ms [Q G A D K E F H C B]
time 109613ms: Process G started using the CPU for 2722ms burst [Q A D K E F H C B]
time 109688ms: Process J (tau 609ms) completed I/O; added to ready queue [Q J A D K E F H C B]
time 112335ms: Process G completed a CPU burst; 37 bursts to go [Q J A D K E F H C B]
time 112335ms: Recalculated tau = 1782ms for process G [Q J A D K E F H C B]
time 112335ms: Process G switching out of CPU; will block on I/O until time 112782ms [Q J A D K E F H C B]
time 112339ms: Process J started using the CPU for 1439ms burst [Q A D K E F H C B]
time 112782ms: Process G (tau 1782ms) completed I/O; added to ready queue [Q A D K E F H G C B]
time 113778ms: Process J completed a CPU burst; 23 bursts to go [Q A D K E F H G C B]
time 113778ms: Recalculated tau = 1024ms for process J [Q A D K E F H G C B]
time 113778ms: Process J switching out of CPU; will block on I/O until time 113915ms [Q A D K E F H G C B]
time 113782ms: Process A started using the CPU for 384ms burst [Q D K E F H G C B]
time 113915ms: Process J (tau 1024ms) completed I/O; added to ready queue [Q J D K E F H G C B]
time 114166ms: Process A completed a CPU burst; 2 bursts to go [Q J D K E F H G C B]
time 114166ms: Recalculated tau = 867ms for process A [Q J D K E F H G C B]
time 114166ms: Process A switching out of CPU; will block on I/O until time 114505ms [Q J D K E F H G C B]
time 114170ms: Process J started using the CPU for 208ms burst [Q D K E F H G C B]
time 114378ms: Process J completed a CPU burst; 22 bursts to go [Q D K E F H G C B]
time 114378ms: Recalculated tau = 616ms for process J [Q D K E F H G C B]
time 114378ms: Process J switching out of CPU; will block on I/O until time 115236ms [Q D K E F H G C B]
time 114382ms: Process D started using the CPU for 914ms burst [Q K E F H G C B]
time 114505ms: Process A (tau 867ms) completed I/O; added to ready queue [Q A K E F H G C B]
time 115236ms: Process J (tau 616ms) completed I/O; added to ready queue [Q J A K E F H G C B]
time 115296ms: Process D completed a CPU burst; 69 bursts to go [Q J A K E F H G C B]
time 115296ms: Recalculated tau = 1229ms for process D [Q J A K E F H G C B]
time 115296ms: Process D switching out of CPU; will block on I/O until time 118091ms [Q J A K E F H G C B]
time 115300ms: Process J started using the CPU for 87ms burst [Q A K E F H G C B]
time 115387ms: Process J completed a CPU burst; 21 bursts to go [Q A K E F H G C B]
time 115387ms: Recalculated tau = 352ms for process J [Q A K E F H G C B]
time 115387ms: Process J switching out of CPU; will block on I/O until time 115990ms [Q A K E F H G C B]
time 115391ms: Process A started using the CPU for 1839ms burst [Q K E F H G C B]
time 115990ms: Process J (tau 352ms) completed I/O; added to ready queue [Q J K E F H G C B]
time 117230ms: Process A completed a CPU burst; 1 burst to go [Q J K E F H G C B]
time 117230ms: Recalculated tau = 1353ms for process A [Q J K E F H G C B]
time 117230ms: Process A switching out of CPU; will block on I/O until time 119929ms [Q J K E F H G C B]
time 117234ms: Process J started using the CPU for 299ms burst [Q K E F H G C B]
time 117533ms: Process J completed a CPU burst; 20 bursts to go [Q K E F H G C B]
time 117533ms: Recalculated tau = 326ms for process J [Q K E F H G C B]
time 117533ms: Process J switching out of CPU; will block on I/O until time 118531ms [Q K E F H G C B]
time 117537ms: Process K started using the CPU for 1471ms burst [Q E F H G C B]
time 118091ms: Process D (tau 1229ms) completed I/O; added to ready queue [Q D E F H G C B]
time 118531ms: Process J (tau 326ms) completed I/O; added to ready queue [Q J D E F H G C B]
time 119008ms: Process K completed a CPU burst; 3 bursts to go [Q J D E F H G C B]
time 119008ms: Recalculated tau = 1508ms for process K [Q J D E F H G C B]
time 119008ms: Process K switching out of CPU; will block on I/O until time 119667ms [Q J D E F H G C B]
time 119012ms: Process J started using the CPU for 1243ms burst [Q D E F H G C B]
time 119667ms: Process K (tau 1508ms) completed I/O; added to ready queue [Q D K E F H G C B]
time 119929ms: Process A (tau 1353ms) completed I/O; added to ready queue [Q D A K E F H G C B]
time 120255ms: Process J completed a CPU burst; 19 bursts to go [Q D A K E F H G C B]
time 120255ms: Recalculated tau = 785ms for process J [Q D A K E F H G C B]
time 120255ms: Process J switching out of CPU; will block on I/O until time 121076ms [Q D A K E F H G C B]
time 120259ms: Process D started using the CPU for 403ms burst [Q A K E F H G C B]
time 120662ms: Process D completed a CPU burst; 68 bursts to go [Q A K E F H G C B]
time 120662ms: Recalculated tau = 816ms for process D [Q A K E F H G C B]
time 120662ms: Process D switching out of CPU; will block on I/O until time 123646ms [Q A K E F H G C B]
time 120666ms: Process A started using the CPU for 832ms burst [Q K E F H G C B]
time 121076ms: Process J (tau 785ms) completed I/O; added to ready queue [Q J K E F H G C B]
time 121498ms: Process A terminated [Q J K E F H G C B]
time 121502ms: Process J started using the CPU for 1134ms burst [Q K E F H G C B]
time 122636ms: Process J completed a CPU burst; 18 bursts to go [Q K E F H G C B]
time 122636ms: Recalculated tau = 960ms for process J [Q K E F H G C B]
time 122636ms: Process J switching out of CPU; will block on I/O until time 122823ms [Q K E F H G C B]
time 122640ms: Process K started using the CPU for 6ms burst [Q E F H G C B]
time 122646ms: Process K completed a CPU burst; 2 bursts to go [Q E F H G C B]
time 122646ms: Recalculated tau = 757ms for process K [Q E F H G C B]
time 122646ms: Process K switching out of CPU; will block on I/O until time 123219ms [Q E F H G C B]
time 122650ms: Process E started using the CPU for 1035ms burst [Q F H G C B]
time 122823ms: Process J (tau 960ms) completed I/O; added to ready queue [Q J F H G C B]
time 123219ms: Process K (tau 757ms) completed I/O; added to ready queue [Q K J F H G C B]
time 123646ms: Process D (tau 816ms) completed I/O; added to ready queue [Q K D J F H G C B]
time 123685ms: Process E completed a CPU burst; 18 bursts to go [Q K D J F H G C B]
time 123685ms: Recalculated tau = 1306ms for process E [Q K D J F H G C B]
time 123685ms: Process E switching out of CPU; will block on I/O until time 123972ms [Q K D J F H G C B]
time 123689ms: Process K started using the CPU for 462ms burst [Q D J F H G C B]
time 123972ms: Process E (tau 1306ms) completed I/O; added to ready queue [Q D J E F H G C B]
time 124151ms: Process K completed a CPU burst; 1 burst to go [Q D J E F H G C B]
time 124151ms: Recalculated tau = 610ms for process K [Q D J E F H G C B]
time 124151ms: Process K switching out of CPU; will block on I/O until time 124507ms [Q D J E F H G C B]
time 124155ms: Process D started using the CPU for 28ms burst [Q J E F H G C B]
time 124183ms: Process D completed a CPU burst; 67 bursts to go [Q J E F H G C B]
time 124183ms: Recalculated tau = 422ms for process D [Q J E F H G C B]
time 124183ms: Process D switching out of CPU; will block on I/O until time 124500ms [Q J E F H G C B]
time 124187ms: Process J started using the CPU for 271ms burst [Q E F H G C B]
time 124458ms: Process J completed a CPU burst; 17 bursts to go [Q E F H G C B]
time 124458ms: Recalculated tau = 616ms for process J [Q E F H G C B]
time 124458ms: Process J switching out of CPU; will block on I/O until time 126321ms [Q E F H G C B]
time 124462ms: Process E started using the CPU for 51ms burst [Q F H G C B]
time 124500ms: Process D (tau 422ms) completed I/O; added to ready queue [Q D F H G C B]
time 124507ms: Process K (tau 610ms) completed I/O; added to ready queue [Q D K F H G C B]
time 124513ms: Process E completed a CPU burst; 17 bursts to go [Q D K F H G C B]
time 124513ms: Recalculated tau = 679ms for process E [Q D K F H G C B]
time 124513ms: Process E switching out of CPU; will block on I/O until time 126770ms [Q D K F H G C B]
time 124517ms: Process D started using the CPU for 409ms burst [Q K F H G C B]
time 124926ms: Process D completed a CPU burst; 66 bursts to go [Q K F H G C B]
time 124926ms: Recalculated tau = 416ms for process D [Q K F H G C B]
time 124926ms: Process D switching out of CPU; will block on I/O until time 125373ms [Q K F H G C B]
time 124930ms: Process K started using the CPU for 121ms burst [Q F H G C B]
time 125051ms: Process K terminated [Q F H G C B]
time 125055ms: Process F started using the CPU for 1486ms burst [Q H G C B]
time 125373ms: Process D (tau 416ms) completed I/O; added to ready queue [Q D H G C B]
time 126321ms: Process J (tau 616ms) completed I/O; added to ready queue [Q D J H G C B]
time 126541ms: Process F completed a CPU burst; 78 bursts to go [Q D J H G C B]
time 126541ms: Recalculated tau = 1571ms for process F [Q D J H G C B]
time 126541ms: Process F switching out of CPU; will block on I/O until time 126867ms [Q D J H G C B]
time 126545ms: Process D started using the CPU for 289ms burst [Q J H G C B]
time 126770ms: Process E (tau 679ms) completed I/O; added to ready queue [Q J E H G C B]
time 126834ms: Process D completed a CPU burst; 65 bursts to go [Q J E H G C B]
time 126834ms: Recalculated tau = 353ms for process D [Q J E H G C B]
time 126834ms: Process D switching out of CPU; will block on I/O until time 127086ms [Q J E H G C B]
time 126838ms: Process J started using the CPU for 996ms burst [Q E H G C B]
time 126867ms: Process F (tau 1571ms) completed I/O; added to ready queue [Q E F H G C B]
time 127086ms: Process D (tau 353ms) completed I/O; added to ready queue [Q D E F H G C B]
time 127834ms: Process J completed a CPU burst; 16 bursts to go [Q D E F H G C B]
time 127834ms: Recalculated tau = 806ms for process J [Q D E F H G C B]
time 127834ms: Process J switching out of CPU; will block on I/O until time 128232ms [Q D E F H G C B]
time 127838ms: Process D started using the CPU for 300ms burst [Q E F H G C B]
time 128138ms: Process D completed a CPU burst; 64 bursts to go [Q E F H G C B]
time 128138ms: Recalculated tau = 327ms for process D [Q E F H G C B]
time 128138ms: Process D switching out of CPU; will block on I/O until time 128516ms [Q E F H G C B]
time 128142ms: Process E started using the CPU for 96ms burst [Q F H G C B]
time 128232ms: Process J (tau 806ms) completed I/O; added to ready queue [Q J F H G C B]
time 128238ms: Process E completed a CPU burst; 16 bursts to go [Q J F H G C B]
time 128238ms: Recalculated tau = 388ms for process E [Q J F H G C B]
time 128238ms: Process E switching out of CPU; will block on I/O until time 128526ms [Q J F H G C B]
time 128242ms: Process J started using the CPU for 704ms burst [Q F H G C B]
time 128516ms: Process D (tau 327ms) completed I/O; added to ready queue [Q D F H G C B]
time 128526ms: Process E (tau 388ms) completed I/O; added to ready queue [Q D E F H G C B]
time 128946ms: Process J completed a CPU burst; 15 bursts to go [Q D E F H G C B]
time 128946ms: Recalculated tau = 755ms for process J [Q D E F H G C B]
time 128946ms: Process J switching out of CPU; will block on I/O until time 129415ms [Q D E F H G C B]
time 128950ms: Process D started using the CPU for 40ms burst [Q E F H G C B]
time 128990ms: Process D completed a CPU burst; 63 bursts to go [Q E F H G C B]
time 128990ms: Recalculated tau = 184ms for process D [Q E F H G C B]
time 128990ms: Process D switching out of CPU; will block on I/O until time 129634ms [Q E F H G C B]
time 128994ms: Process E started using the CPU for 315ms burst [Q F H G C B]
time 129309ms: Process E completed a CPU burst; 15 bursts to go [Q F H G C B]
time 129309ms: Recalculated tau = 352ms for process E [Q F H G C B]
time 129309ms: Process E switching out of CPU; will block on I/O until time 129568ms [Q F H G C B]
time 129313ms: Process F started using the CPU for 1754ms burst [Q H G C B]
time 129415ms: Process J (tau 755ms) completed I/O; added to ready queue [Q J H G C B]
time 129568ms: Process E (tau 352ms) completed I/O; added to ready queue [Q E J H G C B]
time 129634ms: Process D (tau 184ms) completed I/O; added to ready queue [Q D E J H G C B]
time 131067ms: Process F completed a CPU burst; 77 bursts to go [Q D E J H G C B]
time 131067ms: Recalculated tau = 1663ms for process F [Q D E J H G C B]
time 131067ms: Process F switching out of CPU; will block on I/O until time 131467ms [Q D E J H G C B]
time 131071ms: Process D started using the CPU for 1107ms burst [Q E J H G C B]
time 131467ms: Process F (tau 1663ms) completed I/O; added to ready queue [Q E J F H G C B]
time 132178ms: Process D completed a CPU burst; 62 bursts to go [Q E J F H G C B]
time 132178ms: Recalculated tau = 646ms for process D [Q E J F H G C B]
time 132178ms: Process D switching out of CPU; will block on I/O until time 133368ms [Q E J F H G C B]
time 132182ms: Process E started using the CPU for 318ms burst [Q J F H G C B]
time 132500ms: Process E completed a CPU burst; 14 bursts to go [Q J F H G C B]
time 132500ms: Recalculated tau = 335ms for process E [Q J F H G C B]
time 132500ms: Process E switching out of CPU; will block on I/O until time 133401ms [Q J F H G C B]
time 132504ms: Process J started using the CPU for 338ms burst [Q F H G C B]
time 132842ms: Process J completed a CPU burst; 14 bursts to go [Q F H G C B]
time 132842ms: Recalculated tau = 547ms for process J [Q F H G C B]
time 132842ms: Process J switching out of CPU; will block on I/O until time 133413ms [Q F H G C B]
time 132846ms: Process F started using the CPU for 83ms burst [Q H G C B]
time 132929ms: Process F completed a CPU burst; 76 bursts to go [Q H G C B]
time 132929ms: Recalculated tau = 873ms for process F [Q H G C B]
time 132929ms: Process F switching out of CPU; will block on I/O until time 132947ms [Q H G C B]
time 132933ms: Process H started using the CPU for 25ms burst [Q G C B]
time 132947ms: Process F (tau 873ms) completed I/O; added to ready queue [Q F G C B]
time 132958ms: Process H completed a CPU burst; 9 bursts to go [Q F G C B]
time 132958ms: Recalculated tau = 869ms for process H [Q F G C B]
time 132958ms: Process H switching out of CPU; will block on I/O until time 133012ms [Q F G C B]
time 132962ms: Process F started using the CPU for 1063ms burst [Q G C B]
time 133012ms: Process H (tau 869ms) completed I/O; added to ready queue [Q H G C B]
time 133368ms: Process D (tau 646ms) completed I/O; added to ready queue [Q D H G C B]
time 133401ms: Process E (tau 335ms) completed I/O; added to ready queue [Q E D H G C B]
time 133413ms: Process J (tau 547ms) completed I/O; added to ready queue [Q E J D H G C B]
time 134025ms: Process F completed a CPU burst; 75 bursts to go [Q E J D H G C B]
time 134025ms: Recalculated tau = 968ms for process F [Q E J D H G C B]
time 134025ms: Process F switching out of CPU; will block on I/O until time 134286ms [Q E J D H G C B]
time 134029ms: Process E started using the CPU for 157ms burst [Q J D H G C B]
time 134186ms: Process E completed a CPU burst; 13 bursts to go [Q J D H G C B]
time 134186ms: Recalculated tau = 246ms for process E [Q J D H G C B]
time 134186ms: Process E switching out of CPU; will block on I/O until time 134264ms [Q J D H G C B]
time 134190ms: Process J started using the CPU for 645ms burst [Q D H G C B]
time 134264ms: Process E (tau 246ms) completed I/O; added to ready queue [Q E D H G C B]
time 134286ms: Process F (tau 968ms) completed I/O; added to ready queue [Q E D H F G C B]
time 134835ms: Process J completed a CPU burst; 13 bursts to go [Q E D H F G C B]
time 134835ms: Recalculated tau = 596ms for process J [Q E D H F G C B]
time 134835ms: Process J switching out of CPU; will block on I/O until time 136457ms [Q E D H F G C B]
time 134839ms: Process E started using the CPU for 728ms burst [Q D H F G C B]
time 135567ms: Process E completed a CPU burst; 12 bursts to go [Q D H F G C B]
time 135567ms: Recalculated tau = 487ms for process E [Q D H F G C B]
time 135567ms: Process E switching out of CPU; will block on I/O until time 136291ms [Q D H F G C B]
time 135571ms: Process D started using the CPU for 983ms burst [Q H F G C B]
time 136291ms: Process E (tau 487ms) completed I/O; added to ready queue [Q E H F G C B]
time 136457ms: Process J (tau 596ms) completed I/O; added to ready queue [Q E J H F G C B]
time 136554ms: Process D completed a CPU burst; 61 bursts to go [Q E J H F G C B]
time 136554ms: Recalculated tau = 815ms for process D [Q E J H F G C B]
time 136554ms: Process D switching out of CPU; will block on I/O until time 139306ms [Q E J H F G C B]
time 136558ms: Process E started using the CPU for 307ms burst [Q J H F G C B]
time 136865ms: Process E completed a CPU burst; 11 bursts to go [Q J H F G C B]
time 136865ms: Recalculated tau = 397ms for process E [Q J H F G C B]
time 136865ms: Process E switching out of CPU; will block on I/O until time 137724ms [Q J H F G C B]
time 136869ms: Process J started using the CPU for 961ms burst [Q H F G C B]
time 137724ms: Process E (tau 397ms) completed I/O; added to ready queue [Q E H F G C B]
time 137830ms: Process J completed a CPU burst; 12 bursts to go [Q E H F G C B]
time 137830ms: Recalculated tau = 779ms for process J [Q E H F G C B]
time 137830ms: Process J switching out of CPU; will block on I/O until time 140014ms [Q E H F G C B]
time 137834ms: Process E started using the CPU for 1518ms burst [Q H F G C B]
time 139306ms: Process D (tau 815ms) completed I/O; added to ready queue [Q D H F G C B]
time 139352ms: Process E completed a CPU burst; 10 bursts to go [Q D H F G C B]
time 139352ms: Recalculated tau = 958ms for process E [Q D H F G C B]
time 139352ms: Process E switching out of CPU; will block on I/O until time 142024ms [Q D H F G C B]
time 139356ms: Process D started using the CPU for 356ms burst [Q H F G C B]
time 139712ms: Process D completed a CPU burst; 60 bursts to go [Q H F G C B]
time 139712ms: Recalculated tau = 586ms for process D [Q H F G C B]
time 139712ms: Process D switching out of CPU; will block on I/O until time 139803ms [Q H F G C B]
time 139716ms: Process H started using the CPU for 1208ms burst [Q F G C B]
time 139803ms: Process D (tau 586ms) completed I/O; added to ready queue [Q D F G C B]
time 140014ms: Process J (tau 779ms) completed I/O; added to ready queue [Q D J F G C B]
time 140924ms: Process H completed a CPU burst; 8 bursts to go [Q D J F G C B]
time 140924ms: Recalculated tau = 1039ms for process H [Q D J F G C B]
time 140924ms: Process H switching out of CPU; will block on I/O until time 142263ms [Q D J F G C B]
time 140928ms: Process D started using the CPU for 171ms burst [Q J F G C B]
time 141099ms: Process D completed a CPU burst; 59 bursts to go [Q J F G C B]
time 141099ms: Recalculated tau = 379ms for process D [Q J F G C B]
time 141099ms: Process D switching out of CPU; will block on I/O until time 141565ms [Q J F G C B]
time 141103ms: Process J started using the CPU for 2833ms burst [Q F G C B]
time 141565ms: Process D (tau 379ms) completed I/O; added to ready queue [Q D F G C B]
time 142024ms: Process E (tau 958ms) completed I/O; added to ready queue [Q D E F G C B]
time 142263ms: Process H (tau 1039ms) completed I/O; added to ready queue [Q D E F H G C B]
time 143936ms: Process J completed a CPU burst; 11 bursts to go [Q D E F H G C B]
time 143936ms: Recalculated tau = 1806ms for process J [Q D E F H G C B]
time 143936ms: Process J switching out of CPU; will block on I/O until time 144930ms [Q D E F H G C B]
time 143940ms: Process D started using the CPU for 1613ms burst [Q E F H G C B]
time 144930ms: Process J (tau 1806ms) completed I/O; added to ready queue [Q E F H G J C B]
time 145553ms: Process D completed a CPU burst; 58 bursts to go [Q E F H G J C B]
time 145553ms: Recalculated tau = 996ms for process D [Q E F H G J C B]
time 145553ms: Process D switching out of CPU; will block on I/O until time 146355ms [Q E F H G J C B]
time 145557ms: Process E started using the CPU for 1454ms burst [Q F H G J C B]
time 146355ms: Process D (tau 996ms) completed I/O; added to ready queue [Q F D H G J C B]
time 147011ms: Process E completed a CPU burst; 9 bursts to go [Q F D H G J C B]
time 147011ms: Recalculated tau = 1206ms for process E [Q F D H G J C B]
time 147011ms: Process E switching out of CPU; will block on I/O until time 149192ms [Q F D H G J C B]
time 147015ms: Process F started using the CPU for 1087ms burst [Q D H G J C B]
time 148102ms: Process F completed a CPU burst; 74 bursts to go [Q D H G J C B]
time 148102ms: Recalculated tau = 1028ms for process F [Q D H G J C B]
time 148102ms: Process F switching out of CPU; will block on I/O until time 148266ms [Q D H G J C B]
time 148106ms: Process D started using the CPU for 1064ms burst [Q H G J C B]
time 148266ms: Process F (tau 1028ms) completed I/O; added to ready queue [Q F H G J C B]
time 149170ms: Process D completed a CPU burst; 57 bursts to go [Q F H G J C B]
time 149170ms: Recalculated tau = 1030ms for process D [Q F H G J C B]
time 149170ms: Process D switching out of CPU; will block on I/O until time 149705ms [Q F H G J C B]
time 149174ms: Process F started using the CPU for 1480ms burst [Q H G J C B]
time 149192ms: Process E (tau 1206ms) completed I/O; added to ready queue [Q H E G J C B]
time 149705ms: Process D (tau 1030ms) completed I/O; added to ready queue [Q D H E G J C B]
time 150654ms: Process F completed a CPU burst; 73 bursts to go [Q D H E G J C B]
time 150654ms: Recalculated tau = 1254ms for process F [Q D H E G J C B]
time 150654ms: Process F switching out of CPU; will block on I/O until time 150721ms [Q D H E G J C B]
time 150658ms: Process D started using the CPU for 2140ms burst [Q H E G J C B]
time 150721ms: Process F (tau 1254ms) completed I/O; added to ready queue [Q H E F G J C B]
time 152798ms: Process D completed a CPU burst; 56 bursts to go [Q H E F G J C B]
time 152798ms: Recalculated tau = 1585ms for process D [Q H E F G J C B]
time 152798ms: Process D switching out of CPU; will block on I/O until time 153255ms [Q H E F G J C B]
time 152802ms: Process H started using the CPU for 1465ms burst [Q E F G J C B]
time 153255ms: Process D (tau 1585ms) completed I/O; added to ready queue [Q E F D G J C B]
time 154267ms: Process H completed a CPU burst; 7 bursts to go [Q E F D G J C B]
time 154267ms: Recalculated tau = 1252ms for process H [Q E F D G J C B]
time 154267ms: Process H switching out of CPU; will block on I/O until time 154953ms [Q E F D G J C B]
time 154271ms: Process E started using the CPU for 877ms burst [Q F D G J C B]
time 154953ms: Process H (tau 1252ms) completed I/O; added to ready queue [Q H F D G J C B]
time 155148ms: Process E completed a CPU burst; 8 bursts to go [Q H F D G J C B]
time 155148ms: Recalculated tau = 1042ms for process E [Q H F D G J C B]
time 155148ms: Process E switching out of CPU; will block on I/O until time 155803ms [Q H F D G J C B]
time 155152ms: Process H started using the CPU for 36ms burst [Q F D G J C B]
time 155188ms: Process H completed a CPU burst; 6 bursts to go [Q F D G J C B]
time 155188ms: Recalculated tau = 644ms for process H [Q F D G J C B]
time 155188ms: Process H switching out of CPU; will block on I/O until time 156190ms [Q F D G J C B]
time 155192ms: Process F started using the CPU for 1861ms burst [Q D G J C B]
time 155803ms: Process E (tau 1042ms) completed I/O; added to ready queue [Q E D G J C B]
time 156190ms: Process H (tau 644ms) completed I/O; added to ready queue [Q H E D G J C B]
time 157053ms: Process F completed a CPU burst; 72 bursts to go [Q H E D G J C B]
time 157053ms: Recalculated tau = 1558ms for process F [Q H E D G J C B]
time 157053ms: Process F switching out of CPU; will block on I/O until time 158541ms [Q H E D G J C B]
time 157057ms: Process H started using the CPU for 356ms burst [Q E D G J C B]
time 157413ms: Process H completed a CPU burst; 5 bursts to go [Q E D G J C B]
time 157413ms: Recalculated tau = 500ms for process H [Q E D G J C B]
time 157413ms: Process H switching out of CPU; will block on I/O until time 158082ms [Q E D G J C B]
time 157417ms: Process E started using the CPU for 2447ms burst [Q D G J C B]
time 158082ms: Process H (tau 500ms) completed I/O; added to ready queue [Q H D G J C B]
time 158541ms: Process F (tau 1558ms) completed I/O; added to ready queue [Q H F D G J C B]
time 159864ms: Process E completed a CPU burst; 7 bursts to go [Q H F D G J C B]
time 159864ms: Recalculated tau = 1745ms for process E [Q H F D G J C B]
time 159864ms: Process E switching out of CPU; will block on I/O until time 161508ms [Q H F D G J C B]
time 159868ms: Process H started using the CPU for 612ms burst [Q F D G J C B]
time 160480ms: Process H completed a CPU burst; 4 bursts to go [Q F D G J C B]
time 160480ms: Recalculated tau = 556ms for process H [Q F D G J C B]
time 160480ms: Process H switching out of CPU; will block on I/O until time 161447ms [Q F D G J C B]
time 160484ms: Process F started using the CPU for 354ms burst [Q D G J C B]
time 160838ms: Process F completed a CPU burst; 71 bursts to go [Q D G J C B]
time 160838ms: Recalculated tau = 956ms for process F [Q D G J C B]
time 160838ms: Process F switching out of CPU; will block on I/O until time 161399ms [Q D G J C B]
time 160842ms: Process D started using the CPU for 268ms burst [Q G J C B]
time 161110ms: Process D completed a CPU burst; 55 bursts to go [Q G J C B]
time 161110ms: Recalculated tau = 927ms for process D [Q G J C B]
time 161110ms: Process D switching out of CPU; will block on I/O until time 163071ms [Q G J C B]
time 161114ms: Process G started using the CPU for 68ms burst [Q J C B]
time 161182ms: Process G completed a CPU burst; 36 bursts to go [Q J C B]
time 161182ms: Recalculated tau = 925ms for process G [Q J C B]
time 161182ms: Process G switching out of CPU; will block on I/O until time 163446ms [Q J C B]
time 161186ms: Process J started using the CPU for 1188ms burst [Q C B]
time 161399ms: Process F (tau 956ms) completed I/O; added to ready queue [Q F C B]
time 161447ms: Process H (tau 556ms) completed I/O; added to ready queue [Q H F C B]
time 161508ms: Process E (tau 1745ms) completed I/O; added to ready queue [Q H F E C B]
time 162374ms: Process J completed a CPU burst; 10 bursts to go [Q H F E C B]
time 162374ms: Recalculated tau = 1497ms for process J [Q H F E C B]
time 162374ms: Process J switching out of CPU; will block on I/O until time 163107ms [Q H F E C B]
time 162378ms: Process H started using the CPU for 299ms burst [Q F E C B]
time 162677ms: Process H completed a CPU burst; 3 bursts to go [Q F E C B]
time 162677ms: Recalculated tau = 428ms for process H [Q F E C B]
time 162677ms: Process H switching out of CPU; will block on I/O until time 163770ms [Q F E C B]
time 162681ms: Process F started using the CPU for 268ms burst [Q E C B]
time 162949ms: Process F completed a CPU burst; 70 bursts to go [Q E C B]
time 162949ms: Recalculated tau = 612ms for process F [Q E C B]
time 162949ms: Process F switching out of CPU; will block on I/O until time 163279ms [Q E C B]
time 162953ms: Process E started using the CPU for 2937ms burst [Q C B]
time 163071ms: Process D (tau 927ms) completed I/O; added to ready queue [Q D C B]
time 163107ms: Process J (tau 1497ms) completed I/O; added to ready queue [Q D J C B]
time 163279ms: Process F (tau 612ms) completed I/O; added to ready queue [Q F D J C B]
time 163446ms: Process G (tau 925ms) completed I/O; added to ready queue [Q F G D J C B]
time 163770ms: Process H (tau 428ms) completed I/O; added to ready queue [Q H F G D J C B]
time 165890ms: Process E completed a CPU burst; 6 bursts to go [Q H F G D J C B]
time 165890ms: Recalculated tau = 2341ms for process E [Q H F G D J C B]
time 165890ms: Process E switching out of CPU; will block on I/O until time 166086ms [Q H F G D J C B]
time 165894ms: Process H started using the CPU for 1150ms burst [Q F G D J C B]
time 166086ms: Process E (tau 2341ms) completed I/O; added to ready queue [Q F G D J C B E]
time 167044ms: Process H completed a CPU burst; 2 bursts to go [Q F G D J C B E]
time 167044ms: Recalculated tau = 789ms for process H [Q F G D J C B E]
time 167044ms: Process H switching out of CPU; will block on I/O until time 167585ms [Q F G D J C B E]
time 167048ms: Process F started using the CPU for 76ms burst [Q G D J C B E]
time 167124ms: Process F completed a CPU burst; 69 bursts to go [Q G D J C B E]
time 167124ms: Recalculated tau = 344ms for process F [Q G D J C B E]
time 167124ms: Process F switching out of CPU; will block on I/O until time 167169ms [Q G D J C B E]
time 167128ms: Process G started using the CPU for 95ms burst [Q D J C B E]
time 167169ms: Process F (tau 344ms) completed I/O; added to ready queue [Q F D J C B E]
time 167223ms: Process G completed a CPU burst; 35 bursts to go [Q F D J C B E]
time 167223ms: Recalculated tau = 510ms for process G [Q F D J C B E]
time 167223ms: Process G switching out of CPU; will block on I/O until time 168413ms [Q F D J C B E]
time 167227ms: Process F started using the CPU for 2713ms burst [Q D J C B E]
time 167585ms: Process H (tau 789ms) completed I/O; added to ready queue [Q H D J C B E]
time 168413ms: Process G (tau 510ms) completed I/O; added to ready queue [Q G H D J C B E]
time 169940ms: Process F completed a CPU burst; 68 bursts to go [Q G H D J C B E]
time 169940ms: Recalculated tau = 1529ms for process F [Q G H D J C B E]
time 169940ms: Process F switching out of CPU; will block on I/O until time 171003ms [Q G H D J C B E]
time 169944ms: Process G started using the CPU for 267ms burst [Q H D J C B E]
time 170211ms: Process G completed a CPU burst; 34 bursts to go [Q H D J C B E]
time 170211ms: Recalculated tau = 389ms for process G [Q H D J C B E]
time 170211ms: Process G switching out of CPU; will block on I/O until time 170941ms [Q H D J C B E]
time 170215ms: Process H started using the CPU for 1316ms burst [Q D J C B E]
time 170941ms: Process G (tau 389ms) completed I/O; added to ready queue [Q G D J C B E]
time 171003ms: Process F (tau 1529ms) completed I/O; added to ready queue [Q G D J F C B E]
time 171531ms: Process H completed a CPU burst; 1 burst to go [Q G D J F C B E]
time 171531ms: Recalculated tau = 1053ms for process H [Q G D J F C B E]
time 171531ms: Process H switching out of CPU; will block on I/O until time 172752ms [Q G D J F C B E]
time 171535ms: Process G started using the CPU for 530ms burst [Q D J F C B E]
time 172065ms: Process G completed a CPU burst; 33 bursts to go [Q D J F C B E]
time 172065ms: Recalculated tau = 460ms for process G [Q D J F C B E]
time 172065ms: Process G switching out of CPU; will block on I/O until time 172187ms [Q D J F C B E]
time 172069ms: Process D started using the CPU for 269ms burst [Q J F C B E]
time 172187ms: Process G (tau 460ms) completed I/O; added to ready queue [Q G J F C B E]
time 172338ms: Process D completed a CPU burst; 54 bursts to go [Q G J F C B E]
time 172338ms: Recalculated tau = 598ms for process D [Q G J F C B E]
time 172338ms: Process D switching out of CPU; will block on I/O until time 173461ms [Q G J F C B E]
time 172342ms: Process G started using the CPU for 2254ms burst [Q J F C B E]
time 172752ms: Process H (tau 1053ms) completed I/O; added to ready queue [Q H J F C B E]
time 173461ms: Process D (tau 598ms) completed I/O; added to ready queue [Q D H J F C B E]
time 174596ms: Process G completed a CPU burst; 32 bursts to go [Q D H J F C B E]
time 174596ms: Recalculated tau = 1357ms for process G [Q D H J F C B E]
time 174596ms: Process G switching out of CPU; will block on I/O until time 174884ms [Q D H J F C B E]
time 174600ms: Process D started using the CPU for 1287ms burst [Q H J F C B E]
time 174884ms: Process G (tau 1357ms) completed I/O; added to ready queue [Q H G J F C B E]
time 175887ms: Process D completed a CPU burst; 53 bursts to go [Q H G J F C B E]
time 175887ms: Recalculated tau = 943ms for process D [Q H G J F C B E]
time 175887ms: Process D switching out of CPU; will block on I/O until time 176891ms [Q H G J F C B E]
time 175891ms: Process H started using the CPU for 313ms burst [Q G J F C B E]
time 176204ms: Process H terminated [Q G J F C B E]
time 176208ms: Process G started using the CPU for 146ms burst [Q J F C B E]
time 176354ms: Process G completed a CPU burst; 31 bursts to go [Q J F C B E]
time 176354ms: Recalculated tau = 752ms for process G [Q J F C B E]
time 176354ms: Process G switching out of CPU; will block on I/O until time 177073ms [Q J F C B E]
time 176358ms: Process J started using the CPU for 1281ms burst [Q F C B E]
time 176891ms: Process D (tau 943ms) completed I/O; added to ready queue [Q D F C B E]
time 177073ms: Process G (tau 752ms) completed I/O; added to ready queue [Q G D F C B E]
time 177639ms: Process J completed a CPU burst; 9 bursts to go [Q G D F C B E]
time 177639ms: Recalculated tau = 1389ms for process J [Q G D F C B E]
time 177639ms: Process J switching out of CPU; will block on I/O until time 178247ms [Q G D F C B E]
time 177643ms: Process G started using the CPU for 125ms burst [Q D F C B E]
time 177768ms: Process G completed a CPU burst; 30 bursts to go [Q D F C B E]
time 177768ms: Recalculated tau = 439ms for process G [Q D F C B E]
time 177768ms: Process G switching out of CPU; will block on I/O until time 178624ms [Q D F C B E]
time 177772ms: Process D started using the CPU for 520ms burst [Q F C B E]
time 178247ms: Process J (tau 1389ms) completed I/O; added to ready queue [Q J F C B E]
time 178292ms: Process D completed a CPU burst; 52 bursts to go [Q J F C B E]
time 178292ms: Recalculated tau = 732ms for process D [Q J F C B E]
time 178292ms: Process D switching out of CPU; will block on I/O until time 181139ms [Q J F C B E]
time 178296ms: Process J started using the CPU for 475ms burst [Q F C B E]
time 178624ms: Process G (tau 439ms) completed I/O; added to ready queue [Q G F C B E]
time 178771ms: Process J completed a CPU burst; 8 bursts to go [Q G F C B E]
time 178771ms: Recalculated tau = 932ms for process J [Q G F C B E]
time 178771ms: Process J switching out of CPU; will block on I/O until time 179519ms [Q G F C B E]
time 178775ms: Process G started using the CPU for 167ms burst [Q F C B E]
time 178942ms: Process G completed a CPU burst; 29 bursts to go [Q F C B E]
time 178942ms: Recalculated tau = 303ms for process G [Q F C B E]
time 178942ms: Process G switching out of CPU; will block on I/O until time 180199ms [Q F C B E]
time 178946ms: Process F started using the CPU for 307ms burst [Q C B E]
time 179253ms: Process F completed a CPU burst; 67 bursts to go [Q C B E]
time 179253ms: Recalculated tau = 918ms for process F [Q C B E]
time 179253ms: Process F switching out of CPU; will block on I/O until time 180721ms [Q C B E]
time 179257ms: Process C started using the CPU for 89ms burst [Q B E]
time 179346ms: Process C completed a CPU burst; 77 bursts to go [Q B E]
time 179346ms: Recalculated tau = 980ms for process C [Q B E]
time 179346ms: Process C switching out of CPU; will block on I/O until time 179433ms [Q B E]
time 179350ms: Process B started using the CPU for 2707ms burst [Q E]
time 179433ms: Process C (tau 980ms) completed I/O; added to ready queue [Q C E]
time 179519ms: Process J (tau 932ms) completed I/O; added to ready queue [Q J C E]
time 180199ms: Process G (tau 303ms) completed I/O; added to ready queue [Q G J C E]
time 180721ms: Process F (tau 918ms) completed I/O; added to ready queue [Q G F J C E]
time 181139ms: Process D (tau 732ms) completed I/O; added to ready queue [Q G D F J C E]
time 182057ms: Process B completed a CPU burst; 80 bursts to go [Q G D F J C E]
time 182057ms: Recalculated tau = 2343ms for process B [Q G D F J C E]
time 182057ms: Process B switching out of CPU; will block on I/O until time 182326ms [Q G D F J C E]
time 182061ms: Process G started using the CPU for 157ms burst [Q D F J C E]
time 182218ms: Process G completed a CPU burst; 28 bursts to go [Q D F J C E]
time 182218ms: Recalculated tau = 230ms for process G [Q D F J C E]
time 182218ms: Process G switching out of CPU; will block on I/O until time 182658ms [Q D F J C E]
time 182222ms: Process D started using the CPU for 519ms burst [Q F J C E]
time 182326ms: Process B (tau 2343ms) completed I/O; added to ready queue [Q F J C E B]
time 182658ms: Process G (tau 230ms) completed I/O; added to ready queue [Q G F J C E B]
time 182741ms: Process D completed a CPU burst; 51 bursts to go [Q G F J C E B]
time 182741ms: Recalculated tau = 626ms for process D [Q G F J C E B]
time 182741ms: Process D switching out of CPU; will block on I/O until time 183480ms [Q G F J C E B]
time 182745ms: Process G started using the CPU for 1628ms burst [Q F J C E B]
time 183480ms: Process D (tau 626ms) completed I/O; added to ready queue [Q D F J C E B]
time 184373ms: Process G completed a CPU burst; 27 bursts to go [Q D F J C E B]
time 184373ms: Recalculated tau = 929ms for process G [Q D F J C E B]
time 184373ms: Process G switching out of CPU; will block on I/O until time 186841ms [Q D F J C E B]
time 184377ms: Process D started using the CPU for 102ms burst [Q F J C E B]
time 184479ms: Process D completed a CPU burst; 50 bursts to go [Q F J C E B]
time 184479ms: Recalculated tau = 364ms for process D [Q F J C E B]
time 184479ms: Process D switching out of CPU; will block on I/O until time 184626ms [Q F J C E B]
time 184483ms: Process F started using the CPU for 1847ms burst [Q J C E B]
time 184626ms: Process D (tau 364ms) completed I/O; added to ready queue [Q D J C E B]
time 186330ms: Process F completed a CPU burst; 66 bursts to go [Q D J C E B]
time 186330ms: Recalculated tau = 1383ms for process F [Q D J C E B]
time 186330ms: Process F switching out of CPU; will block on I/O until time 187628ms [Q D J C E B]
time 186334ms: Process D started using the CPU for 464ms burst [Q J C E B]
time 186798ms: Process D completed a CPU burst; 49 bursts to go [Q J C E B]
time 186798ms: Recalculated tau = 414ms for process D [Q J C E B]
time 186798ms: Process D switching out of CPU; will block on I/O until time 187733ms [Q J C E B]
time 186802ms: Process J started using the CPU for 524ms burst [Q C E B]
time 186841ms: Process G (tau 929ms) completed I/O; added to ready queue [Q G C E B]
time 187326ms: Process J completed a CPU burst; 7 bursts to go [Q G C E B]
time 187326ms: Recalculated tau = 728ms for process J [Q G C E B]
time 187326ms: Process J switching out of CPU; will block on I/O until time 189542ms [Q G C E B]
time 187330ms: Process G started using the CPU for 2807ms burst [Q C E B]
time 187628ms: Process F (tau 1383ms) completed I/O; added to ready queue [Q C F E B]
time 187733ms: Process D (tau 414ms) completed I/O; added to ready queue [Q D C F E B]
time 189542ms: Process J (tau 728ms) completed I/O; added to ready queue [Q D J C F E B]
time 190137ms: Process G completed a CPU burst; 26 bursts to go [Q D J C F E B]
time 190137ms: Recalculated tau = 1868ms for process G [Q D J C F E B]
time 190137ms: Process G switching out of CPU; will block on I/O until time 190736ms [Q D J C F E B]
time 190141ms: Process D started using the CPU for 671ms burst [Q J C F E B]
time 190736ms: Process G (tau 1868ms) completed I/O; added to ready queue [Q J C F G E B]
time 190812ms: Process D completed a CPU burst; 48 bursts to go [Q J C F G E B]
time 190812ms: Recalculated tau = 543ms for process D [Q J C F G E B]
time 190812ms: Process D switching out of CPU; will block on I/O until time 191049ms [Q J C F G E B]
time 190816ms: Process J started using the CPU for 84ms burst [Q C F G E B]
time 190900ms: Process J completed a CPU burst; 6 bursts to go [Q C F G E B]
time 190900ms: Recalculated tau = 406ms for process J [Q C F G E B]
time 190900ms: Process J switching out of CPU; will block on I/O until time 191305ms [Q C F G E B]
time 190904ms: Process C started using the CPU for 1441ms burst [Q F G E B]
time 191049ms: Process D (tau 543ms) completed I/O; added to ready queue [Q D F G E B]
time 191305ms: Process J (tau 406ms) completed I/O; added to ready queue [Q J D F G E B]
time 192345ms: Process C completed a CPU burst; 76 bursts to go [Q J D F G E B]
time 192345ms: Recalculated tau = 1211ms for process C [Q J D F G E B]
time 192345ms: Process C switching out of CPU; will block on I/O until time 193317ms [Q J D F G E B]
time 192349ms: Process J started using the CPU for 1881ms burst [Q D F G E B]
time 193317ms: Process C (tau 1211ms) completed I/O; added to ready queue [Q D C F G E B]
time 194230ms: Process J completed a CPU burst; 5 bursts to go [Q D C F G E B]
time 194230ms: Recalculated tau = 1144ms for process J [Q D C F G E B]
time 194230ms: Process J switching out of CPU; will block on I/O until time 194404ms [Q D C F G E B]
time 194234ms: Process D started using the CPU for 648ms burst [Q C F G E B]
time 194404ms: Process J (tau 1144ms) completed I/O; added to ready queue [Q J C F G E B]
time 194882ms: Process D completed a CPU burst; 47 bursts to go [Q J C F G E B]
time 194882ms: Recalculated tau = 596ms for process D [Q J C F G E B]
time 194882ms: Process D switching out of CPU; will block on I/O until time 196461ms [Q J C F G E B]
time 194886ms: Process J started using the CPU for 208ms burst [Q C F G E B]
time 195094ms: Process J completed a CPU burst; 4 bursts to go [Q C F G E B]
time 195094ms: Recalculated tau = 676ms for process J [Q C F G E B]
time 195094ms: Process J switching out of CPU; will block on I/O until time 195510ms [Q C F G E B]
time 195098ms: Process C started using the CPU for 1062ms burst [Q F G E B]
time 195510ms: Process J (tau 676ms) completed I/O; added to ready queue [Q J F G E B]
time 196160ms: Process C completed a CPU burst; 75 bursts to go [Q J F G E B]
time 196160ms: Recalculated tau = 1137ms for process C [Q J F G E B]
time 196160ms: Process C switching out of CPU; will block on I/O until time 196235ms [Q J F G E B]
time 196164ms: Process J started using the CPU for 1822ms burst [Q F G E B]
time 196235ms: Process C (tau 1137ms) completed I/O; added to ready queue [Q C F G E B]
time 196461ms: Process D (tau 596ms) completed I/O; added to ready queue [Q D C F G E B]
time 197986ms: Process J completed a CPU burst; 3 bursts to go [Q D C F G E B]
time 197986ms: Recalculated tau = 1249ms for process J [Q D C F G E B]
time 197986ms: Process J switching out of CPU; will block on I/O until time 199186ms [Q D C F G E B]
time 197990ms: Process D started using the CPU for 201ms burst [Q C F G E B]
time 198191ms: Process D completed a CPU burst; 46 bursts to go [Q C F G E B]
time 198191ms: Recalculated tau = 399ms for process D [Q C F G E B]
time 198191ms: Process D switching out of CPU; will block on I/O until time 198705ms [Q C F G E B]
time 198195ms: Process C started using the CPU for 2923ms burst [Q F G E B]
time 198705ms: Process D (tau 399ms) completed I/O; added to ready queue [Q D F G E B]
time 199186ms: Process J (tau 1249ms) completed I/O; added to ready queue [Q D J F G E B]
time 201118ms: Process C completed a CPU burst; 74 bursts to go [Q D J F G E B]
time 201118ms: Recalculated tau = 2030ms for process C [Q D J F G E B]
time 201118ms: Process C switching out of CPU; will block on I/O until time 203077ms [Q D J F G E B]
time 201122ms: Process D started using the CPU for 278ms burst [Q J F G E B]
time 201400ms: Process D completed a CPU burst; 45 bursts to go [Q J F G E B]
time 201400ms: Recalculated tau = 339ms for process D [Q J F G E B]
time 201400ms: Process D switching out of CPU; will block on I/O until time 201908ms [Q J F G E B]
time 201404ms: Process J started using the CPU for 377ms burst [Q F G E B]
time 201781ms: Process J completed a CPU burst; 2 bursts to go [Q F G E B]
time 201781ms: Recalculated tau = 813ms for process J [Q F G E B]
time 201781ms: Process J switching out of CPU; will block on I/O until time 202153ms [Q F G E B]
time 201785ms: Process F started using the CPU for 1057ms burst [Q G E B]
time 201908ms: Process D (tau 339ms) completed I/O; added to ready queue [Q D G E B]
time 202153ms: Process J (tau 813ms) completed I/O; added to ready queue [Q D J G E B]
time 202842ms: Process F completed a CPU burst; 65 bursts to go [Q D J G E B]
time 202842ms: Recalculated tau = 1220ms for process F [Q D J G E B]
time 202842ms: Process F switching out of CPU; will block on I/O until time 203321ms [Q D J G E B]
time 202846ms: Process D started using the CPU for 531ms burst [Q J G E B]
time 203077ms: Process C (tau 2030ms) completed I/O; added to ready queue [Q J G C E B]
time 203321ms: Process F (tau 1220ms) completed I/O; added to ready queue [Q J F G C E B]
time 203377ms: Process D completed a CPU burst; 44 bursts to go [Q J F G C E B]
time 203377ms: Recalculated tau = 435ms for process D [Q J F G C E B]
time 203377ms: Process D switching out of CPU; will block on I/O until time 203791ms [Q J F G C E B]
time 203381ms: Process J started using the CPU for 915ms burst [Q F G C E B]
time 203791ms: Process D (tau 435ms) completed I/O; added to ready queue [Q D F G C E B]
time 204296ms: Process J completed a CPU burst; 1 burst to go [Q D F G C E B]
time 204296ms: Recalculated tau = 864ms for process J [Q D F G C E B]
time 204296ms: Process J switching out of CPU; will block on I/O until time 204726ms [Q D F G C E B]
time 204300ms: Process D started using the CPU for 928ms burst [Q F G C E B]
time 204726ms: Process J (tau 864ms) completed I/O; added to ready queue [Q J F G C E B]
time 205228ms: Process D completed a CPU burst; 43 bursts to go [Q J F G C E B]
time 205228ms: Recalculated tau = 682ms for process D [Q J F G C E B]
time 205228ms: Process D switching out of CPU; will block on I/O until time 205905ms [Q J F G C E B]
time 205232ms: Process J started using the CPU for 1533ms burst [Q F G C E B]
